2025-01-03 07:04:11,945 - INFO - Starting preprocessing pipeline.
2025-01-03 07:04:12,047 - ERROR - An error occurred during preprocessing: "['Traffic_Congestion_Level', 'Port_Congestion_Level', 'Fuel_Consumption_Rate', 'Driver_Behavior_Score', 'Fatigue_Monitoring_Score', 'Supplier_Reliability_Score'] not in index"
Traceback (most recent call last):
  File "/workspaces/invenlytics/pipelines/v2/feature_pipeline.py", line 37, in run_supplychain_disruption_feature_pipeline
    data = data[selected_columns]
           ~~~~^^^^^^^^^^^^^^^^^^
  File "/home/codespace/.local/lib/python3.12/site-packages/pandas/core/frame.py", line 4108, in __getitem__
    indexer = self.columns._get_indexer_strict(key, "columns")[1]
              ^^^^^^^^^^^^^^^^^^^^^^^^^^^^^^^^^^^^^^^^^^^^^^^^
  File "/home/codespace/.local/lib/python3.12/site-packages/pandas/core/indexes/base.py", line 6200, in _get_indexer_strict
    self._raise_if_missing(keyarr, indexer, axis_name)
  File "/home/codespace/.local/lib/python3.12/site-packages/pandas/core/indexes/base.py", line 6252, in _raise_if_missing
    raise KeyError(f"{not_found} not in index")
KeyError: "['Traffic_Congestion_Level', 'Port_Congestion_Level', 'Fuel_Consumption_Rate', 'Driver_Behavior_Score', 'Fatigue_Monitoring_Score', 'Supplier_Reliability_Score'] not in index"
2025-01-03 07:04:12,052 - CRITICAL - Pipeline execution failed: "['Traffic_Congestion_Level', 'Port_Congestion_Level', 'Fuel_Consumption_Rate', 'Driver_Behavior_Score', 'Fatigue_Monitoring_Score', 'Supplier_Reliability_Score'] not in index"
2025-01-03 07:05:07,816 - INFO - Starting preprocessing pipeline.
2025-01-03 07:05:07,872 - ERROR - An error occurred during preprocessing: "['Traffic_Congestion_Level', 'Port_Congestion_Level', 'Fuel_Consumption_Rate', 'Driver_Behavior_Score', 'Fatigue_Monitoring_Score', 'Supplier_Reliability_Score'] not in index"
Traceback (most recent call last):
  File "/workspaces/invenlytics/pipelines/v2/feature_pipeline.py", line 37, in run_supplychain_disruption_feature_pipeline
    data = data[selected_columns]
           ~~~~^^^^^^^^^^^^^^^^^^
  File "/home/codespace/.local/lib/python3.12/site-packages/pandas/core/frame.py", line 4108, in __getitem__
    indexer = self.columns._get_indexer_strict(key, "columns")[1]
              ^^^^^^^^^^^^^^^^^^^^^^^^^^^^^^^^^^^^^^^^^^^^^^^^
  File "/home/codespace/.local/lib/python3.12/site-packages/pandas/core/indexes/base.py", line 6200, in _get_indexer_strict
    self._raise_if_missing(keyarr, indexer, axis_name)
  File "/home/codespace/.local/lib/python3.12/site-packages/pandas/core/indexes/base.py", line 6252, in _raise_if_missing
    raise KeyError(f"{not_found} not in index")
KeyError: "['Traffic_Congestion_Level', 'Port_Congestion_Level', 'Fuel_Consumption_Rate', 'Driver_Behavior_Score', 'Fatigue_Monitoring_Score', 'Supplier_Reliability_Score'] not in index"
2025-01-03 07:05:07,877 - CRITICAL - Pipeline execution failed: "['Traffic_Congestion_Level', 'Port_Congestion_Level', 'Fuel_Consumption_Rate', 'Driver_Behavior_Score', 'Fatigue_Monitoring_Score', 'Supplier_Reliability_Score'] not in index"
2025-01-03 07:06:03,891 - INFO - Starting preprocessing pipeline.
2025-01-03 07:06:03,947 - ERROR - An error occurred during preprocessing: "['Traffic_Congestion_Level', 'Port_Congestion_Level', 'Fuel_Consumption_Rate', 'Driver_Behavior_Score', 'Fatigue_Monitoring_Score', 'Supplier_Reliability_Score'] not in index"
Traceback (most recent call last):
  File "/workspaces/invenlytics/pipelines/v2/feature_pipeline.py", line 37, in run_supplychain_disruption_feature_pipeline
    data = data[selected_columns]
           ~~~~^^^^^^^^^^^^^^^^^^
  File "/home/codespace/.local/lib/python3.12/site-packages/pandas/core/frame.py", line 4108, in __getitem__
    indexer = self.columns._get_indexer_strict(key, "columns")[1]
              ^^^^^^^^^^^^^^^^^^^^^^^^^^^^^^^^^^^^^^^^^^^^^^^^
  File "/home/codespace/.local/lib/python3.12/site-packages/pandas/core/indexes/base.py", line 6200, in _get_indexer_strict
    self._raise_if_missing(keyarr, indexer, axis_name)
  File "/home/codespace/.local/lib/python3.12/site-packages/pandas/core/indexes/base.py", line 6252, in _raise_if_missing
    raise KeyError(f"{not_found} not in index")
KeyError: "['Traffic_Congestion_Level', 'Port_Congestion_Level', 'Fuel_Consumption_Rate', 'Driver_Behavior_Score', 'Fatigue_Monitoring_Score', 'Supplier_Reliability_Score'] not in index"
2025-01-03 07:06:03,950 - CRITICAL - Pipeline execution failed: "['Traffic_Congestion_Level', 'Port_Congestion_Level', 'Fuel_Consumption_Rate', 'Driver_Behavior_Score', 'Fatigue_Monitoring_Score', 'Supplier_Reliability_Score'] not in index"
2025-01-03 07:06:36,770 - INFO - Starting preprocessing pipeline.
2025-01-03 07:06:36,917 - INFO - None
2025-01-03 07:06:36,918 - ERROR - An error occurred during preprocessing: "['Traffic_Congestion_Level', 'Port_Congestion_Level', 'Fuel_Consumption_Rate', 'Driver_Behavior_Score', 'Fatigue_Monitoring_Score', 'Supplier_Reliability_Score'] not in index"
Traceback (most recent call last):
  File "/workspaces/invenlytics/pipelines/v2/feature_pipeline.py", line 38, in run_supplychain_disruption_feature_pipeline
    data = data[selected_columns]
           ~~~~^^^^^^^^^^^^^^^^^^
  File "/home/codespace/.local/lib/python3.12/site-packages/pandas/core/frame.py", line 4108, in __getitem__
    indexer = self.columns._get_indexer_strict(key, "columns")[1]
              ^^^^^^^^^^^^^^^^^^^^^^^^^^^^^^^^^^^^^^^^^^^^^^^^
  File "/home/codespace/.local/lib/python3.12/site-packages/pandas/core/indexes/base.py", line 6200, in _get_indexer_strict
    self._raise_if_missing(keyarr, indexer, axis_name)
  File "/home/codespace/.local/lib/python3.12/site-packages/pandas/core/indexes/base.py", line 6252, in _raise_if_missing
    raise KeyError(f"{not_found} not in index")
KeyError: "['Traffic_Congestion_Level', 'Port_Congestion_Level', 'Fuel_Consumption_Rate', 'Driver_Behavior_Score', 'Fatigue_Monitoring_Score', 'Supplier_Reliability_Score'] not in index"
2025-01-03 07:06:36,926 - CRITICAL - Pipeline execution failed: "['Traffic_Congestion_Level', 'Port_Congestion_Level', 'Fuel_Consumption_Rate', 'Driver_Behavior_Score', 'Fatigue_Monitoring_Score', 'Supplier_Reliability_Score'] not in index"
2025-01-03 07:08:07,532 - INFO - Starting preprocessing pipeline.
2025-01-03 07:08:07,630 - INFO - None
2025-01-03 07:08:07,630 - ERROR - An error occurred during preprocessing: "['Traffic_Congestion_Level', 'Port_Congestion_Level', 'Fuel_Consumption_Rate', 'Driver_Behavior_Score', 'Fatigue_Monitoring_Score', 'Supplier_Reliability_Score'] not in index"
Traceback (most recent call last):
  File "/workspaces/invenlytics/pipelines/v2/feature_pipeline.py", line 38, in run_supplychain_disruption_feature_pipeline
    data = data[selected_columns]
           ~~~~^^^^^^^^^^^^^^^^^^
  File "/home/codespace/.local/lib/python3.12/site-packages/pandas/core/frame.py", line 4108, in __getitem__
    indexer = self.columns._get_indexer_strict(key, "columns")[1]
              ^^^^^^^^^^^^^^^^^^^^^^^^^^^^^^^^^^^^^^^^^^^^^^^^
  File "/home/codespace/.local/lib/python3.12/site-packages/pandas/core/indexes/base.py", line 6200, in _get_indexer_strict
    self._raise_if_missing(keyarr, indexer, axis_name)
  File "/home/codespace/.local/lib/python3.12/site-packages/pandas/core/indexes/base.py", line 6252, in _raise_if_missing
    raise KeyError(f"{not_found} not in index")
KeyError: "['Traffic_Congestion_Level', 'Port_Congestion_Level', 'Fuel_Consumption_Rate', 'Driver_Behavior_Score', 'Fatigue_Monitoring_Score', 'Supplier_Reliability_Score'] not in index"
2025-01-03 07:08:07,634 - CRITICAL - Pipeline execution failed: "['Traffic_Congestion_Level', 'Port_Congestion_Level', 'Fuel_Consumption_Rate', 'Driver_Behavior_Score', 'Fatigue_Monitoring_Score', 'Supplier_Reliability_Score'] not in index"
2025-01-03 07:09:37,847 - INFO - Starting preprocessing pipeline.
2025-01-03 07:09:37,934 - INFO - None
2025-01-03 07:09:37,935 - ERROR - An error occurred during preprocessing: "['port_pongestion_level'] not in index"
Traceback (most recent call last):
  File "/workspaces/invenlytics/pipelines/v2/feature_pipeline.py", line 38, in run_supplychain_disruption_feature_pipeline
    data = data[selected_columns]
           ~~~~^^^^^^^^^^^^^^^^^^
  File "/home/codespace/.local/lib/python3.12/site-packages/pandas/core/frame.py", line 4108, in __getitem__
    indexer = self.columns._get_indexer_strict(key, "columns")[1]
              ^^^^^^^^^^^^^^^^^^^^^^^^^^^^^^^^^^^^^^^^^^^^^^^^
  File "/home/codespace/.local/lib/python3.12/site-packages/pandas/core/indexes/base.py", line 6200, in _get_indexer_strict
    self._raise_if_missing(keyarr, indexer, axis_name)
  File "/home/codespace/.local/lib/python3.12/site-packages/pandas/core/indexes/base.py", line 6252, in _raise_if_missing
    raise KeyError(f"{not_found} not in index")
KeyError: "['port_pongestion_level'] not in index"
2025-01-03 07:09:37,938 - CRITICAL - Pipeline execution failed: "['port_pongestion_level'] not in index"
2025-01-03 07:11:51,833 - INFO - Starting preprocessing pipeline.
2025-01-03 07:11:51,948 - INFO - None
2025-01-03 07:11:51,989 - INFO - Dataset loaded successfully. None
2025-01-03 07:11:52,022 - INFO - Target encoding completed.
2025-01-03 07:11:52,084 - INFO - Categorical encoding completed.
2025-01-03 07:11:52,125 - INFO - Holiday-related features created.
2025-01-03 07:11:52,147 - INFO - Normalization completed.
2025-01-03 07:11:52,185 - INFO - Rolling and expanding features generated.
2025-01-03 07:11:52,198 - INFO - Lag features generated.
2025-01-03 07:11:52,230 - INFO - Dropped NaN values. Preprocessing complete.
2025-01-03 07:11:52,406 - INFO - Processed dataset saved to /workspaces/invenlytics/data/gold_layer/SupplyChain_DisruptionFeatures.parquet. None
2025-01-03 07:11:52,407 - INFO - Feature pipeline executed successfully.
2025-01-03 08:53:40,378 - INFO - Starting preprocessing pipeline.
2025-01-03 08:53:40,693 - INFO - None
2025-01-03 08:53:40,750 - INFO - Dataset loaded successfully. None
2025-01-03 08:53:40,796 - INFO - Target encoding completed.
2025-01-03 08:53:40,856 - INFO - Categorical encoding completed.
2025-01-03 08:53:40,899 - INFO - Holiday-related features created.
2025-01-03 08:53:40,914 - INFO - Normalization completed.
2025-01-03 08:53:40,936 - INFO - Rolling and expanding features generated.
2025-01-03 08:53:40,946 - INFO - Lag features generated.
2025-01-03 08:53:40,987 - INFO - Dropped NaN values. Preprocessing complete.
2025-01-03 08:53:41,157 - INFO - Processed dataset saved to /workspaces/invenlytics/data/gold_layer/SupplyChain_DisruptionFeatures.parquet. None
2025-01-03 08:53:41,157 - INFO - Feature pipeline executed successfully.
2025-01-05 05:18:48,689 - INFO - Starting preprocessing pipeline.
2025-01-05 05:18:48,887 - INFO - None
2025-01-05 05:18:48,929 - INFO - Dataset loaded successfully. None
2025-01-05 05:18:48,992 - INFO - Target encoding completed.
2025-01-05 05:18:49,095 - INFO - Categorical encoding completed.
2025-01-05 05:18:49,136 - INFO - Holiday-related features created.
2025-01-05 05:18:49,149 - INFO - Normalization completed.
2025-01-05 05:18:49,173 - INFO - Rolling and expanding features generated.
2025-01-05 05:18:49,183 - INFO - Lag features generated.
2025-01-05 05:18:49,207 - INFO - Dropped NaN values. Preprocessing complete.
2025-01-05 05:18:49,360 - ERROR - An error occurred during preprocessing: float() argument must be a string or a real number, not 'Timestamp'
Traceback (most recent call last):
  File "/workspaces/invenlytics/pipelines/v2/feature_pipeline.py", line 128, in run_supplychain_disruption_feature_pipeline
    X_resampled, y_resampled = smote_enn.fit_resample(X, y)
                               ^^^^^^^^^^^^^^^^^^^^^^^^^^^^
  File "/usr/local/python/3.12.1/lib/python3.12/site-packages/imblearn/base.py", line 202, in fit_resample
    return super().fit_resample(X, y, **params)
           ^^^^^^^^^^^^^^^^^^^^^^^^^^^^^^^^^^^^
  File "/usr/local/python/3.12.1/lib/python3.12/site-packages/sklearn/base.py", line 1473, in wrapper
    return fit_method(estimator, *args, **kwargs)
           ^^^^^^^^^^^^^^^^^^^^^^^^^^^^^^^^^^^^^^
  File "/usr/local/python/3.12.1/lib/python3.12/site-packages/imblearn/base.py", line 105, in fit_resample
    output = self._fit_resample(X, y, **params)
             ^^^^^^^^^^^^^^^^^^^^^^^^^^^^^^^^^^
  File "/usr/local/python/3.12.1/lib/python3.12/site-packages/imblearn/combine/_smote_enn.py", line 156, in _fit_resample
    X, y = check_X_y(X, y, accept_sparse=["csr", "csc"])
           ^^^^^^^^^^^^^^^^^^^^^^^^^^^^^^^^^^^^^^^^^^^^^
  File "/usr/local/python/3.12.1/lib/python3.12/site-packages/sklearn/utils/validation.py", line 1301, in check_X_y
    X = check_array(
        ^^^^^^^^^^^^
  File "/usr/local/python/3.12.1/lib/python3.12/site-packages/sklearn/utils/validation.py", line 1012, in check_array
    array = _asarray_with_order(array, order=order, dtype=dtype, xp=xp)
            ^^^^^^^^^^^^^^^^^^^^^^^^^^^^^^^^^^^^^^^^^^^^^^^^^^^^^^^^^^^
  File "/usr/local/python/3.12.1/lib/python3.12/site-packages/sklearn/utils/_array_api.py", line 745, in _asarray_with_order
    array = numpy.asarray(array, order=order, dtype=dtype)
            ^^^^^^^^^^^^^^^^^^^^^^^^^^^^^^^^^^^^^^^^^^^^^^
TypeError: float() argument must be a string or a real number, not 'Timestamp'
2025-01-05 05:18:49,369 - CRITICAL - Pipeline execution failed: float() argument must be a string or a real number, not 'Timestamp'
2025-01-05 05:21:28,493 - INFO - Starting preprocessing pipeline.
2025-01-05 05:21:28,618 - INFO - None
2025-01-05 05:21:28,661 - INFO - Dataset loaded successfully. None
2025-01-05 05:21:28,692 - INFO - Target encoding completed.
2025-01-05 05:21:28,747 - INFO - Categorical encoding completed.
2025-01-05 05:21:28,794 - INFO - Holiday-related features created.
2025-01-05 05:21:28,808 - INFO - Normalization completed.
2025-01-05 05:21:28,832 - INFO - Rolling and expanding features generated.
2025-01-05 05:21:28,841 - INFO - Lag features generated.
2025-01-05 05:21:28,870 - INFO - Dropped NaN values. Preprocessing complete.
2025-01-05 05:21:28,985 - ERROR - An error occurred during preprocessing: could not convert string to float: 'Weather'
Traceback (most recent call last):
  File "/workspaces/invenlytics/pipelines/v2/feature_pipeline.py", line 129, in run_supplychain_disruption_feature_pipeline
    X_resampled, y_resampled = smote_enn.fit_resample(X, y)
                               ^^^^^^^^^^^^^^^^^^^^^^^^^^^^
  File "/usr/local/python/3.12.1/lib/python3.12/site-packages/imblearn/base.py", line 202, in fit_resample
    return super().fit_resample(X, y, **params)
           ^^^^^^^^^^^^^^^^^^^^^^^^^^^^^^^^^^^^
  File "/usr/local/python/3.12.1/lib/python3.12/site-packages/sklearn/base.py", line 1473, in wrapper
    return fit_method(estimator, *args, **kwargs)
           ^^^^^^^^^^^^^^^^^^^^^^^^^^^^^^^^^^^^^^
  File "/usr/local/python/3.12.1/lib/python3.12/site-packages/imblearn/base.py", line 105, in fit_resample
    output = self._fit_resample(X, y, **params)
             ^^^^^^^^^^^^^^^^^^^^^^^^^^^^^^^^^^
  File "/usr/local/python/3.12.1/lib/python3.12/site-packages/imblearn/combine/_smote_enn.py", line 156, in _fit_resample
    X, y = check_X_y(X, y, accept_sparse=["csr", "csc"])
           ^^^^^^^^^^^^^^^^^^^^^^^^^^^^^^^^^^^^^^^^^^^^^
  File "/usr/local/python/3.12.1/lib/python3.12/site-packages/sklearn/utils/validation.py", line 1301, in check_X_y
    X = check_array(
        ^^^^^^^^^^^^
  File "/usr/local/python/3.12.1/lib/python3.12/site-packages/sklearn/utils/validation.py", line 1012, in check_array
    array = _asarray_with_order(array, order=order, dtype=dtype, xp=xp)
            ^^^^^^^^^^^^^^^^^^^^^^^^^^^^^^^^^^^^^^^^^^^^^^^^^^^^^^^^^^^
  File "/usr/local/python/3.12.1/lib/python3.12/site-packages/sklearn/utils/_array_api.py", line 745, in _asarray_with_order
    array = numpy.asarray(array, order=order, dtype=dtype)
            ^^^^^^^^^^^^^^^^^^^^^^^^^^^^^^^^^^^^^^^^^^^^^^
ValueError: could not convert string to float: 'Weather'
2025-01-05 05:21:28,991 - CRITICAL - Pipeline execution failed: could not convert string to float: 'Weather'
2025-01-05 05:22:54,762 - INFO - Starting preprocessing pipeline.
2025-01-05 05:22:54,993 - INFO - None
2025-01-05 05:22:55,035 - INFO - Dataset loaded successfully. None
2025-01-05 05:22:55,066 - INFO - Target encoding completed.
2025-01-05 05:22:55,115 - INFO - Categorical encoding completed.
2025-01-05 05:22:55,163 - INFO - Holiday-related features created.
2025-01-05 05:22:55,179 - INFO - Normalization completed.
2025-01-05 05:22:55,209 - INFO - Rolling and expanding features generated.
2025-01-05 05:22:55,219 - INFO - Lag features generated.
2025-01-05 05:22:55,246 - INFO - Dropped NaN values. Preprocessing complete.
2025-01-05 05:22:55,347 - ERROR - An error occurred during preprocessing: could not convert string to float: 'Weather'
Traceback (most recent call last):
  File "/workspaces/invenlytics/pipelines/v2/feature_pipeline.py", line 130, in run_supplychain_disruption_feature_pipeline
    X_resampled, y_resampled = smote_enn.fit_resample(X, y)
                               ^^^^^^^^^^^^^^^^^^^^^^^^^^^^
  File "/usr/local/python/3.12.1/lib/python3.12/site-packages/imblearn/base.py", line 202, in fit_resample
    return super().fit_resample(X, y, **params)
           ^^^^^^^^^^^^^^^^^^^^^^^^^^^^^^^^^^^^
  File "/usr/local/python/3.12.1/lib/python3.12/site-packages/sklearn/base.py", line 1473, in wrapper
    return fit_method(estimator, *args, **kwargs)
           ^^^^^^^^^^^^^^^^^^^^^^^^^^^^^^^^^^^^^^
  File "/usr/local/python/3.12.1/lib/python3.12/site-packages/imblearn/base.py", line 105, in fit_resample
    output = self._fit_resample(X, y, **params)
             ^^^^^^^^^^^^^^^^^^^^^^^^^^^^^^^^^^
  File "/usr/local/python/3.12.1/lib/python3.12/site-packages/imblearn/combine/_smote_enn.py", line 156, in _fit_resample
    X, y = check_X_y(X, y, accept_sparse=["csr", "csc"])
           ^^^^^^^^^^^^^^^^^^^^^^^^^^^^^^^^^^^^^^^^^^^^^
  File "/usr/local/python/3.12.1/lib/python3.12/site-packages/sklearn/utils/validation.py", line 1301, in check_X_y
    X = check_array(
        ^^^^^^^^^^^^
  File "/usr/local/python/3.12.1/lib/python3.12/site-packages/sklearn/utils/validation.py", line 1012, in check_array
    array = _asarray_with_order(array, order=order, dtype=dtype, xp=xp)
            ^^^^^^^^^^^^^^^^^^^^^^^^^^^^^^^^^^^^^^^^^^^^^^^^^^^^^^^^^^^
  File "/usr/local/python/3.12.1/lib/python3.12/site-packages/sklearn/utils/_array_api.py", line 745, in _asarray_with_order
    array = numpy.asarray(array, order=order, dtype=dtype)
            ^^^^^^^^^^^^^^^^^^^^^^^^^^^^^^^^^^^^^^^^^^^^^^
ValueError: could not convert string to float: 'Weather'
2025-01-05 05:22:55,349 - CRITICAL - Pipeline execution failed: could not convert string to float: 'Weather'
2025-01-05 05:23:54,430 - INFO - Starting preprocessing pipeline.
2025-01-05 05:23:54,515 - INFO - None
2025-01-05 05:23:54,547 - INFO - Dataset loaded successfully. None
2025-01-05 05:23:54,579 - INFO - Target encoding completed.
2025-01-05 05:23:54,646 - INFO - Categorical encoding completed.
2025-01-05 05:23:54,685 - INFO - Holiday-related features created.
2025-01-05 05:23:54,700 - INFO - Normalization completed.
2025-01-05 05:23:54,722 - INFO - Rolling and expanding features generated.
2025-01-05 05:23:54,732 - INFO - Lag features generated.
2025-01-05 05:23:54,762 - INFO - Dropped NaN values. Preprocessing complete.
2025-01-05 05:23:54,862 - ERROR - An error occurred during preprocessing: could not convert string to float: 'Weather'
Traceback (most recent call last):
  File "/workspaces/invenlytics/pipelines/v2/feature_pipeline.py", line 130, in run_supplychain_disruption_feature_pipeline
    X_resampled, y_resampled = smote_enn.fit_resample(X, y)
                               ^^^^^^^^^^^^^^^^^^^^^^^^^^^^
  File "/usr/local/python/3.12.1/lib/python3.12/site-packages/imblearn/base.py", line 202, in fit_resample
    return super().fit_resample(X, y, **params)
           ^^^^^^^^^^^^^^^^^^^^^^^^^^^^^^^^^^^^
  File "/usr/local/python/3.12.1/lib/python3.12/site-packages/sklearn/base.py", line 1473, in wrapper
    return fit_method(estimator, *args, **kwargs)
           ^^^^^^^^^^^^^^^^^^^^^^^^^^^^^^^^^^^^^^
  File "/usr/local/python/3.12.1/lib/python3.12/site-packages/imblearn/base.py", line 105, in fit_resample
    output = self._fit_resample(X, y, **params)
             ^^^^^^^^^^^^^^^^^^^^^^^^^^^^^^^^^^
  File "/usr/local/python/3.12.1/lib/python3.12/site-packages/imblearn/combine/_smote_enn.py", line 156, in _fit_resample
    X, y = check_X_y(X, y, accept_sparse=["csr", "csc"])
           ^^^^^^^^^^^^^^^^^^^^^^^^^^^^^^^^^^^^^^^^^^^^^
  File "/usr/local/python/3.12.1/lib/python3.12/site-packages/sklearn/utils/validation.py", line 1301, in check_X_y
    X = check_array(
        ^^^^^^^^^^^^
  File "/usr/local/python/3.12.1/lib/python3.12/site-packages/sklearn/utils/validation.py", line 1012, in check_array
    array = _asarray_with_order(array, order=order, dtype=dtype, xp=xp)
            ^^^^^^^^^^^^^^^^^^^^^^^^^^^^^^^^^^^^^^^^^^^^^^^^^^^^^^^^^^^
  File "/usr/local/python/3.12.1/lib/python3.12/site-packages/sklearn/utils/_array_api.py", line 745, in _asarray_with_order
    array = numpy.asarray(array, order=order, dtype=dtype)
            ^^^^^^^^^^^^^^^^^^^^^^^^^^^^^^^^^^^^^^^^^^^^^^
ValueError: could not convert string to float: 'Weather'
2025-01-05 05:23:54,864 - CRITICAL - Pipeline execution failed: could not convert string to float: 'Weather'
2025-01-05 05:24:27,676 - INFO - Starting preprocessing pipeline.
2025-01-05 05:24:27,803 - INFO - None
2025-01-05 05:24:27,835 - INFO - Dataset loaded successfully. None
2025-01-05 05:24:27,866 - INFO - Target encoding completed.
2025-01-05 05:24:27,935 - INFO - Categorical encoding completed.
2025-01-05 05:24:28,036 - INFO - Holiday-related features created.
2025-01-05 05:24:28,050 - INFO - Normalization completed.
2025-01-05 05:24:28,082 - INFO - Rolling and expanding features generated.
2025-01-05 05:24:28,094 - INFO - Lag features generated.
2025-01-05 05:24:28,128 - INFO - Dropped NaN values. Preprocessing complete.
2025-01-05 05:24:28,275 - ERROR - An error occurred during preprocessing: could not convert string to float: 'Weather'
Traceback (most recent call last):
  File "/workspaces/invenlytics/pipelines/v2/feature_pipeline.py", line 130, in run_supplychain_disruption_feature_pipeline
    X_resampled, y_resampled = smote_enn.fit_resample(X, y)
                               ^^^^^^^^^^^^^^^^^^^^^^^^^^^^
  File "/usr/local/python/3.12.1/lib/python3.12/site-packages/imblearn/base.py", line 202, in fit_resample
    return super().fit_resample(X, y, **params)
           ^^^^^^^^^^^^^^^^^^^^^^^^^^^^^^^^^^^^
  File "/usr/local/python/3.12.1/lib/python3.12/site-packages/sklearn/base.py", line 1473, in wrapper
    return fit_method(estimator, *args, **kwargs)
           ^^^^^^^^^^^^^^^^^^^^^^^^^^^^^^^^^^^^^^
  File "/usr/local/python/3.12.1/lib/python3.12/site-packages/imblearn/base.py", line 105, in fit_resample
    output = self._fit_resample(X, y, **params)
             ^^^^^^^^^^^^^^^^^^^^^^^^^^^^^^^^^^
  File "/usr/local/python/3.12.1/lib/python3.12/site-packages/imblearn/combine/_smote_enn.py", line 156, in _fit_resample
    X, y = check_X_y(X, y, accept_sparse=["csr", "csc"])
           ^^^^^^^^^^^^^^^^^^^^^^^^^^^^^^^^^^^^^^^^^^^^^
  File "/usr/local/python/3.12.1/lib/python3.12/site-packages/sklearn/utils/validation.py", line 1301, in check_X_y
    X = check_array(
        ^^^^^^^^^^^^
  File "/usr/local/python/3.12.1/lib/python3.12/site-packages/sklearn/utils/validation.py", line 1012, in check_array
    array = _asarray_with_order(array, order=order, dtype=dtype, xp=xp)
            ^^^^^^^^^^^^^^^^^^^^^^^^^^^^^^^^^^^^^^^^^^^^^^^^^^^^^^^^^^^
  File "/usr/local/python/3.12.1/lib/python3.12/site-packages/sklearn/utils/_array_api.py", line 745, in _asarray_with_order
    array = numpy.asarray(array, order=order, dtype=dtype)
            ^^^^^^^^^^^^^^^^^^^^^^^^^^^^^^^^^^^^^^^^^^^^^^
ValueError: could not convert string to float: 'Weather'
2025-01-05 05:24:28,277 - CRITICAL - Pipeline execution failed: could not convert string to float: 'Weather'
2025-01-05 05:25:00,443 - INFO - Starting preprocessing pipeline.
2025-01-05 05:25:00,559 - INFO - None
2025-01-05 05:25:00,591 - INFO - Dataset loaded successfully. None
2025-01-05 05:25:00,624 - INFO - Target encoding completed.
2025-01-05 05:25:00,679 - INFO - Categorical encoding completed.
2025-01-05 05:25:00,746 - INFO - Holiday-related features created.
2025-01-05 05:25:00,769 - INFO - Normalization completed.
2025-01-05 05:25:00,793 - INFO - Rolling and expanding features generated.
2025-01-05 05:25:00,804 - INFO - Lag features generated.
2025-01-05 05:25:00,832 - INFO - Dropped NaN values. Preprocessing complete.
2025-01-05 05:25:01,024 - ERROR - An error occurred during preprocessing: could not convert string to float: 'Weather'
Traceback (most recent call last):
  File "/workspaces/invenlytics/pipelines/v2/feature_pipeline.py", line 131, in run_supplychain_disruption_feature_pipeline
    X_resampled, y_resampled = smote_enn.fit_resample(X, y)
                               ^^^^^^^^^^^^^^^^^^^^^^^^^^^^
  File "/usr/local/python/3.12.1/lib/python3.12/site-packages/imblearn/base.py", line 202, in fit_resample
    return super().fit_resample(X, y, **params)
           ^^^^^^^^^^^^^^^^^^^^^^^^^^^^^^^^^^^^
  File "/usr/local/python/3.12.1/lib/python3.12/site-packages/sklearn/base.py", line 1473, in wrapper
    return fit_method(estimator, *args, **kwargs)
           ^^^^^^^^^^^^^^^^^^^^^^^^^^^^^^^^^^^^^^
  File "/usr/local/python/3.12.1/lib/python3.12/site-packages/imblearn/base.py", line 105, in fit_resample
    output = self._fit_resample(X, y, **params)
             ^^^^^^^^^^^^^^^^^^^^^^^^^^^^^^^^^^
  File "/usr/local/python/3.12.1/lib/python3.12/site-packages/imblearn/combine/_smote_enn.py", line 156, in _fit_resample
    X, y = check_X_y(X, y, accept_sparse=["csr", "csc"])
           ^^^^^^^^^^^^^^^^^^^^^^^^^^^^^^^^^^^^^^^^^^^^^
  File "/usr/local/python/3.12.1/lib/python3.12/site-packages/sklearn/utils/validation.py", line 1301, in check_X_y
    X = check_array(
        ^^^^^^^^^^^^
  File "/usr/local/python/3.12.1/lib/python3.12/site-packages/sklearn/utils/validation.py", line 1012, in check_array
    array = _asarray_with_order(array, order=order, dtype=dtype, xp=xp)
            ^^^^^^^^^^^^^^^^^^^^^^^^^^^^^^^^^^^^^^^^^^^^^^^^^^^^^^^^^^^
  File "/usr/local/python/3.12.1/lib/python3.12/site-packages/sklearn/utils/_array_api.py", line 745, in _asarray_with_order
    array = numpy.asarray(array, order=order, dtype=dtype)
            ^^^^^^^^^^^^^^^^^^^^^^^^^^^^^^^^^^^^^^^^^^^^^^
ValueError: could not convert string to float: 'Weather'
2025-01-05 05:25:01,027 - CRITICAL - Pipeline execution failed: could not convert string to float: 'Weather'
2025-01-05 05:26:16,952 - INFO - Starting preprocessing pipeline.
2025-01-05 05:26:17,051 - INFO - None
2025-01-05 05:26:17,084 - INFO - Dataset loaded successfully. None
2025-01-05 05:26:17,116 - INFO - Target encoding completed.
2025-01-05 05:26:17,168 - INFO - Categorical encoding completed.
2025-01-05 05:26:17,207 - INFO - Holiday-related features created.
2025-01-05 05:26:17,221 - INFO - Normalization completed.
2025-01-05 05:26:17,244 - INFO - Rolling and expanding features generated.
2025-01-05 05:26:17,254 - INFO - Lag features generated.
2025-01-05 05:26:17,282 - INFO - Dropped NaN values. Preprocessing complete.
2025-01-05 05:26:17,395 - ERROR - An error occurred during preprocessing: could not convert string to float: 'Weather'
Traceback (most recent call last):
  File "/workspaces/invenlytics/pipelines/v2/feature_pipeline.py", line 131, in run_supplychain_disruption_feature_pipeline
    X_resampled, y_resampled = smote_enn.fit_resample(X, y)
                               ^^^^^^^^^^^^^^^^^^^^^^^^^^^^
  File "/usr/local/python/3.12.1/lib/python3.12/site-packages/imblearn/base.py", line 202, in fit_resample
    return super().fit_resample(X, y, **params)
           ^^^^^^^^^^^^^^^^^^^^^^^^^^^^^^^^^^^^
  File "/usr/local/python/3.12.1/lib/python3.12/site-packages/sklearn/base.py", line 1473, in wrapper
    return fit_method(estimator, *args, **kwargs)
           ^^^^^^^^^^^^^^^^^^^^^^^^^^^^^^^^^^^^^^
  File "/usr/local/python/3.12.1/lib/python3.12/site-packages/imblearn/base.py", line 105, in fit_resample
    output = self._fit_resample(X, y, **params)
             ^^^^^^^^^^^^^^^^^^^^^^^^^^^^^^^^^^
  File "/usr/local/python/3.12.1/lib/python3.12/site-packages/imblearn/combine/_smote_enn.py", line 156, in _fit_resample
    X, y = check_X_y(X, y, accept_sparse=["csr", "csc"])
           ^^^^^^^^^^^^^^^^^^^^^^^^^^^^^^^^^^^^^^^^^^^^^
  File "/usr/local/python/3.12.1/lib/python3.12/site-packages/sklearn/utils/validation.py", line 1301, in check_X_y
    X = check_array(
        ^^^^^^^^^^^^
  File "/usr/local/python/3.12.1/lib/python3.12/site-packages/sklearn/utils/validation.py", line 1012, in check_array
    array = _asarray_with_order(array, order=order, dtype=dtype, xp=xp)
            ^^^^^^^^^^^^^^^^^^^^^^^^^^^^^^^^^^^^^^^^^^^^^^^^^^^^^^^^^^^
  File "/usr/local/python/3.12.1/lib/python3.12/site-packages/sklearn/utils/_array_api.py", line 745, in _asarray_with_order
    array = numpy.asarray(array, order=order, dtype=dtype)
            ^^^^^^^^^^^^^^^^^^^^^^^^^^^^^^^^^^^^^^^^^^^^^^
ValueError: could not convert string to float: 'Weather'
2025-01-05 05:26:17,397 - CRITICAL - Pipeline execution failed: could not convert string to float: 'Weather'
2025-01-05 05:28:01,558 - INFO - Starting preprocessing pipeline.
2025-01-05 05:28:01,645 - INFO - None
2025-01-05 05:28:01,679 - INFO - Dataset loaded successfully. None
2025-01-05 05:28:01,711 - INFO - Target encoding completed.
2025-01-05 05:28:01,765 - INFO - Categorical encoding completed.
2025-01-05 05:28:01,805 - INFO - Holiday-related features created.
2025-01-05 05:28:01,818 - INFO - Normalization completed.
2025-01-05 05:28:01,841 - INFO - Rolling and expanding features generated.
2025-01-05 05:28:01,851 - INFO - Lag features generated.
2025-01-05 05:28:01,881 - INFO - Dropped NaN values. Preprocessing complete.
2025-01-05 05:28:02,023 - ERROR - An error occurred during preprocessing: could not convert string to float: 'Weather'
Traceback (most recent call last):
  File "/workspaces/invenlytics/pipelines/v2/feature_pipeline.py", line 131, in run_supplychain_disruption_feature_pipeline
    X_resampled, y_resampled = smote_enn.fit_resample(X, y)
                               ^^^^^^^^^^^^^^^^^^^^^^^^^^^^
  File "/usr/local/python/3.12.1/lib/python3.12/site-packages/imblearn/base.py", line 202, in fit_resample
    return super().fit_resample(X, y, **params)
           ^^^^^^^^^^^^^^^^^^^^^^^^^^^^^^^^^^^^
  File "/usr/local/python/3.12.1/lib/python3.12/site-packages/sklearn/base.py", line 1473, in wrapper
    return fit_method(estimator, *args, **kwargs)
           ^^^^^^^^^^^^^^^^^^^^^^^^^^^^^^^^^^^^^^
  File "/usr/local/python/3.12.1/lib/python3.12/site-packages/imblearn/base.py", line 105, in fit_resample
    output = self._fit_resample(X, y, **params)
             ^^^^^^^^^^^^^^^^^^^^^^^^^^^^^^^^^^
  File "/usr/local/python/3.12.1/lib/python3.12/site-packages/imblearn/combine/_smote_enn.py", line 156, in _fit_resample
    X, y = check_X_y(X, y, accept_sparse=["csr", "csc"])
           ^^^^^^^^^^^^^^^^^^^^^^^^^^^^^^^^^^^^^^^^^^^^^
  File "/usr/local/python/3.12.1/lib/python3.12/site-packages/sklearn/utils/validation.py", line 1301, in check_X_y
    X = check_array(
        ^^^^^^^^^^^^
  File "/usr/local/python/3.12.1/lib/python3.12/site-packages/sklearn/utils/validation.py", line 1012, in check_array
    array = _asarray_with_order(array, order=order, dtype=dtype, xp=xp)
            ^^^^^^^^^^^^^^^^^^^^^^^^^^^^^^^^^^^^^^^^^^^^^^^^^^^^^^^^^^^
  File "/usr/local/python/3.12.1/lib/python3.12/site-packages/sklearn/utils/_array_api.py", line 745, in _asarray_with_order
    array = numpy.asarray(array, order=order, dtype=dtype)
            ^^^^^^^^^^^^^^^^^^^^^^^^^^^^^^^^^^^^^^^^^^^^^^
ValueError: could not convert string to float: 'Weather'
2025-01-05 05:28:02,025 - CRITICAL - Pipeline execution failed: could not convert string to float: 'Weather'
2025-01-05 05:28:28,509 - INFO - Starting preprocessing pipeline.
2025-01-05 05:28:28,597 - INFO - None
2025-01-05 05:28:28,631 - INFO - Dataset loaded successfully. None
2025-01-05 05:28:28,664 - INFO - Target encoding completed.
2025-01-05 05:28:28,719 - INFO - Categorical encoding completed.
2025-01-05 05:28:28,759 - INFO - Holiday-related features created.
2025-01-05 05:28:28,773 - INFO - Normalization completed.
2025-01-05 05:28:28,797 - INFO - Rolling and expanding features generated.
2025-01-05 05:28:28,806 - INFO - Lag features generated.
2025-01-05 05:28:28,835 - INFO - Dropped NaN values. Preprocessing complete.
2025-01-05 05:28:28,992 - ERROR - An error occurred during preprocessing: could not convert string to float: 'Weather'
Traceback (most recent call last):
  File "/workspaces/invenlytics/pipelines/v2/feature_pipeline.py", line 131, in run_supplychain_disruption_feature_pipeline
    X_resampled, y_resampled = smote_enn.fit_resample(X, y)
                               ^^^^^^^^^^^^^^^^^^^^^^^^^^^^
  File "/usr/local/python/3.12.1/lib/python3.12/site-packages/imblearn/base.py", line 202, in fit_resample
    return super().fit_resample(X, y, **params)
           ^^^^^^^^^^^^^^^^^^^^^^^^^^^^^^^^^^^^
  File "/usr/local/python/3.12.1/lib/python3.12/site-packages/sklearn/base.py", line 1473, in wrapper
    return fit_method(estimator, *args, **kwargs)
           ^^^^^^^^^^^^^^^^^^^^^^^^^^^^^^^^^^^^^^
  File "/usr/local/python/3.12.1/lib/python3.12/site-packages/imblearn/base.py", line 105, in fit_resample
    output = self._fit_resample(X, y, **params)
             ^^^^^^^^^^^^^^^^^^^^^^^^^^^^^^^^^^
  File "/usr/local/python/3.12.1/lib/python3.12/site-packages/imblearn/combine/_smote_enn.py", line 156, in _fit_resample
    X, y = check_X_y(X, y, accept_sparse=["csr", "csc"])
           ^^^^^^^^^^^^^^^^^^^^^^^^^^^^^^^^^^^^^^^^^^^^^
  File "/usr/local/python/3.12.1/lib/python3.12/site-packages/sklearn/utils/validation.py", line 1301, in check_X_y
    X = check_array(
        ^^^^^^^^^^^^
  File "/usr/local/python/3.12.1/lib/python3.12/site-packages/sklearn/utils/validation.py", line 1012, in check_array
    array = _asarray_with_order(array, order=order, dtype=dtype, xp=xp)
            ^^^^^^^^^^^^^^^^^^^^^^^^^^^^^^^^^^^^^^^^^^^^^^^^^^^^^^^^^^^
  File "/usr/local/python/3.12.1/lib/python3.12/site-packages/sklearn/utils/_array_api.py", line 745, in _asarray_with_order
    array = numpy.asarray(array, order=order, dtype=dtype)
            ^^^^^^^^^^^^^^^^^^^^^^^^^^^^^^^^^^^^^^^^^^^^^^
ValueError: could not convert string to float: 'Weather'
2025-01-05 05:28:28,995 - CRITICAL - Pipeline execution failed: could not convert string to float: 'Weather'
2025-01-05 05:29:11,336 - INFO - Starting preprocessing pipeline.
2025-01-05 05:29:11,423 - INFO - None
2025-01-05 05:29:11,455 - INFO - Dataset loaded successfully. None
2025-01-05 05:29:11,487 - INFO - Target encoding completed.
2025-01-05 05:29:11,547 - INFO - Categorical encoding completed.
2025-01-05 05:29:11,586 - INFO - Holiday-related features created.
2025-01-05 05:29:11,600 - INFO - Normalization completed.
2025-01-05 05:29:11,624 - INFO - Rolling and expanding features generated.
2025-01-05 05:29:11,634 - INFO - Lag features generated.
2025-01-05 05:29:11,661 - INFO - Dropped NaN values. Preprocessing complete.
2025-01-05 05:29:27,392 - ERROR - An error occurred during preprocessing: cannot safely cast non-equivalent float64 to uint32
Traceback (most recent call last):
  File "/home/codespace/.local/lib/python3.12/site-packages/pandas/core/arrays/integer.py", line 53, in _safe_cast
    return values.astype(dtype, casting="safe", copy=copy)
           ^^^^^^^^^^^^^^^^^^^^^^^^^^^^^^^^^^^^^^^^^^^^^^^
TypeError: Cannot cast array data from dtype('float64') to dtype('uint32') according to the rule 'safe'

The above exception was the direct cause of the following exception:

Traceback (most recent call last):
  File "/usr/local/python/3.12.1/lib/python3.12/site-packages/imblearn/utils/_validation.py", line 71, in _transfrom_one
    ret = ret.astype(props["dtypes"])
          ^^^^^^^^^^^^^^^^^^^^^^^^^^^
  File "/home/codespace/.local/lib/python3.12/site-packages/pandas/core/generic.py", line 6620, in astype
    res_col = col.astype(dtype=cdt, copy=copy, errors=errors)
              ^^^^^^^^^^^^^^^^^^^^^^^^^^^^^^^^^^^^^^^^^^^^^^^
  File "/home/codespace/.local/lib/python3.12/site-packages/pandas/core/generic.py", line 6643, in astype
    new_data = self._mgr.astype(dtype=dtype, copy=copy, errors=errors)
               ^^^^^^^^^^^^^^^^^^^^^^^^^^^^^^^^^^^^^^^^^^^^^^^^^^^^^^^
  File "/home/codespace/.local/lib/python3.12/site-packages/pandas/core/internals/managers.py", line 430, in astype
    return self.apply(
           ^^^^^^^^^^^
  File "/home/codespace/.local/lib/python3.12/site-packages/pandas/core/internals/managers.py", line 363, in apply
    applied = getattr(b, f)(**kwargs)
              ^^^^^^^^^^^^^^^^^^^^^^^
  File "/home/codespace/.local/lib/python3.12/site-packages/pandas/core/internals/blocks.py", line 758, in astype
    new_values = astype_array_safe(values, dtype, copy=copy, errors=errors)
                 ^^^^^^^^^^^^^^^^^^^^^^^^^^^^^^^^^^^^^^^^^^^^^^^^^^^^^^^^^^
  File "/home/codespace/.local/lib/python3.12/site-packages/pandas/core/dtypes/astype.py", line 237, in astype_array_safe
    new_values = astype_array(values, dtype, copy=copy)
                 ^^^^^^^^^^^^^^^^^^^^^^^^^^^^^^^^^^^^^^
  File "/home/codespace/.local/lib/python3.12/site-packages/pandas/core/dtypes/astype.py", line 182, in astype_array
    values = _astype_nansafe(values, dtype, copy=copy)
             ^^^^^^^^^^^^^^^^^^^^^^^^^^^^^^^^^^^^^^^^^
  File "/home/codespace/.local/lib/python3.12/site-packages/pandas/core/dtypes/astype.py", line 80, in _astype_nansafe
    return dtype.construct_array_type()._from_sequence(arr, dtype=dtype, copy=copy)
           ^^^^^^^^^^^^^^^^^^^^^^^^^^^^^^^^^^^^^^^^^^^^^^^^^^^^^^^^^^^^^^^^^^^^^^^^
  File "/home/codespace/.local/lib/python3.12/site-packages/pandas/core/arrays/masked.py", line 152, in _from_sequence
    values, mask = cls._coerce_to_array(scalars, dtype=dtype, copy=copy)
                   ^^^^^^^^^^^^^^^^^^^^^^^^^^^^^^^^^^^^^^^^^^^^^^^^^^^^^
  File "/home/codespace/.local/lib/python3.12/site-packages/pandas/core/arrays/numeric.py", line 272, in _coerce_to_array
    values, mask, _, _ = _coerce_to_data_and_mask(
                         ^^^^^^^^^^^^^^^^^^^^^^^^^
  File "/home/codespace/.local/lib/python3.12/site-packages/pandas/core/arrays/numeric.py", line 229, in _coerce_to_data_and_mask
    values = dtype_cls._safe_cast(values, dtype, copy=False)
             ^^^^^^^^^^^^^^^^^^^^^^^^^^^^^^^^^^^^^^^^^^^^^^^
  File "/home/codespace/.local/lib/python3.12/site-packages/pandas/core/arrays/integer.py", line 59, in _safe_cast
    raise TypeError(
TypeError: cannot safely cast non-equivalent float64 to uint32

During handling of the above exception, another exception occurred:

Traceback (most recent call last):
  File "/home/codespace/.local/lib/python3.12/site-packages/pandas/core/arrays/integer.py", line 53, in _safe_cast
    return values.astype(dtype, casting="safe", copy=copy)
           ^^^^^^^^^^^^^^^^^^^^^^^^^^^^^^^^^^^^^^^^^^^^^^^
TypeError: Cannot cast array data from dtype('float64') to dtype('uint32') according to the rule 'safe'

The above exception was the direct cause of the following exception:

Traceback (most recent call last):
  File "/workspaces/invenlytics/pipelines/v2/feature_pipeline.py", line 131, in run_supplychain_disruption_feature_pipeline
    X_resampled, y_resampled = smote_enn.fit_resample(X, y)
                               ^^^^^^^^^^^^^^^^^^^^^^^^^^^^
  File "/usr/local/python/3.12.1/lib/python3.12/site-packages/imblearn/base.py", line 202, in fit_resample
    return super().fit_resample(X, y, **params)
           ^^^^^^^^^^^^^^^^^^^^^^^^^^^^^^^^^^^^
  File "/usr/local/python/3.12.1/lib/python3.12/site-packages/sklearn/base.py", line 1473, in wrapper
    return fit_method(estimator, *args, **kwargs)
           ^^^^^^^^^^^^^^^^^^^^^^^^^^^^^^^^^^^^^^
  File "/usr/local/python/3.12.1/lib/python3.12/site-packages/imblearn/base.py", line 111, in fit_resample
    X_, y_ = arrays_transformer.transform(output[0], y_)
             ^^^^^^^^^^^^^^^^^^^^^^^^^^^^^^^^^^^^^^^^^^^
  File "/usr/local/python/3.12.1/lib/python3.12/site-packages/imblearn/utils/_validation.py", line 40, in transform
    X = self._transfrom_one(X, self.x_props)
        ^^^^^^^^^^^^^^^^^^^^^^^^^^^^^^^^^^^^
  File "/usr/local/python/3.12.1/lib/python3.12/site-packages/imblearn/utils/_validation.py", line 86, in _transfrom_one
    ret = ret.astype(props["dtypes"])
          ^^^^^^^^^^^^^^^^^^^^^^^^^^^
  File "/home/codespace/.local/lib/python3.12/site-packages/pandas/core/generic.py", line 6620, in astype
    res_col = col.astype(dtype=cdt, copy=copy, errors=errors)
              ^^^^^^^^^^^^^^^^^^^^^^^^^^^^^^^^^^^^^^^^^^^^^^^
  File "/home/codespace/.local/lib/python3.12/site-packages/pandas/core/generic.py", line 6643, in astype
    new_data = self._mgr.astype(dtype=dtype, copy=copy, errors=errors)
               ^^^^^^^^^^^^^^^^^^^^^^^^^^^^^^^^^^^^^^^^^^^^^^^^^^^^^^^
  File "/home/codespace/.local/lib/python3.12/site-packages/pandas/core/internals/managers.py", line 430, in astype
    return self.apply(
           ^^^^^^^^^^^
  File "/home/codespace/.local/lib/python3.12/site-packages/pandas/core/internals/managers.py", line 363, in apply
    applied = getattr(b, f)(**kwargs)
              ^^^^^^^^^^^^^^^^^^^^^^^
  File "/home/codespace/.local/lib/python3.12/site-packages/pandas/core/internals/blocks.py", line 758, in astype
    new_values = astype_array_safe(values, dtype, copy=copy, errors=errors)
                 ^^^^^^^^^^^^^^^^^^^^^^^^^^^^^^^^^^^^^^^^^^^^^^^^^^^^^^^^^^
  File "/home/codespace/.local/lib/python3.12/site-packages/pandas/core/dtypes/astype.py", line 237, in astype_array_safe
    new_values = astype_array(values, dtype, copy=copy)
                 ^^^^^^^^^^^^^^^^^^^^^^^^^^^^^^^^^^^^^^
  File "/home/codespace/.local/lib/python3.12/site-packages/pandas/core/dtypes/astype.py", line 182, in astype_array
    values = _astype_nansafe(values, dtype, copy=copy)
             ^^^^^^^^^^^^^^^^^^^^^^^^^^^^^^^^^^^^^^^^^
  File "/home/codespace/.local/lib/python3.12/site-packages/pandas/core/dtypes/astype.py", line 80, in _astype_nansafe
    return dtype.construct_array_type()._from_sequence(arr, dtype=dtype, copy=copy)
           ^^^^^^^^^^^^^^^^^^^^^^^^^^^^^^^^^^^^^^^^^^^^^^^^^^^^^^^^^^^^^^^^^^^^^^^^
  File "/home/codespace/.local/lib/python3.12/site-packages/pandas/core/arrays/masked.py", line 152, in _from_sequence
    values, mask = cls._coerce_to_array(scalars, dtype=dtype, copy=copy)
                   ^^^^^^^^^^^^^^^^^^^^^^^^^^^^^^^^^^^^^^^^^^^^^^^^^^^^^
  File "/home/codespace/.local/lib/python3.12/site-packages/pandas/core/arrays/numeric.py", line 272, in _coerce_to_array
    values, mask, _, _ = _coerce_to_data_and_mask(
                         ^^^^^^^^^^^^^^^^^^^^^^^^^
  File "/home/codespace/.local/lib/python3.12/site-packages/pandas/core/arrays/numeric.py", line 229, in _coerce_to_data_and_mask
    values = dtype_cls._safe_cast(values, dtype, copy=False)
             ^^^^^^^^^^^^^^^^^^^^^^^^^^^^^^^^^^^^^^^^^^^^^^^
  File "/home/codespace/.local/lib/python3.12/site-packages/pandas/core/arrays/integer.py", line 59, in _safe_cast
    raise TypeError(
TypeError: cannot safely cast non-equivalent float64 to uint32
2025-01-05 05:29:27,398 - CRITICAL - Pipeline execution failed: cannot safely cast non-equivalent float64 to uint32
2025-01-05 05:30:11,046 - INFO - Starting preprocessing pipeline.
2025-01-05 05:30:11,142 - INFO - None
2025-01-05 05:30:11,174 - INFO - Dataset loaded successfully. None
2025-01-05 05:30:11,205 - INFO - Target encoding completed.
2025-01-05 05:30:11,256 - INFO - Categorical encoding completed.
2025-01-05 05:30:11,298 - INFO - Holiday-related features created.
2025-01-05 05:30:11,317 - INFO - Normalization completed.
2025-01-05 05:30:11,361 - INFO - Rolling and expanding features generated.
2025-01-05 05:30:11,374 - INFO - Lag features generated.
2025-01-05 05:30:11,428 - INFO - Dropped NaN values. Preprocessing complete.
2025-01-05 05:30:27,211 - ERROR - An error occurred during preprocessing: cannot safely cast non-equivalent float64 to uint32
Traceback (most recent call last):
  File "/home/codespace/.local/lib/python3.12/site-packages/pandas/core/arrays/integer.py", line 53, in _safe_cast
    return values.astype(dtype, casting="safe", copy=copy)
           ^^^^^^^^^^^^^^^^^^^^^^^^^^^^^^^^^^^^^^^^^^^^^^^
TypeError: Cannot cast array data from dtype('float64') to dtype('uint32') according to the rule 'safe'

The above exception was the direct cause of the following exception:

Traceback (most recent call last):
  File "/usr/local/python/3.12.1/lib/python3.12/site-packages/imblearn/utils/_validation.py", line 71, in _transfrom_one
    ret = ret.astype(props["dtypes"])
          ^^^^^^^^^^^^^^^^^^^^^^^^^^^
  File "/home/codespace/.local/lib/python3.12/site-packages/pandas/core/generic.py", line 6620, in astype
    res_col = col.astype(dtype=cdt, copy=copy, errors=errors)
              ^^^^^^^^^^^^^^^^^^^^^^^^^^^^^^^^^^^^^^^^^^^^^^^
  File "/home/codespace/.local/lib/python3.12/site-packages/pandas/core/generic.py", line 6643, in astype
    new_data = self._mgr.astype(dtype=dtype, copy=copy, errors=errors)
               ^^^^^^^^^^^^^^^^^^^^^^^^^^^^^^^^^^^^^^^^^^^^^^^^^^^^^^^
  File "/home/codespace/.local/lib/python3.12/site-packages/pandas/core/internals/managers.py", line 430, in astype
    return self.apply(
           ^^^^^^^^^^^
  File "/home/codespace/.local/lib/python3.12/site-packages/pandas/core/internals/managers.py", line 363, in apply
    applied = getattr(b, f)(**kwargs)
              ^^^^^^^^^^^^^^^^^^^^^^^
  File "/home/codespace/.local/lib/python3.12/site-packages/pandas/core/internals/blocks.py", line 758, in astype
    new_values = astype_array_safe(values, dtype, copy=copy, errors=errors)
                 ^^^^^^^^^^^^^^^^^^^^^^^^^^^^^^^^^^^^^^^^^^^^^^^^^^^^^^^^^^
  File "/home/codespace/.local/lib/python3.12/site-packages/pandas/core/dtypes/astype.py", line 237, in astype_array_safe
    new_values = astype_array(values, dtype, copy=copy)
                 ^^^^^^^^^^^^^^^^^^^^^^^^^^^^^^^^^^^^^^
  File "/home/codespace/.local/lib/python3.12/site-packages/pandas/core/dtypes/astype.py", line 182, in astype_array
    values = _astype_nansafe(values, dtype, copy=copy)
             ^^^^^^^^^^^^^^^^^^^^^^^^^^^^^^^^^^^^^^^^^
  File "/home/codespace/.local/lib/python3.12/site-packages/pandas/core/dtypes/astype.py", line 80, in _astype_nansafe
    return dtype.construct_array_type()._from_sequence(arr, dtype=dtype, copy=copy)
           ^^^^^^^^^^^^^^^^^^^^^^^^^^^^^^^^^^^^^^^^^^^^^^^^^^^^^^^^^^^^^^^^^^^^^^^^
  File "/home/codespace/.local/lib/python3.12/site-packages/pandas/core/arrays/masked.py", line 152, in _from_sequence
    values, mask = cls._coerce_to_array(scalars, dtype=dtype, copy=copy)
                   ^^^^^^^^^^^^^^^^^^^^^^^^^^^^^^^^^^^^^^^^^^^^^^^^^^^^^
  File "/home/codespace/.local/lib/python3.12/site-packages/pandas/core/arrays/numeric.py", line 272, in _coerce_to_array
    values, mask, _, _ = _coerce_to_data_and_mask(
                         ^^^^^^^^^^^^^^^^^^^^^^^^^
  File "/home/codespace/.local/lib/python3.12/site-packages/pandas/core/arrays/numeric.py", line 229, in _coerce_to_data_and_mask
    values = dtype_cls._safe_cast(values, dtype, copy=False)
             ^^^^^^^^^^^^^^^^^^^^^^^^^^^^^^^^^^^^^^^^^^^^^^^
  File "/home/codespace/.local/lib/python3.12/site-packages/pandas/core/arrays/integer.py", line 59, in _safe_cast
    raise TypeError(
TypeError: cannot safely cast non-equivalent float64 to uint32

During handling of the above exception, another exception occurred:

Traceback (most recent call last):
  File "/home/codespace/.local/lib/python3.12/site-packages/pandas/core/arrays/integer.py", line 53, in _safe_cast
    return values.astype(dtype, casting="safe", copy=copy)
           ^^^^^^^^^^^^^^^^^^^^^^^^^^^^^^^^^^^^^^^^^^^^^^^
TypeError: Cannot cast array data from dtype('float64') to dtype('uint32') according to the rule 'safe'

The above exception was the direct cause of the following exception:

Traceback (most recent call last):
  File "/workspaces/invenlytics/pipelines/v2/feature_pipeline.py", line 130, in run_supplychain_disruption_feature_pipeline
    X_resampled, y_resampled = smote_enn.fit_resample(X, y)
                               ^^^^^^^^^^^^^^^^^^^^^^^^^^^^
  File "/usr/local/python/3.12.1/lib/python3.12/site-packages/imblearn/base.py", line 202, in fit_resample
    return super().fit_resample(X, y, **params)
           ^^^^^^^^^^^^^^^^^^^^^^^^^^^^^^^^^^^^
  File "/usr/local/python/3.12.1/lib/python3.12/site-packages/sklearn/base.py", line 1473, in wrapper
    return fit_method(estimator, *args, **kwargs)
           ^^^^^^^^^^^^^^^^^^^^^^^^^^^^^^^^^^^^^^
  File "/usr/local/python/3.12.1/lib/python3.12/site-packages/imblearn/base.py", line 111, in fit_resample
    X_, y_ = arrays_transformer.transform(output[0], y_)
             ^^^^^^^^^^^^^^^^^^^^^^^^^^^^^^^^^^^^^^^^^^^
  File "/usr/local/python/3.12.1/lib/python3.12/site-packages/imblearn/utils/_validation.py", line 40, in transform
    X = self._transfrom_one(X, self.x_props)
        ^^^^^^^^^^^^^^^^^^^^^^^^^^^^^^^^^^^^
  File "/usr/local/python/3.12.1/lib/python3.12/site-packages/imblearn/utils/_validation.py", line 86, in _transfrom_one
    ret = ret.astype(props["dtypes"])
          ^^^^^^^^^^^^^^^^^^^^^^^^^^^
  File "/home/codespace/.local/lib/python3.12/site-packages/pandas/core/generic.py", line 6620, in astype
    res_col = col.astype(dtype=cdt, copy=copy, errors=errors)
              ^^^^^^^^^^^^^^^^^^^^^^^^^^^^^^^^^^^^^^^^^^^^^^^
  File "/home/codespace/.local/lib/python3.12/site-packages/pandas/core/generic.py", line 6643, in astype
    new_data = self._mgr.astype(dtype=dtype, copy=copy, errors=errors)
               ^^^^^^^^^^^^^^^^^^^^^^^^^^^^^^^^^^^^^^^^^^^^^^^^^^^^^^^
  File "/home/codespace/.local/lib/python3.12/site-packages/pandas/core/internals/managers.py", line 430, in astype
    return self.apply(
           ^^^^^^^^^^^
  File "/home/codespace/.local/lib/python3.12/site-packages/pandas/core/internals/managers.py", line 363, in apply
    applied = getattr(b, f)(**kwargs)
              ^^^^^^^^^^^^^^^^^^^^^^^
  File "/home/codespace/.local/lib/python3.12/site-packages/pandas/core/internals/blocks.py", line 758, in astype
    new_values = astype_array_safe(values, dtype, copy=copy, errors=errors)
                 ^^^^^^^^^^^^^^^^^^^^^^^^^^^^^^^^^^^^^^^^^^^^^^^^^^^^^^^^^^
  File "/home/codespace/.local/lib/python3.12/site-packages/pandas/core/dtypes/astype.py", line 237, in astype_array_safe
    new_values = astype_array(values, dtype, copy=copy)
                 ^^^^^^^^^^^^^^^^^^^^^^^^^^^^^^^^^^^^^^
  File "/home/codespace/.local/lib/python3.12/site-packages/pandas/core/dtypes/astype.py", line 182, in astype_array
    values = _astype_nansafe(values, dtype, copy=copy)
             ^^^^^^^^^^^^^^^^^^^^^^^^^^^^^^^^^^^^^^^^^
  File "/home/codespace/.local/lib/python3.12/site-packages/pandas/core/dtypes/astype.py", line 80, in _astype_nansafe
    return dtype.construct_array_type()._from_sequence(arr, dtype=dtype, copy=copy)
           ^^^^^^^^^^^^^^^^^^^^^^^^^^^^^^^^^^^^^^^^^^^^^^^^^^^^^^^^^^^^^^^^^^^^^^^^
  File "/home/codespace/.local/lib/python3.12/site-packages/pandas/core/arrays/masked.py", line 152, in _from_sequence
    values, mask = cls._coerce_to_array(scalars, dtype=dtype, copy=copy)
                   ^^^^^^^^^^^^^^^^^^^^^^^^^^^^^^^^^^^^^^^^^^^^^^^^^^^^^
  File "/home/codespace/.local/lib/python3.12/site-packages/pandas/core/arrays/numeric.py", line 272, in _coerce_to_array
    values, mask, _, _ = _coerce_to_data_and_mask(
                         ^^^^^^^^^^^^^^^^^^^^^^^^^
  File "/home/codespace/.local/lib/python3.12/site-packages/pandas/core/arrays/numeric.py", line 229, in _coerce_to_data_and_mask
    values = dtype_cls._safe_cast(values, dtype, copy=False)
             ^^^^^^^^^^^^^^^^^^^^^^^^^^^^^^^^^^^^^^^^^^^^^^^
  File "/home/codespace/.local/lib/python3.12/site-packages/pandas/core/arrays/integer.py", line 59, in _safe_cast
    raise TypeError(
TypeError: cannot safely cast non-equivalent float64 to uint32
2025-01-05 05:30:27,217 - CRITICAL - Pipeline execution failed: cannot safely cast non-equivalent float64 to uint32
2025-01-05 05:30:48,310 - INFO - Starting preprocessing pipeline.
2025-01-05 05:30:48,417 - INFO - None
2025-01-05 05:30:48,466 - INFO - Dataset loaded successfully. None
2025-01-05 05:30:48,505 - INFO - Target encoding completed.
2025-01-05 05:30:48,554 - INFO - Categorical encoding completed.
2025-01-05 05:30:48,592 - INFO - Holiday-related features created.
2025-01-05 05:30:48,605 - INFO - Normalization completed.
2025-01-05 05:30:48,626 - INFO - Rolling and expanding features generated.
2025-01-05 05:30:48,635 - INFO - Lag features generated.
2025-01-05 05:30:48,660 - INFO - Dropped NaN values. Preprocessing complete.
2025-01-05 05:31:04,335 - ERROR - An error occurred during preprocessing: cannot safely cast non-equivalent float64 to uint32
Traceback (most recent call last):
  File "/home/codespace/.local/lib/python3.12/site-packages/pandas/core/arrays/integer.py", line 53, in _safe_cast
    return values.astype(dtype, casting="safe", copy=copy)
           ^^^^^^^^^^^^^^^^^^^^^^^^^^^^^^^^^^^^^^^^^^^^^^^
TypeError: Cannot cast array data from dtype('float64') to dtype('uint32') according to the rule 'safe'

The above exception was the direct cause of the following exception:

Traceback (most recent call last):
  File "/usr/local/python/3.12.1/lib/python3.12/site-packages/imblearn/utils/_validation.py", line 71, in _transfrom_one
    ret = ret.astype(props["dtypes"])
          ^^^^^^^^^^^^^^^^^^^^^^^^^^^
  File "/home/codespace/.local/lib/python3.12/site-packages/pandas/core/generic.py", line 6620, in astype
    res_col = col.astype(dtype=cdt, copy=copy, errors=errors)
              ^^^^^^^^^^^^^^^^^^^^^^^^^^^^^^^^^^^^^^^^^^^^^^^
  File "/home/codespace/.local/lib/python3.12/site-packages/pandas/core/generic.py", line 6643, in astype
    new_data = self._mgr.astype(dtype=dtype, copy=copy, errors=errors)
               ^^^^^^^^^^^^^^^^^^^^^^^^^^^^^^^^^^^^^^^^^^^^^^^^^^^^^^^
  File "/home/codespace/.local/lib/python3.12/site-packages/pandas/core/internals/managers.py", line 430, in astype
    return self.apply(
           ^^^^^^^^^^^
  File "/home/codespace/.local/lib/python3.12/site-packages/pandas/core/internals/managers.py", line 363, in apply
    applied = getattr(b, f)(**kwargs)
              ^^^^^^^^^^^^^^^^^^^^^^^
  File "/home/codespace/.local/lib/python3.12/site-packages/pandas/core/internals/blocks.py", line 758, in astype
    new_values = astype_array_safe(values, dtype, copy=copy, errors=errors)
                 ^^^^^^^^^^^^^^^^^^^^^^^^^^^^^^^^^^^^^^^^^^^^^^^^^^^^^^^^^^
  File "/home/codespace/.local/lib/python3.12/site-packages/pandas/core/dtypes/astype.py", line 237, in astype_array_safe
    new_values = astype_array(values, dtype, copy=copy)
                 ^^^^^^^^^^^^^^^^^^^^^^^^^^^^^^^^^^^^^^
  File "/home/codespace/.local/lib/python3.12/site-packages/pandas/core/dtypes/astype.py", line 182, in astype_array
    values = _astype_nansafe(values, dtype, copy=copy)
             ^^^^^^^^^^^^^^^^^^^^^^^^^^^^^^^^^^^^^^^^^
  File "/home/codespace/.local/lib/python3.12/site-packages/pandas/core/dtypes/astype.py", line 80, in _astype_nansafe
    return dtype.construct_array_type()._from_sequence(arr, dtype=dtype, copy=copy)
           ^^^^^^^^^^^^^^^^^^^^^^^^^^^^^^^^^^^^^^^^^^^^^^^^^^^^^^^^^^^^^^^^^^^^^^^^
  File "/home/codespace/.local/lib/python3.12/site-packages/pandas/core/arrays/masked.py", line 152, in _from_sequence
    values, mask = cls._coerce_to_array(scalars, dtype=dtype, copy=copy)
                   ^^^^^^^^^^^^^^^^^^^^^^^^^^^^^^^^^^^^^^^^^^^^^^^^^^^^^
  File "/home/codespace/.local/lib/python3.12/site-packages/pandas/core/arrays/numeric.py", line 272, in _coerce_to_array
    values, mask, _, _ = _coerce_to_data_and_mask(
                         ^^^^^^^^^^^^^^^^^^^^^^^^^
  File "/home/codespace/.local/lib/python3.12/site-packages/pandas/core/arrays/numeric.py", line 229, in _coerce_to_data_and_mask
    values = dtype_cls._safe_cast(values, dtype, copy=False)
             ^^^^^^^^^^^^^^^^^^^^^^^^^^^^^^^^^^^^^^^^^^^^^^^
  File "/home/codespace/.local/lib/python3.12/site-packages/pandas/core/arrays/integer.py", line 59, in _safe_cast
    raise TypeError(
TypeError: cannot safely cast non-equivalent float64 to uint32

During handling of the above exception, another exception occurred:

Traceback (most recent call last):
  File "/home/codespace/.local/lib/python3.12/site-packages/pandas/core/arrays/integer.py", line 53, in _safe_cast
    return values.astype(dtype, casting="safe", copy=copy)
           ^^^^^^^^^^^^^^^^^^^^^^^^^^^^^^^^^^^^^^^^^^^^^^^
TypeError: Cannot cast array data from dtype('float64') to dtype('uint32') according to the rule 'safe'

The above exception was the direct cause of the following exception:

Traceback (most recent call last):
  File "/workspaces/invenlytics/pipelines/v2/feature_pipeline.py", line 130, in run_supplychain_disruption_feature_pipeline
    X_resampled, y_resampled = smote_enn.fit_resample(X, y)
                               ^^^^^^^^^^^^^^^^^^^^^^^^^^^^
  File "/usr/local/python/3.12.1/lib/python3.12/site-packages/imblearn/base.py", line 202, in fit_resample
    return super().fit_resample(X, y, **params)
           ^^^^^^^^^^^^^^^^^^^^^^^^^^^^^^^^^^^^
  File "/usr/local/python/3.12.1/lib/python3.12/site-packages/sklearn/base.py", line 1473, in wrapper
    return fit_method(estimator, *args, **kwargs)
           ^^^^^^^^^^^^^^^^^^^^^^^^^^^^^^^^^^^^^^
  File "/usr/local/python/3.12.1/lib/python3.12/site-packages/imblearn/base.py", line 111, in fit_resample
    X_, y_ = arrays_transformer.transform(output[0], y_)
             ^^^^^^^^^^^^^^^^^^^^^^^^^^^^^^^^^^^^^^^^^^^
  File "/usr/local/python/3.12.1/lib/python3.12/site-packages/imblearn/utils/_validation.py", line 40, in transform
    X = self._transfrom_one(X, self.x_props)
        ^^^^^^^^^^^^^^^^^^^^^^^^^^^^^^^^^^^^
  File "/usr/local/python/3.12.1/lib/python3.12/site-packages/imblearn/utils/_validation.py", line 86, in _transfrom_one
    ret = ret.astype(props["dtypes"])
          ^^^^^^^^^^^^^^^^^^^^^^^^^^^
  File "/home/codespace/.local/lib/python3.12/site-packages/pandas/core/generic.py", line 6620, in astype
    res_col = col.astype(dtype=cdt, copy=copy, errors=errors)
              ^^^^^^^^^^^^^^^^^^^^^^^^^^^^^^^^^^^^^^^^^^^^^^^
  File "/home/codespace/.local/lib/python3.12/site-packages/pandas/core/generic.py", line 6643, in astype
    new_data = self._mgr.astype(dtype=dtype, copy=copy, errors=errors)
               ^^^^^^^^^^^^^^^^^^^^^^^^^^^^^^^^^^^^^^^^^^^^^^^^^^^^^^^
  File "/home/codespace/.local/lib/python3.12/site-packages/pandas/core/internals/managers.py", line 430, in astype
    return self.apply(
           ^^^^^^^^^^^
  File "/home/codespace/.local/lib/python3.12/site-packages/pandas/core/internals/managers.py", line 363, in apply
    applied = getattr(b, f)(**kwargs)
              ^^^^^^^^^^^^^^^^^^^^^^^
  File "/home/codespace/.local/lib/python3.12/site-packages/pandas/core/internals/blocks.py", line 758, in astype
    new_values = astype_array_safe(values, dtype, copy=copy, errors=errors)
                 ^^^^^^^^^^^^^^^^^^^^^^^^^^^^^^^^^^^^^^^^^^^^^^^^^^^^^^^^^^
  File "/home/codespace/.local/lib/python3.12/site-packages/pandas/core/dtypes/astype.py", line 237, in astype_array_safe
    new_values = astype_array(values, dtype, copy=copy)
                 ^^^^^^^^^^^^^^^^^^^^^^^^^^^^^^^^^^^^^^
  File "/home/codespace/.local/lib/python3.12/site-packages/pandas/core/dtypes/astype.py", line 182, in astype_array
    values = _astype_nansafe(values, dtype, copy=copy)
             ^^^^^^^^^^^^^^^^^^^^^^^^^^^^^^^^^^^^^^^^^
  File "/home/codespace/.local/lib/python3.12/site-packages/pandas/core/dtypes/astype.py", line 80, in _astype_nansafe
    return dtype.construct_array_type()._from_sequence(arr, dtype=dtype, copy=copy)
           ^^^^^^^^^^^^^^^^^^^^^^^^^^^^^^^^^^^^^^^^^^^^^^^^^^^^^^^^^^^^^^^^^^^^^^^^
  File "/home/codespace/.local/lib/python3.12/site-packages/pandas/core/arrays/masked.py", line 152, in _from_sequence
    values, mask = cls._coerce_to_array(scalars, dtype=dtype, copy=copy)
                   ^^^^^^^^^^^^^^^^^^^^^^^^^^^^^^^^^^^^^^^^^^^^^^^^^^^^^
  File "/home/codespace/.local/lib/python3.12/site-packages/pandas/core/arrays/numeric.py", line 272, in _coerce_to_array
    values, mask, _, _ = _coerce_to_data_and_mask(
                         ^^^^^^^^^^^^^^^^^^^^^^^^^
  File "/home/codespace/.local/lib/python3.12/site-packages/pandas/core/arrays/numeric.py", line 229, in _coerce_to_data_and_mask
    values = dtype_cls._safe_cast(values, dtype, copy=False)
             ^^^^^^^^^^^^^^^^^^^^^^^^^^^^^^^^^^^^^^^^^^^^^^^
  File "/home/codespace/.local/lib/python3.12/site-packages/pandas/core/arrays/integer.py", line 59, in _safe_cast
    raise TypeError(
TypeError: cannot safely cast non-equivalent float64 to uint32
2025-01-05 05:31:04,340 - CRITICAL - Pipeline execution failed: cannot safely cast non-equivalent float64 to uint32
2025-01-05 05:32:16,710 - INFO - Starting preprocessing pipeline.
2025-01-05 05:32:16,801 - INFO - None
2025-01-05 05:32:16,832 - INFO - Dataset loaded successfully. None
2025-01-05 05:32:16,883 - INFO - Target encoding completed.
2025-01-05 05:32:16,940 - INFO - Categorical encoding completed.
2025-01-05 05:32:16,980 - INFO - Holiday-related features created.
2025-01-05 05:32:16,993 - INFO - Normalization completed.
2025-01-05 05:32:17,016 - INFO - Rolling and expanding features generated.
2025-01-05 05:32:17,026 - INFO - Lag features generated.
2025-01-05 05:32:17,052 - INFO - Dropped NaN values. Preprocessing complete.
2025-01-05 05:32:32,612 - ERROR - An error occurred during preprocessing: cannot safely cast non-equivalent float64 to uint32
Traceback (most recent call last):
  File "/home/codespace/.local/lib/python3.12/site-packages/pandas/core/arrays/integer.py", line 53, in _safe_cast
    return values.astype(dtype, casting="safe", copy=copy)
           ^^^^^^^^^^^^^^^^^^^^^^^^^^^^^^^^^^^^^^^^^^^^^^^
TypeError: Cannot cast array data from dtype('float64') to dtype('uint32') according to the rule 'safe'

The above exception was the direct cause of the following exception:

Traceback (most recent call last):
  File "/usr/local/python/3.12.1/lib/python3.12/site-packages/imblearn/utils/_validation.py", line 71, in _transfrom_one
    ret = ret.astype(props["dtypes"])
          ^^^^^^^^^^^^^^^^^^^^^^^^^^^
  File "/home/codespace/.local/lib/python3.12/site-packages/pandas/core/generic.py", line 6620, in astype
    res_col = col.astype(dtype=cdt, copy=copy, errors=errors)
              ^^^^^^^^^^^^^^^^^^^^^^^^^^^^^^^^^^^^^^^^^^^^^^^
  File "/home/codespace/.local/lib/python3.12/site-packages/pandas/core/generic.py", line 6643, in astype
    new_data = self._mgr.astype(dtype=dtype, copy=copy, errors=errors)
               ^^^^^^^^^^^^^^^^^^^^^^^^^^^^^^^^^^^^^^^^^^^^^^^^^^^^^^^
  File "/home/codespace/.local/lib/python3.12/site-packages/pandas/core/internals/managers.py", line 430, in astype
    return self.apply(
           ^^^^^^^^^^^
  File "/home/codespace/.local/lib/python3.12/site-packages/pandas/core/internals/managers.py", line 363, in apply
    applied = getattr(b, f)(**kwargs)
              ^^^^^^^^^^^^^^^^^^^^^^^
  File "/home/codespace/.local/lib/python3.12/site-packages/pandas/core/internals/blocks.py", line 758, in astype
    new_values = astype_array_safe(values, dtype, copy=copy, errors=errors)
                 ^^^^^^^^^^^^^^^^^^^^^^^^^^^^^^^^^^^^^^^^^^^^^^^^^^^^^^^^^^
  File "/home/codespace/.local/lib/python3.12/site-packages/pandas/core/dtypes/astype.py", line 237, in astype_array_safe
    new_values = astype_array(values, dtype, copy=copy)
                 ^^^^^^^^^^^^^^^^^^^^^^^^^^^^^^^^^^^^^^
  File "/home/codespace/.local/lib/python3.12/site-packages/pandas/core/dtypes/astype.py", line 182, in astype_array
    values = _astype_nansafe(values, dtype, copy=copy)
             ^^^^^^^^^^^^^^^^^^^^^^^^^^^^^^^^^^^^^^^^^
  File "/home/codespace/.local/lib/python3.12/site-packages/pandas/core/dtypes/astype.py", line 80, in _astype_nansafe
    return dtype.construct_array_type()._from_sequence(arr, dtype=dtype, copy=copy)
           ^^^^^^^^^^^^^^^^^^^^^^^^^^^^^^^^^^^^^^^^^^^^^^^^^^^^^^^^^^^^^^^^^^^^^^^^
  File "/home/codespace/.local/lib/python3.12/site-packages/pandas/core/arrays/masked.py", line 152, in _from_sequence
    values, mask = cls._coerce_to_array(scalars, dtype=dtype, copy=copy)
                   ^^^^^^^^^^^^^^^^^^^^^^^^^^^^^^^^^^^^^^^^^^^^^^^^^^^^^
  File "/home/codespace/.local/lib/python3.12/site-packages/pandas/core/arrays/numeric.py", line 272, in _coerce_to_array
    values, mask, _, _ = _coerce_to_data_and_mask(
                         ^^^^^^^^^^^^^^^^^^^^^^^^^
  File "/home/codespace/.local/lib/python3.12/site-packages/pandas/core/arrays/numeric.py", line 229, in _coerce_to_data_and_mask
    values = dtype_cls._safe_cast(values, dtype, copy=False)
             ^^^^^^^^^^^^^^^^^^^^^^^^^^^^^^^^^^^^^^^^^^^^^^^
  File "/home/codespace/.local/lib/python3.12/site-packages/pandas/core/arrays/integer.py", line 59, in _safe_cast
    raise TypeError(
TypeError: cannot safely cast non-equivalent float64 to uint32

During handling of the above exception, another exception occurred:

Traceback (most recent call last):
  File "/home/codespace/.local/lib/python3.12/site-packages/pandas/core/arrays/integer.py", line 53, in _safe_cast
    return values.astype(dtype, casting="safe", copy=copy)
           ^^^^^^^^^^^^^^^^^^^^^^^^^^^^^^^^^^^^^^^^^^^^^^^
TypeError: Cannot cast array data from dtype('float64') to dtype('uint32') according to the rule 'safe'

The above exception was the direct cause of the following exception:

Traceback (most recent call last):
  File "/workspaces/invenlytics/pipelines/v2/feature_pipeline.py", line 131, in run_supplychain_disruption_feature_pipeline
    X_resampled, y_resampled = smote_enn.fit_resample(X, y)
                               ^^^^^^^^^^^^^^^^^^^^^^^^^^^^
  File "/usr/local/python/3.12.1/lib/python3.12/site-packages/imblearn/base.py", line 202, in fit_resample
    return super().fit_resample(X, y, **params)
           ^^^^^^^^^^^^^^^^^^^^^^^^^^^^^^^^^^^^
  File "/usr/local/python/3.12.1/lib/python3.12/site-packages/sklearn/base.py", line 1473, in wrapper
    return fit_method(estimator, *args, **kwargs)
           ^^^^^^^^^^^^^^^^^^^^^^^^^^^^^^^^^^^^^^
  File "/usr/local/python/3.12.1/lib/python3.12/site-packages/imblearn/base.py", line 111, in fit_resample
    X_, y_ = arrays_transformer.transform(output[0], y_)
             ^^^^^^^^^^^^^^^^^^^^^^^^^^^^^^^^^^^^^^^^^^^
  File "/usr/local/python/3.12.1/lib/python3.12/site-packages/imblearn/utils/_validation.py", line 40, in transform
    X = self._transfrom_one(X, self.x_props)
        ^^^^^^^^^^^^^^^^^^^^^^^^^^^^^^^^^^^^
  File "/usr/local/python/3.12.1/lib/python3.12/site-packages/imblearn/utils/_validation.py", line 86, in _transfrom_one
    ret = ret.astype(props["dtypes"])
          ^^^^^^^^^^^^^^^^^^^^^^^^^^^
  File "/home/codespace/.local/lib/python3.12/site-packages/pandas/core/generic.py", line 6620, in astype
    res_col = col.astype(dtype=cdt, copy=copy, errors=errors)
              ^^^^^^^^^^^^^^^^^^^^^^^^^^^^^^^^^^^^^^^^^^^^^^^
  File "/home/codespace/.local/lib/python3.12/site-packages/pandas/core/generic.py", line 6643, in astype
    new_data = self._mgr.astype(dtype=dtype, copy=copy, errors=errors)
               ^^^^^^^^^^^^^^^^^^^^^^^^^^^^^^^^^^^^^^^^^^^^^^^^^^^^^^^
  File "/home/codespace/.local/lib/python3.12/site-packages/pandas/core/internals/managers.py", line 430, in astype
    return self.apply(
           ^^^^^^^^^^^
  File "/home/codespace/.local/lib/python3.12/site-packages/pandas/core/internals/managers.py", line 363, in apply
    applied = getattr(b, f)(**kwargs)
              ^^^^^^^^^^^^^^^^^^^^^^^
  File "/home/codespace/.local/lib/python3.12/site-packages/pandas/core/internals/blocks.py", line 758, in astype
    new_values = astype_array_safe(values, dtype, copy=copy, errors=errors)
                 ^^^^^^^^^^^^^^^^^^^^^^^^^^^^^^^^^^^^^^^^^^^^^^^^^^^^^^^^^^
  File "/home/codespace/.local/lib/python3.12/site-packages/pandas/core/dtypes/astype.py", line 237, in astype_array_safe
    new_values = astype_array(values, dtype, copy=copy)
                 ^^^^^^^^^^^^^^^^^^^^^^^^^^^^^^^^^^^^^^
  File "/home/codespace/.local/lib/python3.12/site-packages/pandas/core/dtypes/astype.py", line 182, in astype_array
    values = _astype_nansafe(values, dtype, copy=copy)
             ^^^^^^^^^^^^^^^^^^^^^^^^^^^^^^^^^^^^^^^^^
  File "/home/codespace/.local/lib/python3.12/site-packages/pandas/core/dtypes/astype.py", line 80, in _astype_nansafe
    return dtype.construct_array_type()._from_sequence(arr, dtype=dtype, copy=copy)
           ^^^^^^^^^^^^^^^^^^^^^^^^^^^^^^^^^^^^^^^^^^^^^^^^^^^^^^^^^^^^^^^^^^^^^^^^
  File "/home/codespace/.local/lib/python3.12/site-packages/pandas/core/arrays/masked.py", line 152, in _from_sequence
    values, mask = cls._coerce_to_array(scalars, dtype=dtype, copy=copy)
                   ^^^^^^^^^^^^^^^^^^^^^^^^^^^^^^^^^^^^^^^^^^^^^^^^^^^^^
  File "/home/codespace/.local/lib/python3.12/site-packages/pandas/core/arrays/numeric.py", line 272, in _coerce_to_array
    values, mask, _, _ = _coerce_to_data_and_mask(
                         ^^^^^^^^^^^^^^^^^^^^^^^^^
  File "/home/codespace/.local/lib/python3.12/site-packages/pandas/core/arrays/numeric.py", line 229, in _coerce_to_data_and_mask
    values = dtype_cls._safe_cast(values, dtype, copy=False)
             ^^^^^^^^^^^^^^^^^^^^^^^^^^^^^^^^^^^^^^^^^^^^^^^
  File "/home/codespace/.local/lib/python3.12/site-packages/pandas/core/arrays/integer.py", line 59, in _safe_cast
    raise TypeError(
TypeError: cannot safely cast non-equivalent float64 to uint32
2025-01-05 05:32:32,617 - CRITICAL - Pipeline execution failed: cannot safely cast non-equivalent float64 to uint32
2025-01-05 05:34:56,088 - INFO - Starting preprocessing pipeline.
2025-01-05 05:34:56,182 - INFO - None
2025-01-05 05:34:56,214 - INFO - Dataset loaded successfully. None
2025-01-05 05:34:56,246 - INFO - Target encoding completed.
2025-01-05 05:34:56,303 - INFO - Categorical encoding completed.
2025-01-05 05:34:56,340 - INFO - Holiday-related features created.
2025-01-05 05:34:56,353 - INFO - Normalization completed.
2025-01-05 05:34:56,376 - INFO - Rolling and expanding features generated.
2025-01-05 05:34:56,385 - INFO - Lag features generated.
2025-01-05 05:34:56,412 - INFO - Dropped NaN values. Preprocessing complete.
2025-01-05 05:34:56,421 - INFO - Feature pipeline executed successfully.
2025-01-05 05:36:12,271 - INFO - Starting preprocessing pipeline.
2025-01-05 05:36:12,369 - INFO - None
2025-01-05 05:36:12,403 - INFO - Dataset loaded successfully. None
2025-01-05 05:36:12,436 - INFO - Target encoding completed.
2025-01-05 05:36:12,489 - INFO - Categorical encoding completed.
2025-01-05 05:36:12,528 - INFO - Holiday-related features created.
2025-01-05 05:36:12,546 - INFO - Normalization completed.
2025-01-05 05:36:12,584 - INFO - Rolling and expanding features generated.
2025-01-05 05:36:12,596 - INFO - Lag features generated.
2025-01-05 05:36:12,623 - INFO - Dropped NaN values. Preprocessing complete.
2025-01-05 05:36:12,631 - INFO - Feature pipeline executed successfully.
2025-01-05 05:36:38,876 - INFO - Starting preprocessing pipeline.
2025-01-05 05:36:38,965 - INFO - None
2025-01-05 05:36:38,997 - INFO - Dataset loaded successfully. None
2025-01-05 05:36:39,028 - INFO - Target encoding completed.
2025-01-05 05:36:39,103 - INFO - Categorical encoding completed.
2025-01-05 05:36:39,143 - INFO - Holiday-related features created.
2025-01-05 05:36:39,156 - INFO - Normalization completed.
2025-01-05 05:36:39,178 - INFO - Rolling and expanding features generated.
2025-01-05 05:36:39,188 - INFO - Lag features generated.
2025-01-05 05:36:39,210 - INFO - Dropped NaN values. Preprocessing complete.
2025-01-05 05:36:39,220 - INFO - Feature pipeline executed successfully.
2025-01-05 05:36:48,622 - INFO - Starting preprocessing pipeline.
2025-01-05 05:36:48,749 - INFO - None
2025-01-05 05:36:48,799 - INFO - Dataset loaded successfully. None
2025-01-05 05:36:48,832 - INFO - Target encoding completed.
2025-01-05 05:36:48,884 - INFO - Categorical encoding completed.
2025-01-05 05:36:48,924 - INFO - Holiday-related features created.
2025-01-05 05:36:48,937 - INFO - Normalization completed.
2025-01-05 05:36:48,960 - INFO - Rolling and expanding features generated.
2025-01-05 05:36:48,970 - INFO - Lag features generated.
2025-01-05 05:36:48,992 - INFO - Dropped NaN values. Preprocessing complete.
2025-01-05 05:36:49,004 - INFO - Feature pipeline executed successfully.
2025-01-05 05:37:26,402 - INFO - Starting preprocessing pipeline.
2025-01-05 05:37:26,512 - INFO - None
2025-01-05 05:37:26,543 - INFO - Dataset loaded successfully. None
2025-01-05 05:37:26,576 - INFO - Target encoding completed.
2025-01-05 05:37:26,629 - INFO - Categorical encoding completed.
2025-01-05 05:37:26,669 - INFO - Holiday-related features created.
2025-01-05 05:37:26,683 - INFO - Normalization completed.
2025-01-05 05:37:26,706 - INFO - Rolling and expanding features generated.
2025-01-05 05:37:26,716 - INFO - Lag features generated.
2025-01-05 05:37:26,738 - INFO - Dropped NaN values. Preprocessing complete.
2025-01-05 05:37:26,868 - ERROR - An error occurred during preprocessing: float() argument must be a string or a real number, not 'Timestamp'
Traceback (most recent call last):
  File "/workspaces/invenlytics/pipelines/v2/feature_pipeline.py", line 131, in run_supplychain_disruption_feature_pipeline
    X_resampled, y_resampled = smote_enn.fit_resample(X, y)
                               ^^^^^^^^^^^^^^^^^^^^^^^^^^^^
  File "/usr/local/python/3.12.1/lib/python3.12/site-packages/imblearn/base.py", line 202, in fit_resample
    return super().fit_resample(X, y, **params)
           ^^^^^^^^^^^^^^^^^^^^^^^^^^^^^^^^^^^^
  File "/usr/local/python/3.12.1/lib/python3.12/site-packages/sklearn/base.py", line 1473, in wrapper
    return fit_method(estimator, *args, **kwargs)
           ^^^^^^^^^^^^^^^^^^^^^^^^^^^^^^^^^^^^^^
  File "/usr/local/python/3.12.1/lib/python3.12/site-packages/imblearn/base.py", line 105, in fit_resample
    output = self._fit_resample(X, y, **params)
             ^^^^^^^^^^^^^^^^^^^^^^^^^^^^^^^^^^
  File "/usr/local/python/3.12.1/lib/python3.12/site-packages/imblearn/combine/_smote_enn.py", line 156, in _fit_resample
    X, y = check_X_y(X, y, accept_sparse=["csr", "csc"])
           ^^^^^^^^^^^^^^^^^^^^^^^^^^^^^^^^^^^^^^^^^^^^^
  File "/usr/local/python/3.12.1/lib/python3.12/site-packages/sklearn/utils/validation.py", line 1301, in check_X_y
    X = check_array(
        ^^^^^^^^^^^^
  File "/usr/local/python/3.12.1/lib/python3.12/site-packages/sklearn/utils/validation.py", line 1012, in check_array
    array = _asarray_with_order(array, order=order, dtype=dtype, xp=xp)
            ^^^^^^^^^^^^^^^^^^^^^^^^^^^^^^^^^^^^^^^^^^^^^^^^^^^^^^^^^^^
  File "/usr/local/python/3.12.1/lib/python3.12/site-packages/sklearn/utils/_array_api.py", line 745, in _asarray_with_order
    array = numpy.asarray(array, order=order, dtype=dtype)
            ^^^^^^^^^^^^^^^^^^^^^^^^^^^^^^^^^^^^^^^^^^^^^^
TypeError: float() argument must be a string or a real number, not 'Timestamp'
2025-01-05 05:37:26,870 - CRITICAL - Pipeline execution failed: float() argument must be a string or a real number, not 'Timestamp'
2025-01-05 05:37:50,088 - INFO - Starting preprocessing pipeline.
2025-01-05 05:37:50,178 - INFO - None
2025-01-05 05:37:50,210 - INFO - Dataset loaded successfully. None
2025-01-05 05:37:50,242 - INFO - Target encoding completed.
2025-01-05 05:37:50,294 - INFO - Categorical encoding completed.
2025-01-05 05:37:50,333 - INFO - Holiday-related features created.
2025-01-05 05:37:50,346 - INFO - Normalization completed.
2025-01-05 05:37:50,372 - INFO - Rolling and expanding features generated.
2025-01-05 05:37:50,381 - INFO - Lag features generated.
2025-01-05 05:37:50,410 - INFO - Dropped NaN values. Preprocessing complete.
2025-01-05 05:37:50,567 - ERROR - An error occurred during preprocessing: float() argument must be a string or a real number, not 'Timestamp'
Traceback (most recent call last):
  File "/workspaces/invenlytics/pipelines/v2/feature_pipeline.py", line 130, in run_supplychain_disruption_feature_pipeline
    X_resampled, y_resampled = smote_enn.fit_resample(X, y)
                               ^^^^^^^^^^^^^^^^^^^^^^^^^^^^
  File "/usr/local/python/3.12.1/lib/python3.12/site-packages/imblearn/base.py", line 202, in fit_resample
    return super().fit_resample(X, y, **params)
           ^^^^^^^^^^^^^^^^^^^^^^^^^^^^^^^^^^^^
  File "/usr/local/python/3.12.1/lib/python3.12/site-packages/sklearn/base.py", line 1473, in wrapper
    return fit_method(estimator, *args, **kwargs)
           ^^^^^^^^^^^^^^^^^^^^^^^^^^^^^^^^^^^^^^
  File "/usr/local/python/3.12.1/lib/python3.12/site-packages/imblearn/base.py", line 105, in fit_resample
    output = self._fit_resample(X, y, **params)
             ^^^^^^^^^^^^^^^^^^^^^^^^^^^^^^^^^^
  File "/usr/local/python/3.12.1/lib/python3.12/site-packages/imblearn/combine/_smote_enn.py", line 156, in _fit_resample
    X, y = check_X_y(X, y, accept_sparse=["csr", "csc"])
           ^^^^^^^^^^^^^^^^^^^^^^^^^^^^^^^^^^^^^^^^^^^^^
  File "/usr/local/python/3.12.1/lib/python3.12/site-packages/sklearn/utils/validation.py", line 1301, in check_X_y
    X = check_array(
        ^^^^^^^^^^^^
  File "/usr/local/python/3.12.1/lib/python3.12/site-packages/sklearn/utils/validation.py", line 1012, in check_array
    array = _asarray_with_order(array, order=order, dtype=dtype, xp=xp)
            ^^^^^^^^^^^^^^^^^^^^^^^^^^^^^^^^^^^^^^^^^^^^^^^^^^^^^^^^^^^
  File "/usr/local/python/3.12.1/lib/python3.12/site-packages/sklearn/utils/_array_api.py", line 745, in _asarray_with_order
    array = numpy.asarray(array, order=order, dtype=dtype)
            ^^^^^^^^^^^^^^^^^^^^^^^^^^^^^^^^^^^^^^^^^^^^^^
TypeError: float() argument must be a string or a real number, not 'Timestamp'
2025-01-05 05:37:50,569 - CRITICAL - Pipeline execution failed: float() argument must be a string or a real number, not 'Timestamp'
2025-01-05 05:38:06,858 - INFO - Starting preprocessing pipeline.
2025-01-05 05:38:06,942 - INFO - None
2025-01-05 05:38:06,974 - INFO - Dataset loaded successfully. None
2025-01-05 05:38:07,009 - INFO - Target encoding completed.
2025-01-05 05:38:07,096 - INFO - Categorical encoding completed.
2025-01-05 05:38:07,144 - INFO - Holiday-related features created.
2025-01-05 05:38:07,158 - INFO - Normalization completed.
2025-01-05 05:38:07,180 - INFO - Rolling and expanding features generated.
2025-01-05 05:38:07,190 - INFO - Lag features generated.
2025-01-05 05:38:07,216 - INFO - Dropped NaN values. Preprocessing complete.
2025-01-05 05:38:22,940 - ERROR - An error occurred during preprocessing: cannot safely cast non-equivalent float64 to uint32
Traceback (most recent call last):
  File "/home/codespace/.local/lib/python3.12/site-packages/pandas/core/arrays/integer.py", line 53, in _safe_cast
    return values.astype(dtype, casting="safe", copy=copy)
           ^^^^^^^^^^^^^^^^^^^^^^^^^^^^^^^^^^^^^^^^^^^^^^^
TypeError: Cannot cast array data from dtype('float64') to dtype('uint32') according to the rule 'safe'

The above exception was the direct cause of the following exception:

Traceback (most recent call last):
  File "/usr/local/python/3.12.1/lib/python3.12/site-packages/imblearn/utils/_validation.py", line 71, in _transfrom_one
    ret = ret.astype(props["dtypes"])
          ^^^^^^^^^^^^^^^^^^^^^^^^^^^
  File "/home/codespace/.local/lib/python3.12/site-packages/pandas/core/generic.py", line 6620, in astype
    res_col = col.astype(dtype=cdt, copy=copy, errors=errors)
              ^^^^^^^^^^^^^^^^^^^^^^^^^^^^^^^^^^^^^^^^^^^^^^^
  File "/home/codespace/.local/lib/python3.12/site-packages/pandas/core/generic.py", line 6643, in astype
    new_data = self._mgr.astype(dtype=dtype, copy=copy, errors=errors)
               ^^^^^^^^^^^^^^^^^^^^^^^^^^^^^^^^^^^^^^^^^^^^^^^^^^^^^^^
  File "/home/codespace/.local/lib/python3.12/site-packages/pandas/core/internals/managers.py", line 430, in astype
    return self.apply(
           ^^^^^^^^^^^
  File "/home/codespace/.local/lib/python3.12/site-packages/pandas/core/internals/managers.py", line 363, in apply
    applied = getattr(b, f)(**kwargs)
              ^^^^^^^^^^^^^^^^^^^^^^^
  File "/home/codespace/.local/lib/python3.12/site-packages/pandas/core/internals/blocks.py", line 758, in astype
    new_values = astype_array_safe(values, dtype, copy=copy, errors=errors)
                 ^^^^^^^^^^^^^^^^^^^^^^^^^^^^^^^^^^^^^^^^^^^^^^^^^^^^^^^^^^
  File "/home/codespace/.local/lib/python3.12/site-packages/pandas/core/dtypes/astype.py", line 237, in astype_array_safe
    new_values = astype_array(values, dtype, copy=copy)
                 ^^^^^^^^^^^^^^^^^^^^^^^^^^^^^^^^^^^^^^
  File "/home/codespace/.local/lib/python3.12/site-packages/pandas/core/dtypes/astype.py", line 182, in astype_array
    values = _astype_nansafe(values, dtype, copy=copy)
             ^^^^^^^^^^^^^^^^^^^^^^^^^^^^^^^^^^^^^^^^^
  File "/home/codespace/.local/lib/python3.12/site-packages/pandas/core/dtypes/astype.py", line 80, in _astype_nansafe
    return dtype.construct_array_type()._from_sequence(arr, dtype=dtype, copy=copy)
           ^^^^^^^^^^^^^^^^^^^^^^^^^^^^^^^^^^^^^^^^^^^^^^^^^^^^^^^^^^^^^^^^^^^^^^^^
  File "/home/codespace/.local/lib/python3.12/site-packages/pandas/core/arrays/masked.py", line 152, in _from_sequence
    values, mask = cls._coerce_to_array(scalars, dtype=dtype, copy=copy)
                   ^^^^^^^^^^^^^^^^^^^^^^^^^^^^^^^^^^^^^^^^^^^^^^^^^^^^^
  File "/home/codespace/.local/lib/python3.12/site-packages/pandas/core/arrays/numeric.py", line 272, in _coerce_to_array
    values, mask, _, _ = _coerce_to_data_and_mask(
                         ^^^^^^^^^^^^^^^^^^^^^^^^^
  File "/home/codespace/.local/lib/python3.12/site-packages/pandas/core/arrays/numeric.py", line 229, in _coerce_to_data_and_mask
    values = dtype_cls._safe_cast(values, dtype, copy=False)
             ^^^^^^^^^^^^^^^^^^^^^^^^^^^^^^^^^^^^^^^^^^^^^^^
  File "/home/codespace/.local/lib/python3.12/site-packages/pandas/core/arrays/integer.py", line 59, in _safe_cast
    raise TypeError(
TypeError: cannot safely cast non-equivalent float64 to uint32

During handling of the above exception, another exception occurred:

Traceback (most recent call last):
  File "/home/codespace/.local/lib/python3.12/site-packages/pandas/core/arrays/integer.py", line 53, in _safe_cast
    return values.astype(dtype, casting="safe", copy=copy)
           ^^^^^^^^^^^^^^^^^^^^^^^^^^^^^^^^^^^^^^^^^^^^^^^
TypeError: Cannot cast array data from dtype('float64') to dtype('uint32') according to the rule 'safe'

The above exception was the direct cause of the following exception:

Traceback (most recent call last):
  File "/workspaces/invenlytics/pipelines/v2/feature_pipeline.py", line 130, in run_supplychain_disruption_feature_pipeline
    X_resampled, y_resampled = smote_enn.fit_resample(X, y)
                               ^^^^^^^^^^^^^^^^^^^^^^^^^^^^
  File "/usr/local/python/3.12.1/lib/python3.12/site-packages/imblearn/base.py", line 202, in fit_resample
    return super().fit_resample(X, y, **params)
           ^^^^^^^^^^^^^^^^^^^^^^^^^^^^^^^^^^^^
  File "/usr/local/python/3.12.1/lib/python3.12/site-packages/sklearn/base.py", line 1473, in wrapper
    return fit_method(estimator, *args, **kwargs)
           ^^^^^^^^^^^^^^^^^^^^^^^^^^^^^^^^^^^^^^
  File "/usr/local/python/3.12.1/lib/python3.12/site-packages/imblearn/base.py", line 111, in fit_resample
    X_, y_ = arrays_transformer.transform(output[0], y_)
             ^^^^^^^^^^^^^^^^^^^^^^^^^^^^^^^^^^^^^^^^^^^
  File "/usr/local/python/3.12.1/lib/python3.12/site-packages/imblearn/utils/_validation.py", line 40, in transform
    X = self._transfrom_one(X, self.x_props)
        ^^^^^^^^^^^^^^^^^^^^^^^^^^^^^^^^^^^^
  File "/usr/local/python/3.12.1/lib/python3.12/site-packages/imblearn/utils/_validation.py", line 86, in _transfrom_one
    ret = ret.astype(props["dtypes"])
          ^^^^^^^^^^^^^^^^^^^^^^^^^^^
  File "/home/codespace/.local/lib/python3.12/site-packages/pandas/core/generic.py", line 6620, in astype
    res_col = col.astype(dtype=cdt, copy=copy, errors=errors)
              ^^^^^^^^^^^^^^^^^^^^^^^^^^^^^^^^^^^^^^^^^^^^^^^
  File "/home/codespace/.local/lib/python3.12/site-packages/pandas/core/generic.py", line 6643, in astype
    new_data = self._mgr.astype(dtype=dtype, copy=copy, errors=errors)
               ^^^^^^^^^^^^^^^^^^^^^^^^^^^^^^^^^^^^^^^^^^^^^^^^^^^^^^^
  File "/home/codespace/.local/lib/python3.12/site-packages/pandas/core/internals/managers.py", line 430, in astype
    return self.apply(
           ^^^^^^^^^^^
  File "/home/codespace/.local/lib/python3.12/site-packages/pandas/core/internals/managers.py", line 363, in apply
    applied = getattr(b, f)(**kwargs)
              ^^^^^^^^^^^^^^^^^^^^^^^
  File "/home/codespace/.local/lib/python3.12/site-packages/pandas/core/internals/blocks.py", line 758, in astype
    new_values = astype_array_safe(values, dtype, copy=copy, errors=errors)
                 ^^^^^^^^^^^^^^^^^^^^^^^^^^^^^^^^^^^^^^^^^^^^^^^^^^^^^^^^^^
  File "/home/codespace/.local/lib/python3.12/site-packages/pandas/core/dtypes/astype.py", line 237, in astype_array_safe
    new_values = astype_array(values, dtype, copy=copy)
                 ^^^^^^^^^^^^^^^^^^^^^^^^^^^^^^^^^^^^^^
  File "/home/codespace/.local/lib/python3.12/site-packages/pandas/core/dtypes/astype.py", line 182, in astype_array
    values = _astype_nansafe(values, dtype, copy=copy)
             ^^^^^^^^^^^^^^^^^^^^^^^^^^^^^^^^^^^^^^^^^
  File "/home/codespace/.local/lib/python3.12/site-packages/pandas/core/dtypes/astype.py", line 80, in _astype_nansafe
    return dtype.construct_array_type()._from_sequence(arr, dtype=dtype, copy=copy)
           ^^^^^^^^^^^^^^^^^^^^^^^^^^^^^^^^^^^^^^^^^^^^^^^^^^^^^^^^^^^^^^^^^^^^^^^^
  File "/home/codespace/.local/lib/python3.12/site-packages/pandas/core/arrays/masked.py", line 152, in _from_sequence
    values, mask = cls._coerce_to_array(scalars, dtype=dtype, copy=copy)
                   ^^^^^^^^^^^^^^^^^^^^^^^^^^^^^^^^^^^^^^^^^^^^^^^^^^^^^
  File "/home/codespace/.local/lib/python3.12/site-packages/pandas/core/arrays/numeric.py", line 272, in _coerce_to_array
    values, mask, _, _ = _coerce_to_data_and_mask(
                         ^^^^^^^^^^^^^^^^^^^^^^^^^
  File "/home/codespace/.local/lib/python3.12/site-packages/pandas/core/arrays/numeric.py", line 229, in _coerce_to_data_and_mask
    values = dtype_cls._safe_cast(values, dtype, copy=False)
             ^^^^^^^^^^^^^^^^^^^^^^^^^^^^^^^^^^^^^^^^^^^^^^^
  File "/home/codespace/.local/lib/python3.12/site-packages/pandas/core/arrays/integer.py", line 59, in _safe_cast
    raise TypeError(
TypeError: cannot safely cast non-equivalent float64 to uint32
2025-01-05 05:38:22,946 - CRITICAL - Pipeline execution failed: cannot safely cast non-equivalent float64 to uint32
2025-01-05 05:38:37,801 - INFO - Starting preprocessing pipeline.
2025-01-05 05:38:37,888 - INFO - None
2025-01-05 05:38:37,921 - INFO - Dataset loaded successfully. None
2025-01-05 05:38:37,953 - INFO - Target encoding completed.
2025-01-05 05:38:38,011 - INFO - Categorical encoding completed.
2025-01-05 05:38:38,051 - INFO - Holiday-related features created.
2025-01-05 05:38:38,066 - INFO - Normalization completed.
2025-01-05 05:38:38,088 - INFO - Rolling and expanding features generated.
2025-01-05 05:38:38,098 - INFO - Lag features generated.
2025-01-05 05:38:38,125 - INFO - Dropped NaN values. Preprocessing complete.
2025-01-05 05:38:53,914 - ERROR - An error occurred during preprocessing: cannot safely cast non-equivalent float64 to uint32
Traceback (most recent call last):
  File "/home/codespace/.local/lib/python3.12/site-packages/pandas/core/arrays/integer.py", line 53, in _safe_cast
    return values.astype(dtype, casting="safe", copy=copy)
           ^^^^^^^^^^^^^^^^^^^^^^^^^^^^^^^^^^^^^^^^^^^^^^^
TypeError: Cannot cast array data from dtype('float64') to dtype('uint32') according to the rule 'safe'

The above exception was the direct cause of the following exception:

Traceback (most recent call last):
  File "/usr/local/python/3.12.1/lib/python3.12/site-packages/imblearn/utils/_validation.py", line 71, in _transfrom_one
    ret = ret.astype(props["dtypes"])
          ^^^^^^^^^^^^^^^^^^^^^^^^^^^
  File "/home/codespace/.local/lib/python3.12/site-packages/pandas/core/generic.py", line 6620, in astype
    res_col = col.astype(dtype=cdt, copy=copy, errors=errors)
              ^^^^^^^^^^^^^^^^^^^^^^^^^^^^^^^^^^^^^^^^^^^^^^^
  File "/home/codespace/.local/lib/python3.12/site-packages/pandas/core/generic.py", line 6643, in astype
    new_data = self._mgr.astype(dtype=dtype, copy=copy, errors=errors)
               ^^^^^^^^^^^^^^^^^^^^^^^^^^^^^^^^^^^^^^^^^^^^^^^^^^^^^^^
  File "/home/codespace/.local/lib/python3.12/site-packages/pandas/core/internals/managers.py", line 430, in astype
    return self.apply(
           ^^^^^^^^^^^
  File "/home/codespace/.local/lib/python3.12/site-packages/pandas/core/internals/managers.py", line 363, in apply
    applied = getattr(b, f)(**kwargs)
              ^^^^^^^^^^^^^^^^^^^^^^^
  File "/home/codespace/.local/lib/python3.12/site-packages/pandas/core/internals/blocks.py", line 758, in astype
    new_values = astype_array_safe(values, dtype, copy=copy, errors=errors)
                 ^^^^^^^^^^^^^^^^^^^^^^^^^^^^^^^^^^^^^^^^^^^^^^^^^^^^^^^^^^
  File "/home/codespace/.local/lib/python3.12/site-packages/pandas/core/dtypes/astype.py", line 237, in astype_array_safe
    new_values = astype_array(values, dtype, copy=copy)
                 ^^^^^^^^^^^^^^^^^^^^^^^^^^^^^^^^^^^^^^
  File "/home/codespace/.local/lib/python3.12/site-packages/pandas/core/dtypes/astype.py", line 182, in astype_array
    values = _astype_nansafe(values, dtype, copy=copy)
             ^^^^^^^^^^^^^^^^^^^^^^^^^^^^^^^^^^^^^^^^^
  File "/home/codespace/.local/lib/python3.12/site-packages/pandas/core/dtypes/astype.py", line 80, in _astype_nansafe
    return dtype.construct_array_type()._from_sequence(arr, dtype=dtype, copy=copy)
           ^^^^^^^^^^^^^^^^^^^^^^^^^^^^^^^^^^^^^^^^^^^^^^^^^^^^^^^^^^^^^^^^^^^^^^^^
  File "/home/codespace/.local/lib/python3.12/site-packages/pandas/core/arrays/masked.py", line 152, in _from_sequence
    values, mask = cls._coerce_to_array(scalars, dtype=dtype, copy=copy)
                   ^^^^^^^^^^^^^^^^^^^^^^^^^^^^^^^^^^^^^^^^^^^^^^^^^^^^^
  File "/home/codespace/.local/lib/python3.12/site-packages/pandas/core/arrays/numeric.py", line 272, in _coerce_to_array
    values, mask, _, _ = _coerce_to_data_and_mask(
                         ^^^^^^^^^^^^^^^^^^^^^^^^^
  File "/home/codespace/.local/lib/python3.12/site-packages/pandas/core/arrays/numeric.py", line 229, in _coerce_to_data_and_mask
    values = dtype_cls._safe_cast(values, dtype, copy=False)
             ^^^^^^^^^^^^^^^^^^^^^^^^^^^^^^^^^^^^^^^^^^^^^^^
  File "/home/codespace/.local/lib/python3.12/site-packages/pandas/core/arrays/integer.py", line 59, in _safe_cast
    raise TypeError(
TypeError: cannot safely cast non-equivalent float64 to uint32

During handling of the above exception, another exception occurred:

Traceback (most recent call last):
  File "/home/codespace/.local/lib/python3.12/site-packages/pandas/core/arrays/integer.py", line 53, in _safe_cast
    return values.astype(dtype, casting="safe", copy=copy)
           ^^^^^^^^^^^^^^^^^^^^^^^^^^^^^^^^^^^^^^^^^^^^^^^
TypeError: Cannot cast array data from dtype('float64') to dtype('uint32') according to the rule 'safe'

The above exception was the direct cause of the following exception:

Traceback (most recent call last):
  File "/workspaces/invenlytics/pipelines/v2/feature_pipeline.py", line 128, in run_supplychain_disruption_feature_pipeline
    X_resampled, y_resampled = smote_enn.fit_resample(X, y)
                               ^^^^^^^^^^^^^^^^^^^^^^^^^^^^
  File "/usr/local/python/3.12.1/lib/python3.12/site-packages/imblearn/base.py", line 202, in fit_resample
    return super().fit_resample(X, y, **params)
           ^^^^^^^^^^^^^^^^^^^^^^^^^^^^^^^^^^^^
  File "/usr/local/python/3.12.1/lib/python3.12/site-packages/sklearn/base.py", line 1473, in wrapper
    return fit_method(estimator, *args, **kwargs)
           ^^^^^^^^^^^^^^^^^^^^^^^^^^^^^^^^^^^^^^
  File "/usr/local/python/3.12.1/lib/python3.12/site-packages/imblearn/base.py", line 111, in fit_resample
    X_, y_ = arrays_transformer.transform(output[0], y_)
             ^^^^^^^^^^^^^^^^^^^^^^^^^^^^^^^^^^^^^^^^^^^
  File "/usr/local/python/3.12.1/lib/python3.12/site-packages/imblearn/utils/_validation.py", line 40, in transform
    X = self._transfrom_one(X, self.x_props)
        ^^^^^^^^^^^^^^^^^^^^^^^^^^^^^^^^^^^^
  File "/usr/local/python/3.12.1/lib/python3.12/site-packages/imblearn/utils/_validation.py", line 86, in _transfrom_one
    ret = ret.astype(props["dtypes"])
          ^^^^^^^^^^^^^^^^^^^^^^^^^^^
  File "/home/codespace/.local/lib/python3.12/site-packages/pandas/core/generic.py", line 6620, in astype
    res_col = col.astype(dtype=cdt, copy=copy, errors=errors)
              ^^^^^^^^^^^^^^^^^^^^^^^^^^^^^^^^^^^^^^^^^^^^^^^
  File "/home/codespace/.local/lib/python3.12/site-packages/pandas/core/generic.py", line 6643, in astype
    new_data = self._mgr.astype(dtype=dtype, copy=copy, errors=errors)
               ^^^^^^^^^^^^^^^^^^^^^^^^^^^^^^^^^^^^^^^^^^^^^^^^^^^^^^^
  File "/home/codespace/.local/lib/python3.12/site-packages/pandas/core/internals/managers.py", line 430, in astype
    return self.apply(
           ^^^^^^^^^^^
  File "/home/codespace/.local/lib/python3.12/site-packages/pandas/core/internals/managers.py", line 363, in apply
    applied = getattr(b, f)(**kwargs)
              ^^^^^^^^^^^^^^^^^^^^^^^
  File "/home/codespace/.local/lib/python3.12/site-packages/pandas/core/internals/blocks.py", line 758, in astype
    new_values = astype_array_safe(values, dtype, copy=copy, errors=errors)
                 ^^^^^^^^^^^^^^^^^^^^^^^^^^^^^^^^^^^^^^^^^^^^^^^^^^^^^^^^^^
  File "/home/codespace/.local/lib/python3.12/site-packages/pandas/core/dtypes/astype.py", line 237, in astype_array_safe
    new_values = astype_array(values, dtype, copy=copy)
                 ^^^^^^^^^^^^^^^^^^^^^^^^^^^^^^^^^^^^^^
  File "/home/codespace/.local/lib/python3.12/site-packages/pandas/core/dtypes/astype.py", line 182, in astype_array
    values = _astype_nansafe(values, dtype, copy=copy)
             ^^^^^^^^^^^^^^^^^^^^^^^^^^^^^^^^^^^^^^^^^
  File "/home/codespace/.local/lib/python3.12/site-packages/pandas/core/dtypes/astype.py", line 80, in _astype_nansafe
    return dtype.construct_array_type()._from_sequence(arr, dtype=dtype, copy=copy)
           ^^^^^^^^^^^^^^^^^^^^^^^^^^^^^^^^^^^^^^^^^^^^^^^^^^^^^^^^^^^^^^^^^^^^^^^^
  File "/home/codespace/.local/lib/python3.12/site-packages/pandas/core/arrays/masked.py", line 152, in _from_sequence
    values, mask = cls._coerce_to_array(scalars, dtype=dtype, copy=copy)
                   ^^^^^^^^^^^^^^^^^^^^^^^^^^^^^^^^^^^^^^^^^^^^^^^^^^^^^
  File "/home/codespace/.local/lib/python3.12/site-packages/pandas/core/arrays/numeric.py", line 272, in _coerce_to_array
    values, mask, _, _ = _coerce_to_data_and_mask(
                         ^^^^^^^^^^^^^^^^^^^^^^^^^
  File "/home/codespace/.local/lib/python3.12/site-packages/pandas/core/arrays/numeric.py", line 229, in _coerce_to_data_and_mask
    values = dtype_cls._safe_cast(values, dtype, copy=False)
             ^^^^^^^^^^^^^^^^^^^^^^^^^^^^^^^^^^^^^^^^^^^^^^^
  File "/home/codespace/.local/lib/python3.12/site-packages/pandas/core/arrays/integer.py", line 59, in _safe_cast
    raise TypeError(
TypeError: cannot safely cast non-equivalent float64 to uint32
2025-01-05 05:38:53,923 - CRITICAL - Pipeline execution failed: cannot safely cast non-equivalent float64 to uint32
2025-01-05 05:41:07,283 - INFO - Starting preprocessing pipeline.
2025-01-05 05:41:07,373 - INFO - None
2025-01-05 05:41:07,404 - INFO - Dataset loaded successfully. None
2025-01-05 05:41:07,459 - INFO - Target encoding completed.
2025-01-05 05:41:07,569 - INFO - Categorical encoding completed.
2025-01-05 05:41:07,608 - INFO - Holiday-related features created.
2025-01-05 05:41:07,621 - INFO - Normalization completed.
2025-01-05 05:41:07,643 - INFO - Rolling and expanding features generated.
2025-01-05 05:41:07,653 - INFO - Lag features generated.
2025-01-05 05:41:07,680 - INFO - Dropped NaN values. Preprocessing complete.
2025-01-05 05:41:23,314 - ERROR - An error occurred during preprocessing: cannot safely cast non-equivalent float64 to uint32
Traceback (most recent call last):
  File "/home/codespace/.local/lib/python3.12/site-packages/pandas/core/arrays/integer.py", line 53, in _safe_cast
    return values.astype(dtype, casting="safe", copy=copy)
           ^^^^^^^^^^^^^^^^^^^^^^^^^^^^^^^^^^^^^^^^^^^^^^^
TypeError: Cannot cast array data from dtype('float64') to dtype('uint32') according to the rule 'safe'

The above exception was the direct cause of the following exception:

Traceback (most recent call last):
  File "/usr/local/python/3.12.1/lib/python3.12/site-packages/imblearn/utils/_validation.py", line 71, in _transfrom_one
    ret = ret.astype(props["dtypes"])
          ^^^^^^^^^^^^^^^^^^^^^^^^^^^
  File "/home/codespace/.local/lib/python3.12/site-packages/pandas/core/generic.py", line 6620, in astype
    res_col = col.astype(dtype=cdt, copy=copy, errors=errors)
              ^^^^^^^^^^^^^^^^^^^^^^^^^^^^^^^^^^^^^^^^^^^^^^^
  File "/home/codespace/.local/lib/python3.12/site-packages/pandas/core/generic.py", line 6643, in astype
    new_data = self._mgr.astype(dtype=dtype, copy=copy, errors=errors)
               ^^^^^^^^^^^^^^^^^^^^^^^^^^^^^^^^^^^^^^^^^^^^^^^^^^^^^^^
  File "/home/codespace/.local/lib/python3.12/site-packages/pandas/core/internals/managers.py", line 430, in astype
    return self.apply(
           ^^^^^^^^^^^
  File "/home/codespace/.local/lib/python3.12/site-packages/pandas/core/internals/managers.py", line 363, in apply
    applied = getattr(b, f)(**kwargs)
              ^^^^^^^^^^^^^^^^^^^^^^^
  File "/home/codespace/.local/lib/python3.12/site-packages/pandas/core/internals/blocks.py", line 758, in astype
    new_values = astype_array_safe(values, dtype, copy=copy, errors=errors)
                 ^^^^^^^^^^^^^^^^^^^^^^^^^^^^^^^^^^^^^^^^^^^^^^^^^^^^^^^^^^
  File "/home/codespace/.local/lib/python3.12/site-packages/pandas/core/dtypes/astype.py", line 237, in astype_array_safe
    new_values = astype_array(values, dtype, copy=copy)
                 ^^^^^^^^^^^^^^^^^^^^^^^^^^^^^^^^^^^^^^
  File "/home/codespace/.local/lib/python3.12/site-packages/pandas/core/dtypes/astype.py", line 182, in astype_array
    values = _astype_nansafe(values, dtype, copy=copy)
             ^^^^^^^^^^^^^^^^^^^^^^^^^^^^^^^^^^^^^^^^^
  File "/home/codespace/.local/lib/python3.12/site-packages/pandas/core/dtypes/astype.py", line 80, in _astype_nansafe
    return dtype.construct_array_type()._from_sequence(arr, dtype=dtype, copy=copy)
           ^^^^^^^^^^^^^^^^^^^^^^^^^^^^^^^^^^^^^^^^^^^^^^^^^^^^^^^^^^^^^^^^^^^^^^^^
  File "/home/codespace/.local/lib/python3.12/site-packages/pandas/core/arrays/masked.py", line 152, in _from_sequence
    values, mask = cls._coerce_to_array(scalars, dtype=dtype, copy=copy)
                   ^^^^^^^^^^^^^^^^^^^^^^^^^^^^^^^^^^^^^^^^^^^^^^^^^^^^^
  File "/home/codespace/.local/lib/python3.12/site-packages/pandas/core/arrays/numeric.py", line 272, in _coerce_to_array
    values, mask, _, _ = _coerce_to_data_and_mask(
                         ^^^^^^^^^^^^^^^^^^^^^^^^^
  File "/home/codespace/.local/lib/python3.12/site-packages/pandas/core/arrays/numeric.py", line 229, in _coerce_to_data_and_mask
    values = dtype_cls._safe_cast(values, dtype, copy=False)
             ^^^^^^^^^^^^^^^^^^^^^^^^^^^^^^^^^^^^^^^^^^^^^^^
  File "/home/codespace/.local/lib/python3.12/site-packages/pandas/core/arrays/integer.py", line 59, in _safe_cast
    raise TypeError(
TypeError: cannot safely cast non-equivalent float64 to uint32

During handling of the above exception, another exception occurred:

Traceback (most recent call last):
  File "/home/codespace/.local/lib/python3.12/site-packages/pandas/core/arrays/integer.py", line 53, in _safe_cast
    return values.astype(dtype, casting="safe", copy=copy)
           ^^^^^^^^^^^^^^^^^^^^^^^^^^^^^^^^^^^^^^^^^^^^^^^
TypeError: Cannot cast array data from dtype('float64') to dtype('uint32') according to the rule 'safe'

The above exception was the direct cause of the following exception:

Traceback (most recent call last):
  File "/workspaces/invenlytics/pipelines/v2/feature_pipeline.py", line 128, in run_supplychain_disruption_feature_pipeline
    X_resampled, y_resampled = smote_enn.fit_resample(X, y)
                               ^^^^^^^^^^^^^^^^^^^^^^^^^^^^
  File "/usr/local/python/3.12.1/lib/python3.12/site-packages/imblearn/base.py", line 202, in fit_resample
    return super().fit_resample(X, y, **params)
           ^^^^^^^^^^^^^^^^^^^^^^^^^^^^^^^^^^^^
  File "/usr/local/python/3.12.1/lib/python3.12/site-packages/sklearn/base.py", line 1473, in wrapper
    return fit_method(estimator, *args, **kwargs)
           ^^^^^^^^^^^^^^^^^^^^^^^^^^^^^^^^^^^^^^
  File "/usr/local/python/3.12.1/lib/python3.12/site-packages/imblearn/base.py", line 111, in fit_resample
    X_, y_ = arrays_transformer.transform(output[0], y_)
             ^^^^^^^^^^^^^^^^^^^^^^^^^^^^^^^^^^^^^^^^^^^
  File "/usr/local/python/3.12.1/lib/python3.12/site-packages/imblearn/utils/_validation.py", line 40, in transform
    X = self._transfrom_one(X, self.x_props)
        ^^^^^^^^^^^^^^^^^^^^^^^^^^^^^^^^^^^^
  File "/usr/local/python/3.12.1/lib/python3.12/site-packages/imblearn/utils/_validation.py", line 86, in _transfrom_one
    ret = ret.astype(props["dtypes"])
          ^^^^^^^^^^^^^^^^^^^^^^^^^^^
  File "/home/codespace/.local/lib/python3.12/site-packages/pandas/core/generic.py", line 6620, in astype
    res_col = col.astype(dtype=cdt, copy=copy, errors=errors)
              ^^^^^^^^^^^^^^^^^^^^^^^^^^^^^^^^^^^^^^^^^^^^^^^
  File "/home/codespace/.local/lib/python3.12/site-packages/pandas/core/generic.py", line 6643, in astype
    new_data = self._mgr.astype(dtype=dtype, copy=copy, errors=errors)
               ^^^^^^^^^^^^^^^^^^^^^^^^^^^^^^^^^^^^^^^^^^^^^^^^^^^^^^^
  File "/home/codespace/.local/lib/python3.12/site-packages/pandas/core/internals/managers.py", line 430, in astype
    return self.apply(
           ^^^^^^^^^^^
  File "/home/codespace/.local/lib/python3.12/site-packages/pandas/core/internals/managers.py", line 363, in apply
    applied = getattr(b, f)(**kwargs)
              ^^^^^^^^^^^^^^^^^^^^^^^
  File "/home/codespace/.local/lib/python3.12/site-packages/pandas/core/internals/blocks.py", line 758, in astype
    new_values = astype_array_safe(values, dtype, copy=copy, errors=errors)
                 ^^^^^^^^^^^^^^^^^^^^^^^^^^^^^^^^^^^^^^^^^^^^^^^^^^^^^^^^^^
  File "/home/codespace/.local/lib/python3.12/site-packages/pandas/core/dtypes/astype.py", line 237, in astype_array_safe
    new_values = astype_array(values, dtype, copy=copy)
                 ^^^^^^^^^^^^^^^^^^^^^^^^^^^^^^^^^^^^^^
  File "/home/codespace/.local/lib/python3.12/site-packages/pandas/core/dtypes/astype.py", line 182, in astype_array
    values = _astype_nansafe(values, dtype, copy=copy)
             ^^^^^^^^^^^^^^^^^^^^^^^^^^^^^^^^^^^^^^^^^
  File "/home/codespace/.local/lib/python3.12/site-packages/pandas/core/dtypes/astype.py", line 80, in _astype_nansafe
    return dtype.construct_array_type()._from_sequence(arr, dtype=dtype, copy=copy)
           ^^^^^^^^^^^^^^^^^^^^^^^^^^^^^^^^^^^^^^^^^^^^^^^^^^^^^^^^^^^^^^^^^^^^^^^^
  File "/home/codespace/.local/lib/python3.12/site-packages/pandas/core/arrays/masked.py", line 152, in _from_sequence
    values, mask = cls._coerce_to_array(scalars, dtype=dtype, copy=copy)
                   ^^^^^^^^^^^^^^^^^^^^^^^^^^^^^^^^^^^^^^^^^^^^^^^^^^^^^
  File "/home/codespace/.local/lib/python3.12/site-packages/pandas/core/arrays/numeric.py", line 272, in _coerce_to_array
    values, mask, _, _ = _coerce_to_data_and_mask(
                         ^^^^^^^^^^^^^^^^^^^^^^^^^
  File "/home/codespace/.local/lib/python3.12/site-packages/pandas/core/arrays/numeric.py", line 229, in _coerce_to_data_and_mask
    values = dtype_cls._safe_cast(values, dtype, copy=False)
             ^^^^^^^^^^^^^^^^^^^^^^^^^^^^^^^^^^^^^^^^^^^^^^^
  File "/home/codespace/.local/lib/python3.12/site-packages/pandas/core/arrays/integer.py", line 59, in _safe_cast
    raise TypeError(
TypeError: cannot safely cast non-equivalent float64 to uint32
2025-01-05 05:41:23,320 - CRITICAL - Pipeline execution failed: cannot safely cast non-equivalent float64 to uint32
2025-01-05 05:42:36,212 - INFO - Starting preprocessing pipeline.
2025-01-05 05:42:36,310 - INFO - None
2025-01-05 05:42:36,341 - INFO - Dataset loaded successfully. None
2025-01-05 05:42:36,372 - INFO - Target encoding completed.
2025-01-05 05:42:36,425 - INFO - Categorical encoding completed.
2025-01-05 05:42:36,464 - INFO - Holiday-related features created.
2025-01-05 05:42:36,478 - INFO - Normalization completed.
2025-01-05 05:42:36,500 - INFO - Rolling and expanding features generated.
2025-01-05 05:42:36,510 - INFO - Lag features generated.
2025-01-05 05:42:36,538 - INFO - Dropped NaN values. Preprocessing complete.
2025-01-05 05:42:52,317 - ERROR - An error occurred during preprocessing: cannot safely cast non-equivalent float64 to uint32
Traceback (most recent call last):
  File "/home/codespace/.local/lib/python3.12/site-packages/pandas/core/arrays/integer.py", line 53, in _safe_cast
    return values.astype(dtype, casting="safe", copy=copy)
           ^^^^^^^^^^^^^^^^^^^^^^^^^^^^^^^^^^^^^^^^^^^^^^^
TypeError: Cannot cast array data from dtype('float64') to dtype('uint32') according to the rule 'safe'

The above exception was the direct cause of the following exception:

Traceback (most recent call last):
  File "/usr/local/python/3.12.1/lib/python3.12/site-packages/imblearn/utils/_validation.py", line 71, in _transfrom_one
    ret = ret.astype(props["dtypes"])
          ^^^^^^^^^^^^^^^^^^^^^^^^^^^
  File "/home/codespace/.local/lib/python3.12/site-packages/pandas/core/generic.py", line 6620, in astype
    res_col = col.astype(dtype=cdt, copy=copy, errors=errors)
              ^^^^^^^^^^^^^^^^^^^^^^^^^^^^^^^^^^^^^^^^^^^^^^^
  File "/home/codespace/.local/lib/python3.12/site-packages/pandas/core/generic.py", line 6643, in astype
    new_data = self._mgr.astype(dtype=dtype, copy=copy, errors=errors)
               ^^^^^^^^^^^^^^^^^^^^^^^^^^^^^^^^^^^^^^^^^^^^^^^^^^^^^^^
  File "/home/codespace/.local/lib/python3.12/site-packages/pandas/core/internals/managers.py", line 430, in astype
    return self.apply(
           ^^^^^^^^^^^
  File "/home/codespace/.local/lib/python3.12/site-packages/pandas/core/internals/managers.py", line 363, in apply
    applied = getattr(b, f)(**kwargs)
              ^^^^^^^^^^^^^^^^^^^^^^^
  File "/home/codespace/.local/lib/python3.12/site-packages/pandas/core/internals/blocks.py", line 758, in astype
    new_values = astype_array_safe(values, dtype, copy=copy, errors=errors)
                 ^^^^^^^^^^^^^^^^^^^^^^^^^^^^^^^^^^^^^^^^^^^^^^^^^^^^^^^^^^
  File "/home/codespace/.local/lib/python3.12/site-packages/pandas/core/dtypes/astype.py", line 237, in astype_array_safe
    new_values = astype_array(values, dtype, copy=copy)
                 ^^^^^^^^^^^^^^^^^^^^^^^^^^^^^^^^^^^^^^
  File "/home/codespace/.local/lib/python3.12/site-packages/pandas/core/dtypes/astype.py", line 182, in astype_array
    values = _astype_nansafe(values, dtype, copy=copy)
             ^^^^^^^^^^^^^^^^^^^^^^^^^^^^^^^^^^^^^^^^^
  File "/home/codespace/.local/lib/python3.12/site-packages/pandas/core/dtypes/astype.py", line 80, in _astype_nansafe
    return dtype.construct_array_type()._from_sequence(arr, dtype=dtype, copy=copy)
           ^^^^^^^^^^^^^^^^^^^^^^^^^^^^^^^^^^^^^^^^^^^^^^^^^^^^^^^^^^^^^^^^^^^^^^^^
  File "/home/codespace/.local/lib/python3.12/site-packages/pandas/core/arrays/masked.py", line 152, in _from_sequence
    values, mask = cls._coerce_to_array(scalars, dtype=dtype, copy=copy)
                   ^^^^^^^^^^^^^^^^^^^^^^^^^^^^^^^^^^^^^^^^^^^^^^^^^^^^^
  File "/home/codespace/.local/lib/python3.12/site-packages/pandas/core/arrays/numeric.py", line 272, in _coerce_to_array
    values, mask, _, _ = _coerce_to_data_and_mask(
                         ^^^^^^^^^^^^^^^^^^^^^^^^^
  File "/home/codespace/.local/lib/python3.12/site-packages/pandas/core/arrays/numeric.py", line 229, in _coerce_to_data_and_mask
    values = dtype_cls._safe_cast(values, dtype, copy=False)
             ^^^^^^^^^^^^^^^^^^^^^^^^^^^^^^^^^^^^^^^^^^^^^^^
  File "/home/codespace/.local/lib/python3.12/site-packages/pandas/core/arrays/integer.py", line 59, in _safe_cast
    raise TypeError(
TypeError: cannot safely cast non-equivalent float64 to uint32

During handling of the above exception, another exception occurred:

Traceback (most recent call last):
  File "/home/codespace/.local/lib/python3.12/site-packages/pandas/core/arrays/integer.py", line 53, in _safe_cast
    return values.astype(dtype, casting="safe", copy=copy)
           ^^^^^^^^^^^^^^^^^^^^^^^^^^^^^^^^^^^^^^^^^^^^^^^
TypeError: Cannot cast array data from dtype('float64') to dtype('uint32') according to the rule 'safe'

The above exception was the direct cause of the following exception:

Traceback (most recent call last):
  File "/workspaces/invenlytics/pipelines/v2/feature_pipeline.py", line 128, in run_supplychain_disruption_feature_pipeline
    X_resampled, y_resampled = smote_enn.fit_resample(X, y)
                               ^^^^^^^^^^^^^^^^^^^^^^^^^^^^
  File "/usr/local/python/3.12.1/lib/python3.12/site-packages/imblearn/base.py", line 202, in fit_resample
    return super().fit_resample(X, y, **params)
           ^^^^^^^^^^^^^^^^^^^^^^^^^^^^^^^^^^^^
  File "/usr/local/python/3.12.1/lib/python3.12/site-packages/sklearn/base.py", line 1473, in wrapper
    return fit_method(estimator, *args, **kwargs)
           ^^^^^^^^^^^^^^^^^^^^^^^^^^^^^^^^^^^^^^
  File "/usr/local/python/3.12.1/lib/python3.12/site-packages/imblearn/base.py", line 111, in fit_resample
    X_, y_ = arrays_transformer.transform(output[0], y_)
             ^^^^^^^^^^^^^^^^^^^^^^^^^^^^^^^^^^^^^^^^^^^
  File "/usr/local/python/3.12.1/lib/python3.12/site-packages/imblearn/utils/_validation.py", line 40, in transform
    X = self._transfrom_one(X, self.x_props)
        ^^^^^^^^^^^^^^^^^^^^^^^^^^^^^^^^^^^^
  File "/usr/local/python/3.12.1/lib/python3.12/site-packages/imblearn/utils/_validation.py", line 86, in _transfrom_one
    ret = ret.astype(props["dtypes"])
          ^^^^^^^^^^^^^^^^^^^^^^^^^^^
  File "/home/codespace/.local/lib/python3.12/site-packages/pandas/core/generic.py", line 6620, in astype
    res_col = col.astype(dtype=cdt, copy=copy, errors=errors)
              ^^^^^^^^^^^^^^^^^^^^^^^^^^^^^^^^^^^^^^^^^^^^^^^
  File "/home/codespace/.local/lib/python3.12/site-packages/pandas/core/generic.py", line 6643, in astype
    new_data = self._mgr.astype(dtype=dtype, copy=copy, errors=errors)
               ^^^^^^^^^^^^^^^^^^^^^^^^^^^^^^^^^^^^^^^^^^^^^^^^^^^^^^^
  File "/home/codespace/.local/lib/python3.12/site-packages/pandas/core/internals/managers.py", line 430, in astype
    return self.apply(
           ^^^^^^^^^^^
  File "/home/codespace/.local/lib/python3.12/site-packages/pandas/core/internals/managers.py", line 363, in apply
    applied = getattr(b, f)(**kwargs)
              ^^^^^^^^^^^^^^^^^^^^^^^
  File "/home/codespace/.local/lib/python3.12/site-packages/pandas/core/internals/blocks.py", line 758, in astype
    new_values = astype_array_safe(values, dtype, copy=copy, errors=errors)
                 ^^^^^^^^^^^^^^^^^^^^^^^^^^^^^^^^^^^^^^^^^^^^^^^^^^^^^^^^^^
  File "/home/codespace/.local/lib/python3.12/site-packages/pandas/core/dtypes/astype.py", line 237, in astype_array_safe
    new_values = astype_array(values, dtype, copy=copy)
                 ^^^^^^^^^^^^^^^^^^^^^^^^^^^^^^^^^^^^^^
  File "/home/codespace/.local/lib/python3.12/site-packages/pandas/core/dtypes/astype.py", line 182, in astype_array
    values = _astype_nansafe(values, dtype, copy=copy)
             ^^^^^^^^^^^^^^^^^^^^^^^^^^^^^^^^^^^^^^^^^
  File "/home/codespace/.local/lib/python3.12/site-packages/pandas/core/dtypes/astype.py", line 80, in _astype_nansafe
    return dtype.construct_array_type()._from_sequence(arr, dtype=dtype, copy=copy)
           ^^^^^^^^^^^^^^^^^^^^^^^^^^^^^^^^^^^^^^^^^^^^^^^^^^^^^^^^^^^^^^^^^^^^^^^^
  File "/home/codespace/.local/lib/python3.12/site-packages/pandas/core/arrays/masked.py", line 152, in _from_sequence
    values, mask = cls._coerce_to_array(scalars, dtype=dtype, copy=copy)
                   ^^^^^^^^^^^^^^^^^^^^^^^^^^^^^^^^^^^^^^^^^^^^^^^^^^^^^
  File "/home/codespace/.local/lib/python3.12/site-packages/pandas/core/arrays/numeric.py", line 272, in _coerce_to_array
    values, mask, _, _ = _coerce_to_data_and_mask(
                         ^^^^^^^^^^^^^^^^^^^^^^^^^
  File "/home/codespace/.local/lib/python3.12/site-packages/pandas/core/arrays/numeric.py", line 229, in _coerce_to_data_and_mask
    values = dtype_cls._safe_cast(values, dtype, copy=False)
             ^^^^^^^^^^^^^^^^^^^^^^^^^^^^^^^^^^^^^^^^^^^^^^^
  File "/home/codespace/.local/lib/python3.12/site-packages/pandas/core/arrays/integer.py", line 59, in _safe_cast
    raise TypeError(
TypeError: cannot safely cast non-equivalent float64 to uint32
2025-01-05 05:42:52,323 - CRITICAL - Pipeline execution failed: cannot safely cast non-equivalent float64 to uint32
2025-01-05 05:43:18,489 - INFO - Starting preprocessing pipeline.
2025-01-05 05:43:18,585 - INFO - None
2025-01-05 05:43:18,623 - INFO - Dataset loaded successfully. None
2025-01-05 05:43:18,671 - INFO - Target encoding completed.
2025-01-05 05:43:18,727 - INFO - Categorical encoding completed.
2025-01-05 05:43:18,766 - INFO - Holiday-related features created.
2025-01-05 05:43:18,779 - INFO - Normalization completed.
2025-01-05 05:43:18,801 - INFO - Rolling and expanding features generated.
2025-01-05 05:43:18,811 - INFO - Lag features generated.
2025-01-05 05:43:18,838 - INFO - Dropped NaN values. Preprocessing complete.
2025-01-05 05:43:34,354 - ERROR - An error occurred during preprocessing: cannot safely cast non-equivalent float64 to uint32
Traceback (most recent call last):
  File "/home/codespace/.local/lib/python3.12/site-packages/pandas/core/arrays/integer.py", line 53, in _safe_cast
    return values.astype(dtype, casting="safe", copy=copy)
           ^^^^^^^^^^^^^^^^^^^^^^^^^^^^^^^^^^^^^^^^^^^^^^^
TypeError: Cannot cast array data from dtype('float64') to dtype('uint32') according to the rule 'safe'

The above exception was the direct cause of the following exception:

Traceback (most recent call last):
  File "/usr/local/python/3.12.1/lib/python3.12/site-packages/imblearn/utils/_validation.py", line 71, in _transfrom_one
    ret = ret.astype(props["dtypes"])
          ^^^^^^^^^^^^^^^^^^^^^^^^^^^
  File "/home/codespace/.local/lib/python3.12/site-packages/pandas/core/generic.py", line 6620, in astype
    res_col = col.astype(dtype=cdt, copy=copy, errors=errors)
              ^^^^^^^^^^^^^^^^^^^^^^^^^^^^^^^^^^^^^^^^^^^^^^^
  File "/home/codespace/.local/lib/python3.12/site-packages/pandas/core/generic.py", line 6643, in astype
    new_data = self._mgr.astype(dtype=dtype, copy=copy, errors=errors)
               ^^^^^^^^^^^^^^^^^^^^^^^^^^^^^^^^^^^^^^^^^^^^^^^^^^^^^^^
  File "/home/codespace/.local/lib/python3.12/site-packages/pandas/core/internals/managers.py", line 430, in astype
    return self.apply(
           ^^^^^^^^^^^
  File "/home/codespace/.local/lib/python3.12/site-packages/pandas/core/internals/managers.py", line 363, in apply
    applied = getattr(b, f)(**kwargs)
              ^^^^^^^^^^^^^^^^^^^^^^^
  File "/home/codespace/.local/lib/python3.12/site-packages/pandas/core/internals/blocks.py", line 758, in astype
    new_values = astype_array_safe(values, dtype, copy=copy, errors=errors)
                 ^^^^^^^^^^^^^^^^^^^^^^^^^^^^^^^^^^^^^^^^^^^^^^^^^^^^^^^^^^
  File "/home/codespace/.local/lib/python3.12/site-packages/pandas/core/dtypes/astype.py", line 237, in astype_array_safe
    new_values = astype_array(values, dtype, copy=copy)
                 ^^^^^^^^^^^^^^^^^^^^^^^^^^^^^^^^^^^^^^
  File "/home/codespace/.local/lib/python3.12/site-packages/pandas/core/dtypes/astype.py", line 182, in astype_array
    values = _astype_nansafe(values, dtype, copy=copy)
             ^^^^^^^^^^^^^^^^^^^^^^^^^^^^^^^^^^^^^^^^^
  File "/home/codespace/.local/lib/python3.12/site-packages/pandas/core/dtypes/astype.py", line 80, in _astype_nansafe
    return dtype.construct_array_type()._from_sequence(arr, dtype=dtype, copy=copy)
           ^^^^^^^^^^^^^^^^^^^^^^^^^^^^^^^^^^^^^^^^^^^^^^^^^^^^^^^^^^^^^^^^^^^^^^^^
  File "/home/codespace/.local/lib/python3.12/site-packages/pandas/core/arrays/masked.py", line 152, in _from_sequence
    values, mask = cls._coerce_to_array(scalars, dtype=dtype, copy=copy)
                   ^^^^^^^^^^^^^^^^^^^^^^^^^^^^^^^^^^^^^^^^^^^^^^^^^^^^^
  File "/home/codespace/.local/lib/python3.12/site-packages/pandas/core/arrays/numeric.py", line 272, in _coerce_to_array
    values, mask, _, _ = _coerce_to_data_and_mask(
                         ^^^^^^^^^^^^^^^^^^^^^^^^^
  File "/home/codespace/.local/lib/python3.12/site-packages/pandas/core/arrays/numeric.py", line 229, in _coerce_to_data_and_mask
    values = dtype_cls._safe_cast(values, dtype, copy=False)
             ^^^^^^^^^^^^^^^^^^^^^^^^^^^^^^^^^^^^^^^^^^^^^^^
  File "/home/codespace/.local/lib/python3.12/site-packages/pandas/core/arrays/integer.py", line 59, in _safe_cast
    raise TypeError(
TypeError: cannot safely cast non-equivalent float64 to uint32

During handling of the above exception, another exception occurred:

Traceback (most recent call last):
  File "/home/codespace/.local/lib/python3.12/site-packages/pandas/core/arrays/integer.py", line 53, in _safe_cast
    return values.astype(dtype, casting="safe", copy=copy)
           ^^^^^^^^^^^^^^^^^^^^^^^^^^^^^^^^^^^^^^^^^^^^^^^
TypeError: Cannot cast array data from dtype('float64') to dtype('uint32') according to the rule 'safe'

The above exception was the direct cause of the following exception:

Traceback (most recent call last):
  File "/workspaces/invenlytics/pipelines/v2/feature_pipeline.py", line 128, in run_supplychain_disruption_feature_pipeline
    X_resampled, y_resampled = smote_enn.fit_resample(X, y)
                               ^^^^^^^^^^^^^^^^^^^^^^^^^^^^
  File "/usr/local/python/3.12.1/lib/python3.12/site-packages/imblearn/base.py", line 202, in fit_resample
    return super().fit_resample(X, y, **params)
           ^^^^^^^^^^^^^^^^^^^^^^^^^^^^^^^^^^^^
  File "/usr/local/python/3.12.1/lib/python3.12/site-packages/sklearn/base.py", line 1473, in wrapper
    return fit_method(estimator, *args, **kwargs)
           ^^^^^^^^^^^^^^^^^^^^^^^^^^^^^^^^^^^^^^
  File "/usr/local/python/3.12.1/lib/python3.12/site-packages/imblearn/base.py", line 111, in fit_resample
    X_, y_ = arrays_transformer.transform(output[0], y_)
             ^^^^^^^^^^^^^^^^^^^^^^^^^^^^^^^^^^^^^^^^^^^
  File "/usr/local/python/3.12.1/lib/python3.12/site-packages/imblearn/utils/_validation.py", line 40, in transform
    X = self._transfrom_one(X, self.x_props)
        ^^^^^^^^^^^^^^^^^^^^^^^^^^^^^^^^^^^^
  File "/usr/local/python/3.12.1/lib/python3.12/site-packages/imblearn/utils/_validation.py", line 86, in _transfrom_one
    ret = ret.astype(props["dtypes"])
          ^^^^^^^^^^^^^^^^^^^^^^^^^^^
  File "/home/codespace/.local/lib/python3.12/site-packages/pandas/core/generic.py", line 6620, in astype
    res_col = col.astype(dtype=cdt, copy=copy, errors=errors)
              ^^^^^^^^^^^^^^^^^^^^^^^^^^^^^^^^^^^^^^^^^^^^^^^
  File "/home/codespace/.local/lib/python3.12/site-packages/pandas/core/generic.py", line 6643, in astype
    new_data = self._mgr.astype(dtype=dtype, copy=copy, errors=errors)
               ^^^^^^^^^^^^^^^^^^^^^^^^^^^^^^^^^^^^^^^^^^^^^^^^^^^^^^^
  File "/home/codespace/.local/lib/python3.12/site-packages/pandas/core/internals/managers.py", line 430, in astype
    return self.apply(
           ^^^^^^^^^^^
  File "/home/codespace/.local/lib/python3.12/site-packages/pandas/core/internals/managers.py", line 363, in apply
    applied = getattr(b, f)(**kwargs)
              ^^^^^^^^^^^^^^^^^^^^^^^
  File "/home/codespace/.local/lib/python3.12/site-packages/pandas/core/internals/blocks.py", line 758, in astype
    new_values = astype_array_safe(values, dtype, copy=copy, errors=errors)
                 ^^^^^^^^^^^^^^^^^^^^^^^^^^^^^^^^^^^^^^^^^^^^^^^^^^^^^^^^^^
  File "/home/codespace/.local/lib/python3.12/site-packages/pandas/core/dtypes/astype.py", line 237, in astype_array_safe
    new_values = astype_array(values, dtype, copy=copy)
                 ^^^^^^^^^^^^^^^^^^^^^^^^^^^^^^^^^^^^^^
  File "/home/codespace/.local/lib/python3.12/site-packages/pandas/core/dtypes/astype.py", line 182, in astype_array
    values = _astype_nansafe(values, dtype, copy=copy)
             ^^^^^^^^^^^^^^^^^^^^^^^^^^^^^^^^^^^^^^^^^
  File "/home/codespace/.local/lib/python3.12/site-packages/pandas/core/dtypes/astype.py", line 80, in _astype_nansafe
    return dtype.construct_array_type()._from_sequence(arr, dtype=dtype, copy=copy)
           ^^^^^^^^^^^^^^^^^^^^^^^^^^^^^^^^^^^^^^^^^^^^^^^^^^^^^^^^^^^^^^^^^^^^^^^^
  File "/home/codespace/.local/lib/python3.12/site-packages/pandas/core/arrays/masked.py", line 152, in _from_sequence
    values, mask = cls._coerce_to_array(scalars, dtype=dtype, copy=copy)
                   ^^^^^^^^^^^^^^^^^^^^^^^^^^^^^^^^^^^^^^^^^^^^^^^^^^^^^
  File "/home/codespace/.local/lib/python3.12/site-packages/pandas/core/arrays/numeric.py", line 272, in _coerce_to_array
    values, mask, _, _ = _coerce_to_data_and_mask(
                         ^^^^^^^^^^^^^^^^^^^^^^^^^
  File "/home/codespace/.local/lib/python3.12/site-packages/pandas/core/arrays/numeric.py", line 229, in _coerce_to_data_and_mask
    values = dtype_cls._safe_cast(values, dtype, copy=False)
             ^^^^^^^^^^^^^^^^^^^^^^^^^^^^^^^^^^^^^^^^^^^^^^^
  File "/home/codespace/.local/lib/python3.12/site-packages/pandas/core/arrays/integer.py", line 59, in _safe_cast
    raise TypeError(
TypeError: cannot safely cast non-equivalent float64 to uint32
2025-01-05 05:43:34,359 - CRITICAL - Pipeline execution failed: cannot safely cast non-equivalent float64 to uint32
2025-01-05 05:44:24,437 - INFO - Starting preprocessing pipeline.
2025-01-05 05:44:24,525 - INFO - None
2025-01-05 05:44:24,557 - INFO - Dataset loaded successfully. None
2025-01-05 05:44:24,587 - INFO - Target encoding completed.
2025-01-05 05:44:24,639 - INFO - Categorical encoding completed.
2025-01-05 05:44:24,678 - INFO - Holiday-related features created.
2025-01-05 05:44:24,692 - INFO - Normalization completed.
2025-01-05 05:44:24,715 - INFO - Rolling and expanding features generated.
2025-01-05 05:44:24,724 - INFO - Lag features generated.
2025-01-05 05:44:24,751 - INFO - Dropped NaN values. Preprocessing complete.
2025-01-05 05:44:40,310 - ERROR - An error occurred during preprocessing: cannot safely cast non-equivalent float64 to uint32
Traceback (most recent call last):
  File "/home/codespace/.local/lib/python3.12/site-packages/pandas/core/arrays/integer.py", line 53, in _safe_cast
    return values.astype(dtype, casting="safe", copy=copy)
           ^^^^^^^^^^^^^^^^^^^^^^^^^^^^^^^^^^^^^^^^^^^^^^^
TypeError: Cannot cast array data from dtype('float64') to dtype('uint32') according to the rule 'safe'

The above exception was the direct cause of the following exception:

Traceback (most recent call last):
  File "/usr/local/python/3.12.1/lib/python3.12/site-packages/imblearn/utils/_validation.py", line 71, in _transfrom_one
    ret = ret.astype(props["dtypes"])
          ^^^^^^^^^^^^^^^^^^^^^^^^^^^
  File "/home/codespace/.local/lib/python3.12/site-packages/pandas/core/generic.py", line 6620, in astype
    res_col = col.astype(dtype=cdt, copy=copy, errors=errors)
              ^^^^^^^^^^^^^^^^^^^^^^^^^^^^^^^^^^^^^^^^^^^^^^^
  File "/home/codespace/.local/lib/python3.12/site-packages/pandas/core/generic.py", line 6643, in astype
    new_data = self._mgr.astype(dtype=dtype, copy=copy, errors=errors)
               ^^^^^^^^^^^^^^^^^^^^^^^^^^^^^^^^^^^^^^^^^^^^^^^^^^^^^^^
  File "/home/codespace/.local/lib/python3.12/site-packages/pandas/core/internals/managers.py", line 430, in astype
    return self.apply(
           ^^^^^^^^^^^
  File "/home/codespace/.local/lib/python3.12/site-packages/pandas/core/internals/managers.py", line 363, in apply
    applied = getattr(b, f)(**kwargs)
              ^^^^^^^^^^^^^^^^^^^^^^^
  File "/home/codespace/.local/lib/python3.12/site-packages/pandas/core/internals/blocks.py", line 758, in astype
    new_values = astype_array_safe(values, dtype, copy=copy, errors=errors)
                 ^^^^^^^^^^^^^^^^^^^^^^^^^^^^^^^^^^^^^^^^^^^^^^^^^^^^^^^^^^
  File "/home/codespace/.local/lib/python3.12/site-packages/pandas/core/dtypes/astype.py", line 237, in astype_array_safe
    new_values = astype_array(values, dtype, copy=copy)
                 ^^^^^^^^^^^^^^^^^^^^^^^^^^^^^^^^^^^^^^
  File "/home/codespace/.local/lib/python3.12/site-packages/pandas/core/dtypes/astype.py", line 182, in astype_array
    values = _astype_nansafe(values, dtype, copy=copy)
             ^^^^^^^^^^^^^^^^^^^^^^^^^^^^^^^^^^^^^^^^^
  File "/home/codespace/.local/lib/python3.12/site-packages/pandas/core/dtypes/astype.py", line 80, in _astype_nansafe
    return dtype.construct_array_type()._from_sequence(arr, dtype=dtype, copy=copy)
           ^^^^^^^^^^^^^^^^^^^^^^^^^^^^^^^^^^^^^^^^^^^^^^^^^^^^^^^^^^^^^^^^^^^^^^^^
  File "/home/codespace/.local/lib/python3.12/site-packages/pandas/core/arrays/masked.py", line 152, in _from_sequence
    values, mask = cls._coerce_to_array(scalars, dtype=dtype, copy=copy)
                   ^^^^^^^^^^^^^^^^^^^^^^^^^^^^^^^^^^^^^^^^^^^^^^^^^^^^^
  File "/home/codespace/.local/lib/python3.12/site-packages/pandas/core/arrays/numeric.py", line 272, in _coerce_to_array
    values, mask, _, _ = _coerce_to_data_and_mask(
                         ^^^^^^^^^^^^^^^^^^^^^^^^^
  File "/home/codespace/.local/lib/python3.12/site-packages/pandas/core/arrays/numeric.py", line 229, in _coerce_to_data_and_mask
    values = dtype_cls._safe_cast(values, dtype, copy=False)
             ^^^^^^^^^^^^^^^^^^^^^^^^^^^^^^^^^^^^^^^^^^^^^^^
  File "/home/codespace/.local/lib/python3.12/site-packages/pandas/core/arrays/integer.py", line 59, in _safe_cast
    raise TypeError(
TypeError: cannot safely cast non-equivalent float64 to uint32

During handling of the above exception, another exception occurred:

Traceback (most recent call last):
  File "/home/codespace/.local/lib/python3.12/site-packages/pandas/core/arrays/integer.py", line 53, in _safe_cast
    return values.astype(dtype, casting="safe", copy=copy)
           ^^^^^^^^^^^^^^^^^^^^^^^^^^^^^^^^^^^^^^^^^^^^^^^
TypeError: Cannot cast array data from dtype('float64') to dtype('uint32') according to the rule 'safe'

The above exception was the direct cause of the following exception:

Traceback (most recent call last):
  File "/workspaces/invenlytics/pipelines/v2/feature_pipeline.py", line 128, in run_supplychain_disruption_feature_pipeline
    X_resampled, y_resampled = smote_enn.fit_resample(X, y)
                               ^^^^^^^^^^^^^^^^^^^^^^^^^^^^
  File "/usr/local/python/3.12.1/lib/python3.12/site-packages/imblearn/base.py", line 202, in fit_resample
    return super().fit_resample(X, y, **params)
           ^^^^^^^^^^^^^^^^^^^^^^^^^^^^^^^^^^^^
  File "/usr/local/python/3.12.1/lib/python3.12/site-packages/sklearn/base.py", line 1473, in wrapper
    return fit_method(estimator, *args, **kwargs)
           ^^^^^^^^^^^^^^^^^^^^^^^^^^^^^^^^^^^^^^
  File "/usr/local/python/3.12.1/lib/python3.12/site-packages/imblearn/base.py", line 111, in fit_resample
    X_, y_ = arrays_transformer.transform(output[0], y_)
             ^^^^^^^^^^^^^^^^^^^^^^^^^^^^^^^^^^^^^^^^^^^
  File "/usr/local/python/3.12.1/lib/python3.12/site-packages/imblearn/utils/_validation.py", line 40, in transform
    X = self._transfrom_one(X, self.x_props)
        ^^^^^^^^^^^^^^^^^^^^^^^^^^^^^^^^^^^^
  File "/usr/local/python/3.12.1/lib/python3.12/site-packages/imblearn/utils/_validation.py", line 86, in _transfrom_one
    ret = ret.astype(props["dtypes"])
          ^^^^^^^^^^^^^^^^^^^^^^^^^^^
  File "/home/codespace/.local/lib/python3.12/site-packages/pandas/core/generic.py", line 6620, in astype
    res_col = col.astype(dtype=cdt, copy=copy, errors=errors)
              ^^^^^^^^^^^^^^^^^^^^^^^^^^^^^^^^^^^^^^^^^^^^^^^
  File "/home/codespace/.local/lib/python3.12/site-packages/pandas/core/generic.py", line 6643, in astype
    new_data = self._mgr.astype(dtype=dtype, copy=copy, errors=errors)
               ^^^^^^^^^^^^^^^^^^^^^^^^^^^^^^^^^^^^^^^^^^^^^^^^^^^^^^^
  File "/home/codespace/.local/lib/python3.12/site-packages/pandas/core/internals/managers.py", line 430, in astype
    return self.apply(
           ^^^^^^^^^^^
  File "/home/codespace/.local/lib/python3.12/site-packages/pandas/core/internals/managers.py", line 363, in apply
    applied = getattr(b, f)(**kwargs)
              ^^^^^^^^^^^^^^^^^^^^^^^
  File "/home/codespace/.local/lib/python3.12/site-packages/pandas/core/internals/blocks.py", line 758, in astype
    new_values = astype_array_safe(values, dtype, copy=copy, errors=errors)
                 ^^^^^^^^^^^^^^^^^^^^^^^^^^^^^^^^^^^^^^^^^^^^^^^^^^^^^^^^^^
  File "/home/codespace/.local/lib/python3.12/site-packages/pandas/core/dtypes/astype.py", line 237, in astype_array_safe
    new_values = astype_array(values, dtype, copy=copy)
                 ^^^^^^^^^^^^^^^^^^^^^^^^^^^^^^^^^^^^^^
  File "/home/codespace/.local/lib/python3.12/site-packages/pandas/core/dtypes/astype.py", line 182, in astype_array
    values = _astype_nansafe(values, dtype, copy=copy)
             ^^^^^^^^^^^^^^^^^^^^^^^^^^^^^^^^^^^^^^^^^
  File "/home/codespace/.local/lib/python3.12/site-packages/pandas/core/dtypes/astype.py", line 80, in _astype_nansafe
    return dtype.construct_array_type()._from_sequence(arr, dtype=dtype, copy=copy)
           ^^^^^^^^^^^^^^^^^^^^^^^^^^^^^^^^^^^^^^^^^^^^^^^^^^^^^^^^^^^^^^^^^^^^^^^^
  File "/home/codespace/.local/lib/python3.12/site-packages/pandas/core/arrays/masked.py", line 152, in _from_sequence
    values, mask = cls._coerce_to_array(scalars, dtype=dtype, copy=copy)
                   ^^^^^^^^^^^^^^^^^^^^^^^^^^^^^^^^^^^^^^^^^^^^^^^^^^^^^
  File "/home/codespace/.local/lib/python3.12/site-packages/pandas/core/arrays/numeric.py", line 272, in _coerce_to_array
    values, mask, _, _ = _coerce_to_data_and_mask(
                         ^^^^^^^^^^^^^^^^^^^^^^^^^
  File "/home/codespace/.local/lib/python3.12/site-packages/pandas/core/arrays/numeric.py", line 229, in _coerce_to_data_and_mask
    values = dtype_cls._safe_cast(values, dtype, copy=False)
             ^^^^^^^^^^^^^^^^^^^^^^^^^^^^^^^^^^^^^^^^^^^^^^^
  File "/home/codespace/.local/lib/python3.12/site-packages/pandas/core/arrays/integer.py", line 59, in _safe_cast
    raise TypeError(
TypeError: cannot safely cast non-equivalent float64 to uint32
2025-01-05 05:44:40,316 - CRITICAL - Pipeline execution failed: cannot safely cast non-equivalent float64 to uint32
2025-01-05 05:45:29,695 - INFO - Starting preprocessing pipeline.
2025-01-05 05:45:29,780 - INFO - None
2025-01-05 05:45:29,813 - INFO - Dataset loaded successfully. None
2025-01-05 05:45:29,843 - INFO - Target encoding completed.
2025-01-05 05:45:29,900 - INFO - Categorical encoding completed.
2025-01-05 05:45:29,939 - INFO - Holiday-related features created.
2025-01-05 05:45:29,952 - INFO - Normalization completed.
2025-01-05 05:45:29,975 - INFO - Rolling and expanding features generated.
2025-01-05 05:45:29,985 - INFO - Lag features generated.
2025-01-05 05:45:30,012 - INFO - Dropped NaN values. Preprocessing complete.
2025-01-05 05:45:45,997 - ERROR - An error occurred during feature engineering: cannot safely cast non-equivalent float64 to uint32
Traceback (most recent call last):
  File "/home/codespace/.local/lib/python3.12/site-packages/pandas/core/arrays/integer.py", line 53, in _safe_cast
    return values.astype(dtype, casting="safe", copy=copy)
           ^^^^^^^^^^^^^^^^^^^^^^^^^^^^^^^^^^^^^^^^^^^^^^^
TypeError: Cannot cast array data from dtype('float64') to dtype('uint32') according to the rule 'safe'

The above exception was the direct cause of the following exception:

Traceback (most recent call last):
  File "/usr/local/python/3.12.1/lib/python3.12/site-packages/imblearn/utils/_validation.py", line 71, in _transfrom_one
    ret = ret.astype(props["dtypes"])
          ^^^^^^^^^^^^^^^^^^^^^^^^^^^
  File "/home/codespace/.local/lib/python3.12/site-packages/pandas/core/generic.py", line 6620, in astype
    res_col = col.astype(dtype=cdt, copy=copy, errors=errors)
              ^^^^^^^^^^^^^^^^^^^^^^^^^^^^^^^^^^^^^^^^^^^^^^^
  File "/home/codespace/.local/lib/python3.12/site-packages/pandas/core/generic.py", line 6643, in astype
    new_data = self._mgr.astype(dtype=dtype, copy=copy, errors=errors)
               ^^^^^^^^^^^^^^^^^^^^^^^^^^^^^^^^^^^^^^^^^^^^^^^^^^^^^^^
  File "/home/codespace/.local/lib/python3.12/site-packages/pandas/core/internals/managers.py", line 430, in astype
    return self.apply(
           ^^^^^^^^^^^
  File "/home/codespace/.local/lib/python3.12/site-packages/pandas/core/internals/managers.py", line 363, in apply
    applied = getattr(b, f)(**kwargs)
              ^^^^^^^^^^^^^^^^^^^^^^^
  File "/home/codespace/.local/lib/python3.12/site-packages/pandas/core/internals/blocks.py", line 758, in astype
    new_values = astype_array_safe(values, dtype, copy=copy, errors=errors)
                 ^^^^^^^^^^^^^^^^^^^^^^^^^^^^^^^^^^^^^^^^^^^^^^^^^^^^^^^^^^
  File "/home/codespace/.local/lib/python3.12/site-packages/pandas/core/dtypes/astype.py", line 237, in astype_array_safe
    new_values = astype_array(values, dtype, copy=copy)
                 ^^^^^^^^^^^^^^^^^^^^^^^^^^^^^^^^^^^^^^
  File "/home/codespace/.local/lib/python3.12/site-packages/pandas/core/dtypes/astype.py", line 182, in astype_array
    values = _astype_nansafe(values, dtype, copy=copy)
             ^^^^^^^^^^^^^^^^^^^^^^^^^^^^^^^^^^^^^^^^^
  File "/home/codespace/.local/lib/python3.12/site-packages/pandas/core/dtypes/astype.py", line 80, in _astype_nansafe
    return dtype.construct_array_type()._from_sequence(arr, dtype=dtype, copy=copy)
           ^^^^^^^^^^^^^^^^^^^^^^^^^^^^^^^^^^^^^^^^^^^^^^^^^^^^^^^^^^^^^^^^^^^^^^^^
  File "/home/codespace/.local/lib/python3.12/site-packages/pandas/core/arrays/masked.py", line 152, in _from_sequence
    values, mask = cls._coerce_to_array(scalars, dtype=dtype, copy=copy)
                   ^^^^^^^^^^^^^^^^^^^^^^^^^^^^^^^^^^^^^^^^^^^^^^^^^^^^^
  File "/home/codespace/.local/lib/python3.12/site-packages/pandas/core/arrays/numeric.py", line 272, in _coerce_to_array
    values, mask, _, _ = _coerce_to_data_and_mask(
                         ^^^^^^^^^^^^^^^^^^^^^^^^^
  File "/home/codespace/.local/lib/python3.12/site-packages/pandas/core/arrays/numeric.py", line 229, in _coerce_to_data_and_mask
    values = dtype_cls._safe_cast(values, dtype, copy=False)
             ^^^^^^^^^^^^^^^^^^^^^^^^^^^^^^^^^^^^^^^^^^^^^^^
  File "/home/codespace/.local/lib/python3.12/site-packages/pandas/core/arrays/integer.py", line 59, in _safe_cast
    raise TypeError(
TypeError: cannot safely cast non-equivalent float64 to uint32

During handling of the above exception, another exception occurred:

Traceback (most recent call last):
  File "/home/codespace/.local/lib/python3.12/site-packages/pandas/core/arrays/integer.py", line 53, in _safe_cast
    return values.astype(dtype, casting="safe", copy=copy)
           ^^^^^^^^^^^^^^^^^^^^^^^^^^^^^^^^^^^^^^^^^^^^^^^
TypeError: Cannot cast array data from dtype('float64') to dtype('uint32') according to the rule 'safe'

The above exception was the direct cause of the following exception:

Traceback (most recent call last):
  File "/workspaces/invenlytics/pipelines/v2/feature_pipeline.py", line 128, in run_supplychain_disruption_feature_pipeline
    X_resampled, y_resampled = smote_enn.fit_resample(X, y)
                               ^^^^^^^^^^^^^^^^^^^^^^^^^^^^
  File "/usr/local/python/3.12.1/lib/python3.12/site-packages/imblearn/base.py", line 202, in fit_resample
    return super().fit_resample(X, y, **params)
           ^^^^^^^^^^^^^^^^^^^^^^^^^^^^^^^^^^^^
  File "/usr/local/python/3.12.1/lib/python3.12/site-packages/sklearn/base.py", line 1473, in wrapper
    return fit_method(estimator, *args, **kwargs)
           ^^^^^^^^^^^^^^^^^^^^^^^^^^^^^^^^^^^^^^
  File "/usr/local/python/3.12.1/lib/python3.12/site-packages/imblearn/base.py", line 111, in fit_resample
    X_, y_ = arrays_transformer.transform(output[0], y_)
             ^^^^^^^^^^^^^^^^^^^^^^^^^^^^^^^^^^^^^^^^^^^
  File "/usr/local/python/3.12.1/lib/python3.12/site-packages/imblearn/utils/_validation.py", line 40, in transform
    X = self._transfrom_one(X, self.x_props)
        ^^^^^^^^^^^^^^^^^^^^^^^^^^^^^^^^^^^^
  File "/usr/local/python/3.12.1/lib/python3.12/site-packages/imblearn/utils/_validation.py", line 86, in _transfrom_one
    ret = ret.astype(props["dtypes"])
          ^^^^^^^^^^^^^^^^^^^^^^^^^^^
  File "/home/codespace/.local/lib/python3.12/site-packages/pandas/core/generic.py", line 6620, in astype
    res_col = col.astype(dtype=cdt, copy=copy, errors=errors)
              ^^^^^^^^^^^^^^^^^^^^^^^^^^^^^^^^^^^^^^^^^^^^^^^
  File "/home/codespace/.local/lib/python3.12/site-packages/pandas/core/generic.py", line 6643, in astype
    new_data = self._mgr.astype(dtype=dtype, copy=copy, errors=errors)
               ^^^^^^^^^^^^^^^^^^^^^^^^^^^^^^^^^^^^^^^^^^^^^^^^^^^^^^^
  File "/home/codespace/.local/lib/python3.12/site-packages/pandas/core/internals/managers.py", line 430, in astype
    return self.apply(
           ^^^^^^^^^^^
  File "/home/codespace/.local/lib/python3.12/site-packages/pandas/core/internals/managers.py", line 363, in apply
    applied = getattr(b, f)(**kwargs)
              ^^^^^^^^^^^^^^^^^^^^^^^
  File "/home/codespace/.local/lib/python3.12/site-packages/pandas/core/internals/blocks.py", line 758, in astype
    new_values = astype_array_safe(values, dtype, copy=copy, errors=errors)
                 ^^^^^^^^^^^^^^^^^^^^^^^^^^^^^^^^^^^^^^^^^^^^^^^^^^^^^^^^^^
  File "/home/codespace/.local/lib/python3.12/site-packages/pandas/core/dtypes/astype.py", line 237, in astype_array_safe
    new_values = astype_array(values, dtype, copy=copy)
                 ^^^^^^^^^^^^^^^^^^^^^^^^^^^^^^^^^^^^^^
  File "/home/codespace/.local/lib/python3.12/site-packages/pandas/core/dtypes/astype.py", line 182, in astype_array
    values = _astype_nansafe(values, dtype, copy=copy)
             ^^^^^^^^^^^^^^^^^^^^^^^^^^^^^^^^^^^^^^^^^
  File "/home/codespace/.local/lib/python3.12/site-packages/pandas/core/dtypes/astype.py", line 80, in _astype_nansafe
    return dtype.construct_array_type()._from_sequence(arr, dtype=dtype, copy=copy)
           ^^^^^^^^^^^^^^^^^^^^^^^^^^^^^^^^^^^^^^^^^^^^^^^^^^^^^^^^^^^^^^^^^^^^^^^^
  File "/home/codespace/.local/lib/python3.12/site-packages/pandas/core/arrays/masked.py", line 152, in _from_sequence
    values, mask = cls._coerce_to_array(scalars, dtype=dtype, copy=copy)
                   ^^^^^^^^^^^^^^^^^^^^^^^^^^^^^^^^^^^^^^^^^^^^^^^^^^^^^
  File "/home/codespace/.local/lib/python3.12/site-packages/pandas/core/arrays/numeric.py", line 272, in _coerce_to_array
    values, mask, _, _ = _coerce_to_data_and_mask(
                         ^^^^^^^^^^^^^^^^^^^^^^^^^
  File "/home/codespace/.local/lib/python3.12/site-packages/pandas/core/arrays/numeric.py", line 229, in _coerce_to_data_and_mask
    values = dtype_cls._safe_cast(values, dtype, copy=False)
             ^^^^^^^^^^^^^^^^^^^^^^^^^^^^^^^^^^^^^^^^^^^^^^^
  File "/home/codespace/.local/lib/python3.12/site-packages/pandas/core/arrays/integer.py", line 59, in _safe_cast
    raise TypeError(
TypeError: cannot safely cast non-equivalent float64 to uint32
2025-01-05 05:45:46,005 - CRITICAL - Pipeline execution failed: cannot safely cast non-equivalent float64 to uint32
2025-01-05 05:47:58,875 - INFO - Starting preprocessing pipeline.
2025-01-05 05:47:58,959 - INFO - None
2025-01-05 05:47:58,991 - INFO - Dataset loaded successfully. None
2025-01-05 05:47:59,022 - INFO - Target encoding completed.
2025-01-05 05:47:59,077 - INFO - Categorical encoding completed.
2025-01-05 05:47:59,115 - INFO - Holiday-related features created.
2025-01-05 05:47:59,129 - INFO - Normalization completed.
2025-01-05 05:47:59,153 - INFO - Rolling and expanding features generated.
2025-01-05 05:47:59,163 - INFO - Lag features generated.
2025-01-05 05:47:59,193 - INFO - Dropped NaN values. Preprocessing complete.
2025-01-05 05:48:14,666 - ERROR - An error occurred during feature engineering: cannot safely cast non-equivalent float64 to uint32
Traceback (most recent call last):
  File "/home/codespace/.local/lib/python3.12/site-packages/pandas/core/arrays/integer.py", line 53, in _safe_cast
    return values.astype(dtype, casting="safe", copy=copy)
           ^^^^^^^^^^^^^^^^^^^^^^^^^^^^^^^^^^^^^^^^^^^^^^^
TypeError: Cannot cast array data from dtype('float64') to dtype('uint32') according to the rule 'safe'

The above exception was the direct cause of the following exception:

Traceback (most recent call last):
  File "/usr/local/python/3.12.1/lib/python3.12/site-packages/imblearn/utils/_validation.py", line 71, in _transfrom_one
    ret = ret.astype(props["dtypes"])
          ^^^^^^^^^^^^^^^^^^^^^^^^^^^
  File "/home/codespace/.local/lib/python3.12/site-packages/pandas/core/generic.py", line 6620, in astype
    res_col = col.astype(dtype=cdt, copy=copy, errors=errors)
              ^^^^^^^^^^^^^^^^^^^^^^^^^^^^^^^^^^^^^^^^^^^^^^^
  File "/home/codespace/.local/lib/python3.12/site-packages/pandas/core/generic.py", line 6643, in astype
    new_data = self._mgr.astype(dtype=dtype, copy=copy, errors=errors)
               ^^^^^^^^^^^^^^^^^^^^^^^^^^^^^^^^^^^^^^^^^^^^^^^^^^^^^^^
  File "/home/codespace/.local/lib/python3.12/site-packages/pandas/core/internals/managers.py", line 430, in astype
    return self.apply(
           ^^^^^^^^^^^
  File "/home/codespace/.local/lib/python3.12/site-packages/pandas/core/internals/managers.py", line 363, in apply
    applied = getattr(b, f)(**kwargs)
              ^^^^^^^^^^^^^^^^^^^^^^^
  File "/home/codespace/.local/lib/python3.12/site-packages/pandas/core/internals/blocks.py", line 758, in astype
    new_values = astype_array_safe(values, dtype, copy=copy, errors=errors)
                 ^^^^^^^^^^^^^^^^^^^^^^^^^^^^^^^^^^^^^^^^^^^^^^^^^^^^^^^^^^
  File "/home/codespace/.local/lib/python3.12/site-packages/pandas/core/dtypes/astype.py", line 237, in astype_array_safe
    new_values = astype_array(values, dtype, copy=copy)
                 ^^^^^^^^^^^^^^^^^^^^^^^^^^^^^^^^^^^^^^
  File "/home/codespace/.local/lib/python3.12/site-packages/pandas/core/dtypes/astype.py", line 182, in astype_array
    values = _astype_nansafe(values, dtype, copy=copy)
             ^^^^^^^^^^^^^^^^^^^^^^^^^^^^^^^^^^^^^^^^^
  File "/home/codespace/.local/lib/python3.12/site-packages/pandas/core/dtypes/astype.py", line 80, in _astype_nansafe
    return dtype.construct_array_type()._from_sequence(arr, dtype=dtype, copy=copy)
           ^^^^^^^^^^^^^^^^^^^^^^^^^^^^^^^^^^^^^^^^^^^^^^^^^^^^^^^^^^^^^^^^^^^^^^^^
  File "/home/codespace/.local/lib/python3.12/site-packages/pandas/core/arrays/masked.py", line 152, in _from_sequence
    values, mask = cls._coerce_to_array(scalars, dtype=dtype, copy=copy)
                   ^^^^^^^^^^^^^^^^^^^^^^^^^^^^^^^^^^^^^^^^^^^^^^^^^^^^^
  File "/home/codespace/.local/lib/python3.12/site-packages/pandas/core/arrays/numeric.py", line 272, in _coerce_to_array
    values, mask, _, _ = _coerce_to_data_and_mask(
                         ^^^^^^^^^^^^^^^^^^^^^^^^^
  File "/home/codespace/.local/lib/python3.12/site-packages/pandas/core/arrays/numeric.py", line 229, in _coerce_to_data_and_mask
    values = dtype_cls._safe_cast(values, dtype, copy=False)
             ^^^^^^^^^^^^^^^^^^^^^^^^^^^^^^^^^^^^^^^^^^^^^^^
  File "/home/codespace/.local/lib/python3.12/site-packages/pandas/core/arrays/integer.py", line 59, in _safe_cast
    raise TypeError(
TypeError: cannot safely cast non-equivalent float64 to uint32

During handling of the above exception, another exception occurred:

Traceback (most recent call last):
  File "/home/codespace/.local/lib/python3.12/site-packages/pandas/core/arrays/integer.py", line 53, in _safe_cast
    return values.astype(dtype, casting="safe", copy=copy)
           ^^^^^^^^^^^^^^^^^^^^^^^^^^^^^^^^^^^^^^^^^^^^^^^
TypeError: Cannot cast array data from dtype('float64') to dtype('uint32') according to the rule 'safe'

The above exception was the direct cause of the following exception:

Traceback (most recent call last):
  File "/workspaces/invenlytics/pipelines/v2/feature_pipeline.py", line 129, in run_supplychain_disruption_feature_pipeline
    X_resampled, y_resampled = smote_enn.fit_resample(X, y)
                               ^^^^^^^^^^^^^^^^^^^^^^^^^^^^
  File "/usr/local/python/3.12.1/lib/python3.12/site-packages/imblearn/base.py", line 202, in fit_resample
    return super().fit_resample(X, y, **params)
           ^^^^^^^^^^^^^^^^^^^^^^^^^^^^^^^^^^^^
  File "/usr/local/python/3.12.1/lib/python3.12/site-packages/sklearn/base.py", line 1473, in wrapper
    return fit_method(estimator, *args, **kwargs)
           ^^^^^^^^^^^^^^^^^^^^^^^^^^^^^^^^^^^^^^
  File "/usr/local/python/3.12.1/lib/python3.12/site-packages/imblearn/base.py", line 111, in fit_resample
    X_, y_ = arrays_transformer.transform(output[0], y_)
             ^^^^^^^^^^^^^^^^^^^^^^^^^^^^^^^^^^^^^^^^^^^
  File "/usr/local/python/3.12.1/lib/python3.12/site-packages/imblearn/utils/_validation.py", line 40, in transform
    X = self._transfrom_one(X, self.x_props)
        ^^^^^^^^^^^^^^^^^^^^^^^^^^^^^^^^^^^^
  File "/usr/local/python/3.12.1/lib/python3.12/site-packages/imblearn/utils/_validation.py", line 86, in _transfrom_one
    ret = ret.astype(props["dtypes"])
          ^^^^^^^^^^^^^^^^^^^^^^^^^^^
  File "/home/codespace/.local/lib/python3.12/site-packages/pandas/core/generic.py", line 6620, in astype
    res_col = col.astype(dtype=cdt, copy=copy, errors=errors)
              ^^^^^^^^^^^^^^^^^^^^^^^^^^^^^^^^^^^^^^^^^^^^^^^
  File "/home/codespace/.local/lib/python3.12/site-packages/pandas/core/generic.py", line 6643, in astype
    new_data = self._mgr.astype(dtype=dtype, copy=copy, errors=errors)
               ^^^^^^^^^^^^^^^^^^^^^^^^^^^^^^^^^^^^^^^^^^^^^^^^^^^^^^^
  File "/home/codespace/.local/lib/python3.12/site-packages/pandas/core/internals/managers.py", line 430, in astype
    return self.apply(
           ^^^^^^^^^^^
  File "/home/codespace/.local/lib/python3.12/site-packages/pandas/core/internals/managers.py", line 363, in apply
    applied = getattr(b, f)(**kwargs)
              ^^^^^^^^^^^^^^^^^^^^^^^
  File "/home/codespace/.local/lib/python3.12/site-packages/pandas/core/internals/blocks.py", line 758, in astype
    new_values = astype_array_safe(values, dtype, copy=copy, errors=errors)
                 ^^^^^^^^^^^^^^^^^^^^^^^^^^^^^^^^^^^^^^^^^^^^^^^^^^^^^^^^^^
  File "/home/codespace/.local/lib/python3.12/site-packages/pandas/core/dtypes/astype.py", line 237, in astype_array_safe
    new_values = astype_array(values, dtype, copy=copy)
                 ^^^^^^^^^^^^^^^^^^^^^^^^^^^^^^^^^^^^^^
  File "/home/codespace/.local/lib/python3.12/site-packages/pandas/core/dtypes/astype.py", line 182, in astype_array
    values = _astype_nansafe(values, dtype, copy=copy)
             ^^^^^^^^^^^^^^^^^^^^^^^^^^^^^^^^^^^^^^^^^
  File "/home/codespace/.local/lib/python3.12/site-packages/pandas/core/dtypes/astype.py", line 80, in _astype_nansafe
    return dtype.construct_array_type()._from_sequence(arr, dtype=dtype, copy=copy)
           ^^^^^^^^^^^^^^^^^^^^^^^^^^^^^^^^^^^^^^^^^^^^^^^^^^^^^^^^^^^^^^^^^^^^^^^^
  File "/home/codespace/.local/lib/python3.12/site-packages/pandas/core/arrays/masked.py", line 152, in _from_sequence
    values, mask = cls._coerce_to_array(scalars, dtype=dtype, copy=copy)
                   ^^^^^^^^^^^^^^^^^^^^^^^^^^^^^^^^^^^^^^^^^^^^^^^^^^^^^
  File "/home/codespace/.local/lib/python3.12/site-packages/pandas/core/arrays/numeric.py", line 272, in _coerce_to_array
    values, mask, _, _ = _coerce_to_data_and_mask(
                         ^^^^^^^^^^^^^^^^^^^^^^^^^
  File "/home/codespace/.local/lib/python3.12/site-packages/pandas/core/arrays/numeric.py", line 229, in _coerce_to_data_and_mask
    values = dtype_cls._safe_cast(values, dtype, copy=False)
             ^^^^^^^^^^^^^^^^^^^^^^^^^^^^^^^^^^^^^^^^^^^^^^^
  File "/home/codespace/.local/lib/python3.12/site-packages/pandas/core/arrays/integer.py", line 59, in _safe_cast
    raise TypeError(
TypeError: cannot safely cast non-equivalent float64 to uint32
2025-01-05 05:48:14,672 - CRITICAL - Pipeline execution failed: cannot safely cast non-equivalent float64 to uint32
2025-01-05 05:48:39,482 - INFO - Starting preprocessing pipeline.
2025-01-05 05:48:39,569 - INFO - None
2025-01-05 05:48:39,601 - INFO - Dataset loaded successfully. None
2025-01-05 05:48:39,631 - INFO - Target encoding completed.
2025-01-05 05:48:39,685 - INFO - Categorical encoding completed.
2025-01-05 05:48:39,724 - INFO - Holiday-related features created.
2025-01-05 05:48:39,736 - INFO - Normalization completed.
2025-01-05 05:48:39,760 - INFO - Rolling and expanding features generated.
2025-01-05 05:48:39,770 - INFO - Lag features generated.
2025-01-05 05:48:39,797 - INFO - Dropped NaN values. Preprocessing complete.
2025-01-05 05:48:55,256 - ERROR - An error occurred during feature engineering: cannot safely cast non-equivalent float64 to uint32
Traceback (most recent call last):
  File "/home/codespace/.local/lib/python3.12/site-packages/pandas/core/arrays/integer.py", line 53, in _safe_cast
    return values.astype(dtype, casting="safe", copy=copy)
           ^^^^^^^^^^^^^^^^^^^^^^^^^^^^^^^^^^^^^^^^^^^^^^^
TypeError: Cannot cast array data from dtype('float64') to dtype('uint32') according to the rule 'safe'

The above exception was the direct cause of the following exception:

Traceback (most recent call last):
  File "/usr/local/python/3.12.1/lib/python3.12/site-packages/imblearn/utils/_validation.py", line 71, in _transfrom_one
    ret = ret.astype(props["dtypes"])
          ^^^^^^^^^^^^^^^^^^^^^^^^^^^
  File "/home/codespace/.local/lib/python3.12/site-packages/pandas/core/generic.py", line 6620, in astype
    res_col = col.astype(dtype=cdt, copy=copy, errors=errors)
              ^^^^^^^^^^^^^^^^^^^^^^^^^^^^^^^^^^^^^^^^^^^^^^^
  File "/home/codespace/.local/lib/python3.12/site-packages/pandas/core/generic.py", line 6643, in astype
    new_data = self._mgr.astype(dtype=dtype, copy=copy, errors=errors)
               ^^^^^^^^^^^^^^^^^^^^^^^^^^^^^^^^^^^^^^^^^^^^^^^^^^^^^^^
  File "/home/codespace/.local/lib/python3.12/site-packages/pandas/core/internals/managers.py", line 430, in astype
    return self.apply(
           ^^^^^^^^^^^
  File "/home/codespace/.local/lib/python3.12/site-packages/pandas/core/internals/managers.py", line 363, in apply
    applied = getattr(b, f)(**kwargs)
              ^^^^^^^^^^^^^^^^^^^^^^^
  File "/home/codespace/.local/lib/python3.12/site-packages/pandas/core/internals/blocks.py", line 758, in astype
    new_values = astype_array_safe(values, dtype, copy=copy, errors=errors)
                 ^^^^^^^^^^^^^^^^^^^^^^^^^^^^^^^^^^^^^^^^^^^^^^^^^^^^^^^^^^
  File "/home/codespace/.local/lib/python3.12/site-packages/pandas/core/dtypes/astype.py", line 237, in astype_array_safe
    new_values = astype_array(values, dtype, copy=copy)
                 ^^^^^^^^^^^^^^^^^^^^^^^^^^^^^^^^^^^^^^
  File "/home/codespace/.local/lib/python3.12/site-packages/pandas/core/dtypes/astype.py", line 182, in astype_array
    values = _astype_nansafe(values, dtype, copy=copy)
             ^^^^^^^^^^^^^^^^^^^^^^^^^^^^^^^^^^^^^^^^^
  File "/home/codespace/.local/lib/python3.12/site-packages/pandas/core/dtypes/astype.py", line 80, in _astype_nansafe
    return dtype.construct_array_type()._from_sequence(arr, dtype=dtype, copy=copy)
           ^^^^^^^^^^^^^^^^^^^^^^^^^^^^^^^^^^^^^^^^^^^^^^^^^^^^^^^^^^^^^^^^^^^^^^^^
  File "/home/codespace/.local/lib/python3.12/site-packages/pandas/core/arrays/masked.py", line 152, in _from_sequence
    values, mask = cls._coerce_to_array(scalars, dtype=dtype, copy=copy)
                   ^^^^^^^^^^^^^^^^^^^^^^^^^^^^^^^^^^^^^^^^^^^^^^^^^^^^^
  File "/home/codespace/.local/lib/python3.12/site-packages/pandas/core/arrays/numeric.py", line 272, in _coerce_to_array
    values, mask, _, _ = _coerce_to_data_and_mask(
                         ^^^^^^^^^^^^^^^^^^^^^^^^^
  File "/home/codespace/.local/lib/python3.12/site-packages/pandas/core/arrays/numeric.py", line 229, in _coerce_to_data_and_mask
    values = dtype_cls._safe_cast(values, dtype, copy=False)
             ^^^^^^^^^^^^^^^^^^^^^^^^^^^^^^^^^^^^^^^^^^^^^^^
  File "/home/codespace/.local/lib/python3.12/site-packages/pandas/core/arrays/integer.py", line 59, in _safe_cast
    raise TypeError(
TypeError: cannot safely cast non-equivalent float64 to uint32

During handling of the above exception, another exception occurred:

Traceback (most recent call last):
  File "/home/codespace/.local/lib/python3.12/site-packages/pandas/core/arrays/integer.py", line 53, in _safe_cast
    return values.astype(dtype, casting="safe", copy=copy)
           ^^^^^^^^^^^^^^^^^^^^^^^^^^^^^^^^^^^^^^^^^^^^^^^
TypeError: Cannot cast array data from dtype('float64') to dtype('uint32') according to the rule 'safe'

The above exception was the direct cause of the following exception:

Traceback (most recent call last):
  File "/workspaces/invenlytics/pipelines/v2/feature_pipeline.py", line 129, in run_supplychain_disruption_feature_pipeline
    X_resampled, y_resampled = smote_enn.fit_resample(X, y)
                               ^^^^^^^^^^^^^^^^^^^^^^^^^^^^
  File "/usr/local/python/3.12.1/lib/python3.12/site-packages/imblearn/base.py", line 202, in fit_resample
    return super().fit_resample(X, y, **params)
           ^^^^^^^^^^^^^^^^^^^^^^^^^^^^^^^^^^^^
  File "/usr/local/python/3.12.1/lib/python3.12/site-packages/sklearn/base.py", line 1473, in wrapper
    return fit_method(estimator, *args, **kwargs)
           ^^^^^^^^^^^^^^^^^^^^^^^^^^^^^^^^^^^^^^
  File "/usr/local/python/3.12.1/lib/python3.12/site-packages/imblearn/base.py", line 111, in fit_resample
    X_, y_ = arrays_transformer.transform(output[0], y_)
             ^^^^^^^^^^^^^^^^^^^^^^^^^^^^^^^^^^^^^^^^^^^
  File "/usr/local/python/3.12.1/lib/python3.12/site-packages/imblearn/utils/_validation.py", line 40, in transform
    X = self._transfrom_one(X, self.x_props)
        ^^^^^^^^^^^^^^^^^^^^^^^^^^^^^^^^^^^^
  File "/usr/local/python/3.12.1/lib/python3.12/site-packages/imblearn/utils/_validation.py", line 86, in _transfrom_one
    ret = ret.astype(props["dtypes"])
          ^^^^^^^^^^^^^^^^^^^^^^^^^^^
  File "/home/codespace/.local/lib/python3.12/site-packages/pandas/core/generic.py", line 6620, in astype
    res_col = col.astype(dtype=cdt, copy=copy, errors=errors)
              ^^^^^^^^^^^^^^^^^^^^^^^^^^^^^^^^^^^^^^^^^^^^^^^
  File "/home/codespace/.local/lib/python3.12/site-packages/pandas/core/generic.py", line 6643, in astype
    new_data = self._mgr.astype(dtype=dtype, copy=copy, errors=errors)
               ^^^^^^^^^^^^^^^^^^^^^^^^^^^^^^^^^^^^^^^^^^^^^^^^^^^^^^^
  File "/home/codespace/.local/lib/python3.12/site-packages/pandas/core/internals/managers.py", line 430, in astype
    return self.apply(
           ^^^^^^^^^^^
  File "/home/codespace/.local/lib/python3.12/site-packages/pandas/core/internals/managers.py", line 363, in apply
    applied = getattr(b, f)(**kwargs)
              ^^^^^^^^^^^^^^^^^^^^^^^
  File "/home/codespace/.local/lib/python3.12/site-packages/pandas/core/internals/blocks.py", line 758, in astype
    new_values = astype_array_safe(values, dtype, copy=copy, errors=errors)
                 ^^^^^^^^^^^^^^^^^^^^^^^^^^^^^^^^^^^^^^^^^^^^^^^^^^^^^^^^^^
  File "/home/codespace/.local/lib/python3.12/site-packages/pandas/core/dtypes/astype.py", line 237, in astype_array_safe
    new_values = astype_array(values, dtype, copy=copy)
                 ^^^^^^^^^^^^^^^^^^^^^^^^^^^^^^^^^^^^^^
  File "/home/codespace/.local/lib/python3.12/site-packages/pandas/core/dtypes/astype.py", line 182, in astype_array
    values = _astype_nansafe(values, dtype, copy=copy)
             ^^^^^^^^^^^^^^^^^^^^^^^^^^^^^^^^^^^^^^^^^
  File "/home/codespace/.local/lib/python3.12/site-packages/pandas/core/dtypes/astype.py", line 80, in _astype_nansafe
    return dtype.construct_array_type()._from_sequence(arr, dtype=dtype, copy=copy)
           ^^^^^^^^^^^^^^^^^^^^^^^^^^^^^^^^^^^^^^^^^^^^^^^^^^^^^^^^^^^^^^^^^^^^^^^^
  File "/home/codespace/.local/lib/python3.12/site-packages/pandas/core/arrays/masked.py", line 152, in _from_sequence
    values, mask = cls._coerce_to_array(scalars, dtype=dtype, copy=copy)
                   ^^^^^^^^^^^^^^^^^^^^^^^^^^^^^^^^^^^^^^^^^^^^^^^^^^^^^
  File "/home/codespace/.local/lib/python3.12/site-packages/pandas/core/arrays/numeric.py", line 272, in _coerce_to_array
    values, mask, _, _ = _coerce_to_data_and_mask(
                         ^^^^^^^^^^^^^^^^^^^^^^^^^
  File "/home/codespace/.local/lib/python3.12/site-packages/pandas/core/arrays/numeric.py", line 229, in _coerce_to_data_and_mask
    values = dtype_cls._safe_cast(values, dtype, copy=False)
             ^^^^^^^^^^^^^^^^^^^^^^^^^^^^^^^^^^^^^^^^^^^^^^^
  File "/home/codespace/.local/lib/python3.12/site-packages/pandas/core/arrays/integer.py", line 59, in _safe_cast
    raise TypeError(
TypeError: cannot safely cast non-equivalent float64 to uint32
2025-01-05 05:48:55,261 - CRITICAL - Pipeline execution failed: cannot safely cast non-equivalent float64 to uint32
2025-01-05 05:54:09,896 - INFO - Starting preprocessing pipeline.
2025-01-05 05:54:09,988 - INFO - None
2025-01-05 05:54:10,024 - INFO - Dataset loaded successfully. None
2025-01-05 05:54:10,055 - INFO - Target encoding completed.
2025-01-05 05:54:10,111 - INFO - Categorical encoding completed.
2025-01-05 05:54:10,153 - INFO - Holiday-related features created.
2025-01-05 05:54:10,168 - INFO - Normalization completed.
2025-01-05 05:54:10,195 - INFO - Rolling and expanding features generated.
2025-01-05 05:54:10,206 - INFO - Lag features generated.
2025-01-05 05:54:10,238 - INFO - Dropped NaN values. Preprocessing complete.
2025-01-05 05:54:25,970 - ERROR - An error occurred during feature engineering: cannot safely cast non-equivalent float64 to uint32
Traceback (most recent call last):
  File "/home/codespace/.local/lib/python3.12/site-packages/pandas/core/arrays/integer.py", line 53, in _safe_cast
    return values.astype(dtype, casting="safe", copy=copy)
           ^^^^^^^^^^^^^^^^^^^^^^^^^^^^^^^^^^^^^^^^^^^^^^^
TypeError: Cannot cast array data from dtype('float64') to dtype('uint32') according to the rule 'safe'

The above exception was the direct cause of the following exception:

Traceback (most recent call last):
  File "/usr/local/python/3.12.1/lib/python3.12/site-packages/imblearn/utils/_validation.py", line 71, in _transfrom_one
    ret = ret.astype(props["dtypes"])
          ^^^^^^^^^^^^^^^^^^^^^^^^^^^
  File "/home/codespace/.local/lib/python3.12/site-packages/pandas/core/generic.py", line 6620, in astype
    res_col = col.astype(dtype=cdt, copy=copy, errors=errors)
              ^^^^^^^^^^^^^^^^^^^^^^^^^^^^^^^^^^^^^^^^^^^^^^^
  File "/home/codespace/.local/lib/python3.12/site-packages/pandas/core/generic.py", line 6643, in astype
    new_data = self._mgr.astype(dtype=dtype, copy=copy, errors=errors)
               ^^^^^^^^^^^^^^^^^^^^^^^^^^^^^^^^^^^^^^^^^^^^^^^^^^^^^^^
  File "/home/codespace/.local/lib/python3.12/site-packages/pandas/core/internals/managers.py", line 430, in astype
    return self.apply(
           ^^^^^^^^^^^
  File "/home/codespace/.local/lib/python3.12/site-packages/pandas/core/internals/managers.py", line 363, in apply
    applied = getattr(b, f)(**kwargs)
              ^^^^^^^^^^^^^^^^^^^^^^^
  File "/home/codespace/.local/lib/python3.12/site-packages/pandas/core/internals/blocks.py", line 758, in astype
    new_values = astype_array_safe(values, dtype, copy=copy, errors=errors)
                 ^^^^^^^^^^^^^^^^^^^^^^^^^^^^^^^^^^^^^^^^^^^^^^^^^^^^^^^^^^
  File "/home/codespace/.local/lib/python3.12/site-packages/pandas/core/dtypes/astype.py", line 237, in astype_array_safe
    new_values = astype_array(values, dtype, copy=copy)
                 ^^^^^^^^^^^^^^^^^^^^^^^^^^^^^^^^^^^^^^
  File "/home/codespace/.local/lib/python3.12/site-packages/pandas/core/dtypes/astype.py", line 182, in astype_array
    values = _astype_nansafe(values, dtype, copy=copy)
             ^^^^^^^^^^^^^^^^^^^^^^^^^^^^^^^^^^^^^^^^^
  File "/home/codespace/.local/lib/python3.12/site-packages/pandas/core/dtypes/astype.py", line 80, in _astype_nansafe
    return dtype.construct_array_type()._from_sequence(arr, dtype=dtype, copy=copy)
           ^^^^^^^^^^^^^^^^^^^^^^^^^^^^^^^^^^^^^^^^^^^^^^^^^^^^^^^^^^^^^^^^^^^^^^^^
  File "/home/codespace/.local/lib/python3.12/site-packages/pandas/core/arrays/masked.py", line 152, in _from_sequence
    values, mask = cls._coerce_to_array(scalars, dtype=dtype, copy=copy)
                   ^^^^^^^^^^^^^^^^^^^^^^^^^^^^^^^^^^^^^^^^^^^^^^^^^^^^^
  File "/home/codespace/.local/lib/python3.12/site-packages/pandas/core/arrays/numeric.py", line 272, in _coerce_to_array
    values, mask, _, _ = _coerce_to_data_and_mask(
                         ^^^^^^^^^^^^^^^^^^^^^^^^^
  File "/home/codespace/.local/lib/python3.12/site-packages/pandas/core/arrays/numeric.py", line 229, in _coerce_to_data_and_mask
    values = dtype_cls._safe_cast(values, dtype, copy=False)
             ^^^^^^^^^^^^^^^^^^^^^^^^^^^^^^^^^^^^^^^^^^^^^^^
  File "/home/codespace/.local/lib/python3.12/site-packages/pandas/core/arrays/integer.py", line 59, in _safe_cast
    raise TypeError(
TypeError: cannot safely cast non-equivalent float64 to uint32

During handling of the above exception, another exception occurred:

Traceback (most recent call last):
  File "/home/codespace/.local/lib/python3.12/site-packages/pandas/core/arrays/integer.py", line 53, in _safe_cast
    return values.astype(dtype, casting="safe", copy=copy)
           ^^^^^^^^^^^^^^^^^^^^^^^^^^^^^^^^^^^^^^^^^^^^^^^
TypeError: Cannot cast array data from dtype('float64') to dtype('uint32') according to the rule 'safe'

The above exception was the direct cause of the following exception:

Traceback (most recent call last):
  File "/workspaces/invenlytics/pipelines/v2/feature_pipeline.py", line 140, in run_supplychain_disruption_feature_pipeline
    X_resampled, y_resampled = smote_enn.fit_resample(X, y)
                               ^^^^^^^^^^^^^^^^^^^^^^^^^^^^
  File "/usr/local/python/3.12.1/lib/python3.12/site-packages/imblearn/base.py", line 202, in fit_resample
    return super().fit_resample(X, y, **params)
           ^^^^^^^^^^^^^^^^^^^^^^^^^^^^^^^^^^^^
  File "/usr/local/python/3.12.1/lib/python3.12/site-packages/sklearn/base.py", line 1473, in wrapper
    return fit_method(estimator, *args, **kwargs)
           ^^^^^^^^^^^^^^^^^^^^^^^^^^^^^^^^^^^^^^
  File "/usr/local/python/3.12.1/lib/python3.12/site-packages/imblearn/base.py", line 111, in fit_resample
    X_, y_ = arrays_transformer.transform(output[0], y_)
             ^^^^^^^^^^^^^^^^^^^^^^^^^^^^^^^^^^^^^^^^^^^
  File "/usr/local/python/3.12.1/lib/python3.12/site-packages/imblearn/utils/_validation.py", line 40, in transform
    X = self._transfrom_one(X, self.x_props)
        ^^^^^^^^^^^^^^^^^^^^^^^^^^^^^^^^^^^^
  File "/usr/local/python/3.12.1/lib/python3.12/site-packages/imblearn/utils/_validation.py", line 86, in _transfrom_one
    ret = ret.astype(props["dtypes"])
          ^^^^^^^^^^^^^^^^^^^^^^^^^^^
  File "/home/codespace/.local/lib/python3.12/site-packages/pandas/core/generic.py", line 6620, in astype
    res_col = col.astype(dtype=cdt, copy=copy, errors=errors)
              ^^^^^^^^^^^^^^^^^^^^^^^^^^^^^^^^^^^^^^^^^^^^^^^
  File "/home/codespace/.local/lib/python3.12/site-packages/pandas/core/generic.py", line 6643, in astype
    new_data = self._mgr.astype(dtype=dtype, copy=copy, errors=errors)
               ^^^^^^^^^^^^^^^^^^^^^^^^^^^^^^^^^^^^^^^^^^^^^^^^^^^^^^^
  File "/home/codespace/.local/lib/python3.12/site-packages/pandas/core/internals/managers.py", line 430, in astype
    return self.apply(
           ^^^^^^^^^^^
  File "/home/codespace/.local/lib/python3.12/site-packages/pandas/core/internals/managers.py", line 363, in apply
    applied = getattr(b, f)(**kwargs)
              ^^^^^^^^^^^^^^^^^^^^^^^
  File "/home/codespace/.local/lib/python3.12/site-packages/pandas/core/internals/blocks.py", line 758, in astype
    new_values = astype_array_safe(values, dtype, copy=copy, errors=errors)
                 ^^^^^^^^^^^^^^^^^^^^^^^^^^^^^^^^^^^^^^^^^^^^^^^^^^^^^^^^^^
  File "/home/codespace/.local/lib/python3.12/site-packages/pandas/core/dtypes/astype.py", line 237, in astype_array_safe
    new_values = astype_array(values, dtype, copy=copy)
                 ^^^^^^^^^^^^^^^^^^^^^^^^^^^^^^^^^^^^^^
  File "/home/codespace/.local/lib/python3.12/site-packages/pandas/core/dtypes/astype.py", line 182, in astype_array
    values = _astype_nansafe(values, dtype, copy=copy)
             ^^^^^^^^^^^^^^^^^^^^^^^^^^^^^^^^^^^^^^^^^
  File "/home/codespace/.local/lib/python3.12/site-packages/pandas/core/dtypes/astype.py", line 80, in _astype_nansafe
    return dtype.construct_array_type()._from_sequence(arr, dtype=dtype, copy=copy)
           ^^^^^^^^^^^^^^^^^^^^^^^^^^^^^^^^^^^^^^^^^^^^^^^^^^^^^^^^^^^^^^^^^^^^^^^^
  File "/home/codespace/.local/lib/python3.12/site-packages/pandas/core/arrays/masked.py", line 152, in _from_sequence
    values, mask = cls._coerce_to_array(scalars, dtype=dtype, copy=copy)
                   ^^^^^^^^^^^^^^^^^^^^^^^^^^^^^^^^^^^^^^^^^^^^^^^^^^^^^
  File "/home/codespace/.local/lib/python3.12/site-packages/pandas/core/arrays/numeric.py", line 272, in _coerce_to_array
    values, mask, _, _ = _coerce_to_data_and_mask(
                         ^^^^^^^^^^^^^^^^^^^^^^^^^
  File "/home/codespace/.local/lib/python3.12/site-packages/pandas/core/arrays/numeric.py", line 229, in _coerce_to_data_and_mask
    values = dtype_cls._safe_cast(values, dtype, copy=False)
             ^^^^^^^^^^^^^^^^^^^^^^^^^^^^^^^^^^^^^^^^^^^^^^^
  File "/home/codespace/.local/lib/python3.12/site-packages/pandas/core/arrays/integer.py", line 59, in _safe_cast
    raise TypeError(
TypeError: cannot safely cast non-equivalent float64 to uint32
2025-01-05 05:54:25,977 - CRITICAL - Pipeline execution failed: cannot safely cast non-equivalent float64 to uint32
2025-01-05 05:55:29,891 - INFO - Starting preprocessing pipeline.
2025-01-05 05:55:29,984 - INFO - None
2025-01-05 05:55:30,016 - INFO - Dataset loaded successfully. None
2025-01-05 05:55:30,046 - INFO - Target encoding completed.
2025-01-05 05:55:30,104 - INFO - Categorical encoding completed.
2025-01-05 05:55:30,150 - INFO - Holiday-related features created.
2025-01-05 05:55:30,163 - INFO - Normalization completed.
2025-01-05 05:55:30,185 - INFO - Rolling and expanding features generated.
2025-01-05 05:55:30,195 - INFO - Lag features generated.
2025-01-05 05:55:30,227 - INFO - Dropped NaN values. Preprocessing complete.
2025-01-05 05:55:46,212 - ERROR - An error occurred during feature engineering: cannot safely cast non-equivalent float64 to uint32
Traceback (most recent call last):
  File "/home/codespace/.local/lib/python3.12/site-packages/pandas/core/arrays/integer.py", line 53, in _safe_cast
    return values.astype(dtype, casting="safe", copy=copy)
           ^^^^^^^^^^^^^^^^^^^^^^^^^^^^^^^^^^^^^^^^^^^^^^^
TypeError: Cannot cast array data from dtype('float64') to dtype('uint32') according to the rule 'safe'

The above exception was the direct cause of the following exception:

Traceback (most recent call last):
  File "/usr/local/python/3.12.1/lib/python3.12/site-packages/imblearn/utils/_validation.py", line 71, in _transfrom_one
    ret = ret.astype(props["dtypes"])
          ^^^^^^^^^^^^^^^^^^^^^^^^^^^
  File "/home/codespace/.local/lib/python3.12/site-packages/pandas/core/generic.py", line 6620, in astype
    res_col = col.astype(dtype=cdt, copy=copy, errors=errors)
              ^^^^^^^^^^^^^^^^^^^^^^^^^^^^^^^^^^^^^^^^^^^^^^^
  File "/home/codespace/.local/lib/python3.12/site-packages/pandas/core/generic.py", line 6643, in astype
    new_data = self._mgr.astype(dtype=dtype, copy=copy, errors=errors)
               ^^^^^^^^^^^^^^^^^^^^^^^^^^^^^^^^^^^^^^^^^^^^^^^^^^^^^^^
  File "/home/codespace/.local/lib/python3.12/site-packages/pandas/core/internals/managers.py", line 430, in astype
    return self.apply(
           ^^^^^^^^^^^
  File "/home/codespace/.local/lib/python3.12/site-packages/pandas/core/internals/managers.py", line 363, in apply
    applied = getattr(b, f)(**kwargs)
              ^^^^^^^^^^^^^^^^^^^^^^^
  File "/home/codespace/.local/lib/python3.12/site-packages/pandas/core/internals/blocks.py", line 758, in astype
    new_values = astype_array_safe(values, dtype, copy=copy, errors=errors)
                 ^^^^^^^^^^^^^^^^^^^^^^^^^^^^^^^^^^^^^^^^^^^^^^^^^^^^^^^^^^
  File "/home/codespace/.local/lib/python3.12/site-packages/pandas/core/dtypes/astype.py", line 237, in astype_array_safe
    new_values = astype_array(values, dtype, copy=copy)
                 ^^^^^^^^^^^^^^^^^^^^^^^^^^^^^^^^^^^^^^
  File "/home/codespace/.local/lib/python3.12/site-packages/pandas/core/dtypes/astype.py", line 182, in astype_array
    values = _astype_nansafe(values, dtype, copy=copy)
             ^^^^^^^^^^^^^^^^^^^^^^^^^^^^^^^^^^^^^^^^^
  File "/home/codespace/.local/lib/python3.12/site-packages/pandas/core/dtypes/astype.py", line 80, in _astype_nansafe
    return dtype.construct_array_type()._from_sequence(arr, dtype=dtype, copy=copy)
           ^^^^^^^^^^^^^^^^^^^^^^^^^^^^^^^^^^^^^^^^^^^^^^^^^^^^^^^^^^^^^^^^^^^^^^^^
  File "/home/codespace/.local/lib/python3.12/site-packages/pandas/core/arrays/masked.py", line 152, in _from_sequence
    values, mask = cls._coerce_to_array(scalars, dtype=dtype, copy=copy)
                   ^^^^^^^^^^^^^^^^^^^^^^^^^^^^^^^^^^^^^^^^^^^^^^^^^^^^^
  File "/home/codespace/.local/lib/python3.12/site-packages/pandas/core/arrays/numeric.py", line 272, in _coerce_to_array
    values, mask, _, _ = _coerce_to_data_and_mask(
                         ^^^^^^^^^^^^^^^^^^^^^^^^^
  File "/home/codespace/.local/lib/python3.12/site-packages/pandas/core/arrays/numeric.py", line 229, in _coerce_to_data_and_mask
    values = dtype_cls._safe_cast(values, dtype, copy=False)
             ^^^^^^^^^^^^^^^^^^^^^^^^^^^^^^^^^^^^^^^^^^^^^^^
  File "/home/codespace/.local/lib/python3.12/site-packages/pandas/core/arrays/integer.py", line 59, in _safe_cast
    raise TypeError(
TypeError: cannot safely cast non-equivalent float64 to uint32

During handling of the above exception, another exception occurred:

Traceback (most recent call last):
  File "/home/codespace/.local/lib/python3.12/site-packages/pandas/core/arrays/integer.py", line 53, in _safe_cast
    return values.astype(dtype, casting="safe", copy=copy)
           ^^^^^^^^^^^^^^^^^^^^^^^^^^^^^^^^^^^^^^^^^^^^^^^
TypeError: Cannot cast array data from dtype('float64') to dtype('uint32') according to the rule 'safe'

The above exception was the direct cause of the following exception:

Traceback (most recent call last):
  File "/workspaces/invenlytics/pipelines/v2/feature_pipeline.py", line 140, in run_supplychain_disruption_feature_pipeline
    X_resampled, y_resampled = smote_enn.fit_resample(X, y)
                               ^^^^^^^^^^^^^^^^^^^^^^^^^^^^
  File "/usr/local/python/3.12.1/lib/python3.12/site-packages/imblearn/base.py", line 202, in fit_resample
    return super().fit_resample(X, y, **params)
           ^^^^^^^^^^^^^^^^^^^^^^^^^^^^^^^^^^^^
  File "/usr/local/python/3.12.1/lib/python3.12/site-packages/sklearn/base.py", line 1473, in wrapper
    return fit_method(estimator, *args, **kwargs)
           ^^^^^^^^^^^^^^^^^^^^^^^^^^^^^^^^^^^^^^
  File "/usr/local/python/3.12.1/lib/python3.12/site-packages/imblearn/base.py", line 111, in fit_resample
    X_, y_ = arrays_transformer.transform(output[0], y_)
             ^^^^^^^^^^^^^^^^^^^^^^^^^^^^^^^^^^^^^^^^^^^
  File "/usr/local/python/3.12.1/lib/python3.12/site-packages/imblearn/utils/_validation.py", line 40, in transform
    X = self._transfrom_one(X, self.x_props)
        ^^^^^^^^^^^^^^^^^^^^^^^^^^^^^^^^^^^^
  File "/usr/local/python/3.12.1/lib/python3.12/site-packages/imblearn/utils/_validation.py", line 86, in _transfrom_one
    ret = ret.astype(props["dtypes"])
          ^^^^^^^^^^^^^^^^^^^^^^^^^^^
  File "/home/codespace/.local/lib/python3.12/site-packages/pandas/core/generic.py", line 6620, in astype
    res_col = col.astype(dtype=cdt, copy=copy, errors=errors)
              ^^^^^^^^^^^^^^^^^^^^^^^^^^^^^^^^^^^^^^^^^^^^^^^
  File "/home/codespace/.local/lib/python3.12/site-packages/pandas/core/generic.py", line 6643, in astype
    new_data = self._mgr.astype(dtype=dtype, copy=copy, errors=errors)
               ^^^^^^^^^^^^^^^^^^^^^^^^^^^^^^^^^^^^^^^^^^^^^^^^^^^^^^^
  File "/home/codespace/.local/lib/python3.12/site-packages/pandas/core/internals/managers.py", line 430, in astype
    return self.apply(
           ^^^^^^^^^^^
  File "/home/codespace/.local/lib/python3.12/site-packages/pandas/core/internals/managers.py", line 363, in apply
    applied = getattr(b, f)(**kwargs)
              ^^^^^^^^^^^^^^^^^^^^^^^
  File "/home/codespace/.local/lib/python3.12/site-packages/pandas/core/internals/blocks.py", line 758, in astype
    new_values = astype_array_safe(values, dtype, copy=copy, errors=errors)
                 ^^^^^^^^^^^^^^^^^^^^^^^^^^^^^^^^^^^^^^^^^^^^^^^^^^^^^^^^^^
  File "/home/codespace/.local/lib/python3.12/site-packages/pandas/core/dtypes/astype.py", line 237, in astype_array_safe
    new_values = astype_array(values, dtype, copy=copy)
                 ^^^^^^^^^^^^^^^^^^^^^^^^^^^^^^^^^^^^^^
  File "/home/codespace/.local/lib/python3.12/site-packages/pandas/core/dtypes/astype.py", line 182, in astype_array
    values = _astype_nansafe(values, dtype, copy=copy)
             ^^^^^^^^^^^^^^^^^^^^^^^^^^^^^^^^^^^^^^^^^
  File "/home/codespace/.local/lib/python3.12/site-packages/pandas/core/dtypes/astype.py", line 80, in _astype_nansafe
    return dtype.construct_array_type()._from_sequence(arr, dtype=dtype, copy=copy)
           ^^^^^^^^^^^^^^^^^^^^^^^^^^^^^^^^^^^^^^^^^^^^^^^^^^^^^^^^^^^^^^^^^^^^^^^^
  File "/home/codespace/.local/lib/python3.12/site-packages/pandas/core/arrays/masked.py", line 152, in _from_sequence
    values, mask = cls._coerce_to_array(scalars, dtype=dtype, copy=copy)
                   ^^^^^^^^^^^^^^^^^^^^^^^^^^^^^^^^^^^^^^^^^^^^^^^^^^^^^
  File "/home/codespace/.local/lib/python3.12/site-packages/pandas/core/arrays/numeric.py", line 272, in _coerce_to_array
    values, mask, _, _ = _coerce_to_data_and_mask(
                         ^^^^^^^^^^^^^^^^^^^^^^^^^
  File "/home/codespace/.local/lib/python3.12/site-packages/pandas/core/arrays/numeric.py", line 229, in _coerce_to_data_and_mask
    values = dtype_cls._safe_cast(values, dtype, copy=False)
             ^^^^^^^^^^^^^^^^^^^^^^^^^^^^^^^^^^^^^^^^^^^^^^^
  File "/home/codespace/.local/lib/python3.12/site-packages/pandas/core/arrays/integer.py", line 59, in _safe_cast
    raise TypeError(
TypeError: cannot safely cast non-equivalent float64 to uint32
2025-01-05 05:55:46,217 - CRITICAL - Pipeline execution failed: cannot safely cast non-equivalent float64 to uint32
